Workbook

Sheet Cover
B2: Commercial Portfolio Monitoring Tracker
B3: Prairie Lantern Bank, N.A. | Commercial Banking Portfolio | Quarter ended September 30, 2026
B4: Prepared by Matthew Dial | Portfolio work sample
B6: DISCLAIMER: The bank, every borrower, and all figures are fictional and were created for portfolio demonstration only. No real customer or employer data is used.
B8: Tab | C8: What it shows
B9: Settings | C9: As-of date, early warning thresholds and point values, concentration limits, rating scale
B10: Loan_Register | C10: One row per relationship: exposure, grades, payment status, covenants, reporting dates, action plans (inputs)
B11: Covenant_Test | C11: Tests every covenant, calculates cushion, and flags Pass / Near Breach / Breach
B12: Early_Warning | C12: Scores each relationship on nine early warning indicators and assigns a flag level
B13: Watch_List | C13: Auto-populated list of relationships at or above the watch threshold, ranked by score
B14: Grade_Migration | C14: Prior vs. current risk grade matrix by count and balance; criticized and classified totals
B15: Concentration | C15: Exposure by sector and industry against internal limits; top five relationships
B16: Reporting_Tickler | C16: Financial statement, borrowing base, and maturity tracking against the as-of date
B18: How to update
C19: 1. Change the as-of date on Settings.
C20: 2. Update blue cells on Loan_Register with new test results, grades, payment status, and dates.
C21: 3. Every other tab recalculates, including the ranked watch list.
B23: Color legend
B24: Blue text | C24: Input
B25: Black text | C25: Formula on the same sheet
B26: Green text | C26: Formula linking to another sheet
B27: Red / amber / green fill | C27: Status (conditional formatting)

Sheet Settings
A1: Settings & Thresholds
A2: Blue cells drive every test in the workbook
A4: General | B4: Value | C4: Notes
A5: As-of date | B5: 46295 | C5: Quarter end being reviewed
A6: Near-breach cushion | B6: 0.1 | C6: Covenant passes but within this % of the requirement
A7: DSCR decline trigger | B7: 0.15 | C7: Decline vs. prior test that counts as a warning
A8: Borrowing base certificate late after (days) | B8: 45 | C8: Monthly BBC due within 20 days of month end
A9: Line utilization trigger | B9: 0.9 | C9: Revolver relationships only
A10: Maturity window (days) | B10: 365 | C10: Flags renewals and refinances coming due
A12: Early warning points | B12: Points | C12: Indicator
A13: Covenant breach | B13: 3
A14: Covenant near breach (no breach) | B14: 1
A15: DSCR decline beyond trigger | B15: 2
A16: 30+ days past due | B16: 3
A17: 15 to 29 days past due | B17: 1
A18: Financial statements late | B18: 1
A19: Borrowing base certificate late | B19: 1
A20: Risk grade downgrade | B20: 2
A21: Collateral coverage below 1.00x | B21: 2
A22: Revolver utilization above trigger | B22: 1
A24: Flag levels (total score) | B24: Minimum | C24: Meaning
A25: Critical | B25: 5 | C25: Escalate to credit administration; action plan within 30 days
A26: Watch | B26: 3 | C26: Added to watch list; quarterly review
A27: Monitor | B27: 1 | C27: Officer awareness; no formal action
A29: Concentration limits (% of commitments) | B29: Limit | C29: Notes
A30: Total commercial real estate | B30: 0.6 | C30: Internal portfolio limit
A31: Any single CRE property type | B31: 0.15
A32: Any single C&I industry | B32: 0.15
A33: Largest single relationship | B33: 0.12
A34: Near-limit trigger (% of limit used) | B34: 0.85 | C34: Flag when exposure reaches this share of its limit
A36: Risk rating scale | B36: Grade | C36: Category
A37: Exceptional | B37: 1 | C37: Pass
A38: Strong | B38: 2 | C38: Pass
A39: Good | B39: 3 | C39: Pass
A40: Satisfactory | B40: 4 | C40: Pass
A41: Acceptable | B41: 5 | C41: Pass
A42: Watch | B42: 6 | C42: Pass
A43: Special Mention | B43: 7 | C43: Criticized
A44: Substandard | B44: 8 | C44: Classified
A45: Doubtful | B45: 9 | C45: Classified

Sheet Loan_Register
A1: Loan Register
A2: Inputs: one row per relationship. Covenant results reflect the most recent test period.
A4: Loan ID | B4: Borrower | C4: Sector | D4: Industry | E4: Facility type | F4: Commitment | G4: Outstanding | H4: Revolver? | I4: Rate type | J4: Maturity | K4: Prior grade (Q2) | L4: Current grade (Q3) | M4: Days past due | N4: Collateral coverage | O4: DSCR minimum | P4: DSCR prior test | Q4: DSCR current test | R4: Covenant 2 | S4: Max / Min | T4: Covenant 2 requirement | U4: Covenant 2 actual | V4: Annual FS due | W4: Annual FS received | X4: Interim FS due | Y4: Interim FS received | Z4: Last BBC date | AA4: Officer comments / action plan
A5: PL-1001 | B5: Brazos Bend Fabrication, LLC | C5: C&I | D5: Manufacturing | E5: Term + RLOC | F5: 2840000 | G5: 2380000 | H5: Y | I5: Fixed / Floating | J5: 47299 | K5: 4 | L5: 4 | M5: 0 | N5: 1.65 | O5: 1.25 | P5: 1.89 | Q5: 2.15 | R5: Funded Debt / EBITDA | S5: Max | T5: 3 | U5: 1.14 | V5: 46142 | W5: 46130 | X5: 46248 | Y5: 46240 | Z5: 46283 | AA5: Strong year. $3.3MM new money approved Oct 2026 for equipment and line increase (see Package 01).
A6: PL-1002 | B6: Gulfway Cold Storage Partners, LP | C6: CRE | D6: CRE - Industrial | E6: CRE Term | F6: 9500000 | G6: 9120000 | H6: N | I6: Fixed | J6: 47938 | K6: 3 | L6: 3 | M6: 0 | N6: 1.38 | O6: 1.3 | P6: 1.6 | Q6: 1.62 | R6: Loan to Value | S6: Max | T6: 0.75 | U6: 0.66 | V6: 46142 | W6: 46122 | X6: 46248 | Y6: 46235 | Z6: n/a | AA6: Fully leased to two food distributors through 2032.
A7: PL-1003 | B7: Bayou City Pediatric Associates, PA | C7: C&I | D7: Healthcare | E7: Term + RLOC | F7: 3200000 | G7: 2400000 | H7: Y | I7: Floating | J7: 47087 | K7: 3 | L7: 3 | M7: 0 | N7: 1.4 | O7: 1.5 | P7: 1.92 | Q7: 1.85 | R7: Funded Debt / EBITDA | S7: Max | T7: 3 | U7: 2.1 | V7: 46142 | W7: 46134 | X7: 46248 | Y7: 46246 | Z7: 46280
A8: PL-1004 | B8: Cypress Ridge Apartments, LP | C8: CRE | D8: CRE - Multifamily | E8: CRE Term | F8: 14000000 | G8: 13700000 | H8: N | I8: Floating | J8: 47391 | K8: 4 | L8: 5 | M8: 0 | N8: 1.3 | O8: 1.2 | P8: 1.38 | Q8: 1.21 | R8: Loan to Value | S8: Max | T8: 0.75 | U8: 0.72 | V8: 46142 | W8: 46140 | X8: 46248 | Y8: 46245 | Z8: n/a | AA8: Insurance premiums up 38% and new-lease concessions compressed NOI; DSCR within 1% of covenant. Downgraded to 5. Action: monthly rent rolls, sponsor-funded insurance reserve, rate cap renewal before Mar 2027 expiry.
A9: PL-1005 | B9: Lone Oak Hospitality, Inc. | C9: CRE | D9: CRE - Hospitality | E9: CRE Term | F9: 8200000 | G9: 7950000 | H9: N | I9: Fixed | J9: 47634 | K9: 5 | L9: 6 | M9: 0 | N9: 1.18 | O9: 1.25 | P9: 1.19 | Q9: 1.08 | R9: Guarantor Liquidity | S9: Min | T9: 500000 | U9: 610000 | V9: 46142 | W9: 46137 | X9: 46248 | Y9: 46248 | Z9: n/a | AA9: RevPAR down 9% after a competing hotel opened nearby; DSCR covenant breached. Downgraded to 6 (Watch). Action: waiver with fee, 6-month debt service reserve, 90-day business plan, monthly STR reports.
A10: PL-1006 | B10: Copperline Electrical Contractors, Inc. | C10: C&I | D10: Construction | E10: RLOC + Equipment | F10: 4500000 | G10: 4140000 | H10: Y | I10: Floating | J10: 46568 | K10: 4 | L10: 4 | M10: 0 | N10: 1.35 | O10: 1.25 | P10: 1.47 | Q10: 1.44 | R10: Debt / Worth | S10: Max | T10: 3 | U10: 2.6 | V10: 46142 | W10: 46127 | X10: 46248 | Y10: 46244 | Z10: 46284 | AA10: Line usage at 92% from retainage on two hospital projects; paydown expected at Q4 completion. Action: confirm retainage collections on monthly BBC.
A11: PL-1007 | B11: Harbor Point Logistics, LLC | C11: C&I | D11: Transportation | E11: Equipment Term | F11: 6100000 | G11: 5200000 | H11: N | I11: Fixed | J11: 47542 | K11: 4 | L11: 5 | M11: 0 | N11: 1.1 | O11: 1.2 | P11: 1.31 | Q11: 1.18 | R11: Funded Debt / EBITDA | S11: Max | T11: 3.5 | U11: 3.3 | V11: 46142 | W11: 46164 | X11: 46248 | Z11: n/a | AA11: Freight rate softness cut EBITDA 14%; DSCR breached and 6/30 interims past due. Downgraded to 5. Action: default notice issued, interims within 15 days, evaluate sale of excess tractors to deleverage.
A12: PL-1008 | B12: Summit Pediatric Dental, PLLC | C12: C&I | D12: Healthcare | E12: Term | F12: 2100000 | G12: 1600000 | H12: N | I12: Fixed | J12: 47361 | K12: 2 | L12: 2 | M12: 0 | N12: 1.55 | O12: 1.25 | P12: 2.35 | Q12: 2.4 | R12: Funded Debt / EBITDA | S12: Max | T12: 3 | U12: 1.3 | V12: 46142 | W12: 46114 | X12: 46248 | Y12: 46233 | Z12: n/a
A13: PL-1009 | B13: Westchase Office Plaza, LLC | C13: CRE | D13: CRE - Office | E13: CRE Term | F13: 11500000 | G13: 11200000 | H13: N | I13: Floating | J13: 46752 | K13: 5 | L13: 7 | M13: 0 | N13: 0.98 | O13: 1.25 | P13: 1.3 | Q13: 1.12 | R13: Loan to Value | S13: Max | T13: 0.75 | U13: 0.79 | V13: 46142 | W13: 46141 | X13: 46248 | Y13: 46247 | Z13: n/a | AA13: Occupancy fell from 86% to 71% after the anchor tenant vacated; new appraisal puts LTV at 79%. Both covenants breached. Downgraded to Special Mention. Action: require $600K curtailment or added collateral, monthly leasing reports, start refinance planning for Dec 2027 maturity.
A14: PL-1010 | B14: Prairie Seed & Supply Co. | C14: C&I | D14: Agriculture | E14: RLOC | F14: 3000000 | G14: 2100000 | H14: Y | I14: Floating | J14: 46477 | K14: 4 | L14: 4 | M14: 0 | N14: 1.45 | O14: 1.25 | P14: 1.55 | Q14: 1.52 | R14: Debt / Worth | S14: Max | T14: 2.5 | U14: 1.8 | V14: 46142 | W14: 46132 | X14: 46248 | Y14: 46242 | Z14: 46277 | AA14: Line renewal due Mar 2027.
A15: PL-1011 | B15: Katy Retail Commons, LLC | C15: CRE | D15: CRE - Retail | E15: CRE Term | F15: 7800000 | G15: 7400000 | H15: N | I15: Fixed | J15: 48244 | K15: 3 | L15: 3 | M15: 0 | N15: 1.45 | O15: 1.25 | P15: 1.53 | Q15: 1.55 | R15: Loan to Value | S15: Max | T15: 0.75 | U15: 0.62 | V15: 46142 | W15: 46128 | X15: 46248 | Y15: 46239 | Z15: n/a
A16: PL-1012 | B16: Trinity Machine Works, Inc. | C16: C&I | D16: Manufacturing | E16: Term + RLOC | F16: 3600000 | G16: 3000000 | H16: Y | I16: Floating | J16: 46873 | K16: 4 | L16: 3 | M16: 0 | N16: 1.5 | O16: 1.25 | P16: 1.7 | Q16: 1.95 | R16: Funded Debt / EBITDA | S16: Max | T16: 3 | U16: 1.6 | V16: 46142 | W16: 46124 | X16: 46248 | Y16: 46238 | Z16: 46281 | AA16: Upgraded to 3: new aerospace contract drove 18% revenue growth.
A17: PL-1013 | B17: Redbird Restaurant Group, LLC | C17: C&I | D17: Restaurants | E17: Term | F17: 2400000 | G17: 2200000 | H17: N | I17: Fixed | J17: 47422 | K17: 5 | L17: 5 | M17: 18 | N17: 1.05 | O17: 1.25 | P17: 1.33 | Q17: 1.29 | R17: Minimum Liquidity | S17: Min | T17: 250000 | U17: 290000 | V17: 46142 | W17: 46139 | X17: 46248 | Y17: 46248 | Z17: n/a | AA17: September payment 18 days late; food cost pressure. Action: monitor payment timing, request monthly sales reports.
A18: PL-1014 | B18: Gulf Coast Oilfield Rentals, LLC | C18: C&I | D18: Energy Services | E18: Term + RLOC | F18: 5500000 | G18: 4600000 | H18: Y | I18: Floating | J18: 47026 | K18: 4 | L18: 4 | M18: 0 | N18: 1.3 | O18: 1.25 | P18: 1.78 | Q18: 1.7 | R18: Funded Debt / EBITDA | S18: Max | T18: 3 | U18: 2.8 | V18: 46142 | W18: 46133 | X18: 46248 | Y18: 46243 | Z18: 46282 | AA18: Leverage within 7% of covenant after equipment additions. Action: quarterly compliance certificate.
A19: PL-1015 | B19: Meridian Physical Therapy Group, LLC | C19: C&I | D19: Healthcare | E19: Term | F19: 1800000 | G19: 1200000 | H19: N | I19: Fixed | J19: 46811 | K19: 3 | L19: 3 | M19: 0 | N19: 1.4 | O19: 1.25 | P19: 2 | Q19: 2.05 | R19: Funded Debt / EBITDA | S19: Max | T19: 3 | U19: 1.5 | V19: 46142 | W19: 46120 | X19: 46248 | Y19: 46236 | Z19: n/a
A20: PL-1016 | B20: Pecan Street Self Storage, LLC | C20: CRE | D20: CRE - Self Storage | E20: CRE Term | F20: 6400000 | G20: 6200000 | H20: N | I20: Fixed | J20: 48060 | K20: 3 | L20: 3 | M20: 0 | N20: 1.45 | O20: 1.25 | P20: 1.69 | Q20: 1.71 | R20: Loan to Value | S20: Max | T20: 0.75 | U20: 0.6 | V20: 46142 | W20: 46126 | X20: 46248 | Y20: 46241 | Z20: n/a
A21: PL-1017 | B21: Allied Packaging Distributors, Inc. | C21: C&I | D21: Wholesale Distribution | E21: Term + RLOC | F21: 4800000 | G21: 3600000 | H21: Y | I21: Floating | J21: 47118 | K21: 4 | L21: 4 | M21: 0 | N21: 1.4 | O21: 1.25 | P21: 1.51 | Q21: 1.48 | R21: Debt / Worth | S21: Max | T21: 3 | U21: 2.2 | V21: 46142 | W21: 46136 | X21: 46248 | Y21: 46246 | Z21: 46279
A22: PL-1018 | B22: Northgate Senior Living, LLC | C22: CRE | D22: CRE - Senior Housing | E22: CRE Term | F22: 9000000 | G22: 8800000 | H22: N | I22: Floating | J22: 47238 | K22: 6 | L22: 5 | M22: 0 | N22: 1.25 | O22: 1.3 | P22: 1.22 | Q22: 1.31 | R22: Loan to Value | S22: Max | T22: 0.75 | U22: 0.7 | V22: 46142 | W22: 46138 | X22: 46248 | Y22: 46247 | Z22: n/a | AA22: Upgraded from 6: occupancy recovered to 91% and DSCR covenant cured. Cushion still thin; keep on quarterly testing.
A23: PL-1019 | B23: Clearwater HVAC Services, Inc. | C23: C&I | D23: Construction | E23: RLOC + Term | F23: 1900000 | G23: 1400000 | H23: Y | I23: Floating | J23: 46630 | K23: 4 | L23: 4 | M23: 0 | N23: 1.5 | O23: 1.25 | P23: 1.6 | Q23: 1.62 | R23: Debt / Worth | S23: Max | T23: 3 | U23: 1.7 | V23: 46142 | W23: 46131 | X23: 46248 | Y23: 46245 | Z23: 46285
A24: PL-1020 | B24: Sabine Marine Services, LLC | C24: C&I | D24: Transportation | E24: Equipment Term | F24: 3900000 | G24: 3500000 | H24: N | I24: Fixed | J24: 47787 | K24: 4 | L24: 4 | M24: 0 | N24: 1.3 | O24: 1.25 | P24: 1.42 | Q24: 1.4 | R24: Funded Debt / EBITDA | S24: Max | T24: 3.5 | U24: 2.6 | V24: 46142 | W24: 46135 | X24: 46248 | Y24: 46244 | Z24: n/a
A25: PL-1021 | B25: Heights Craft Brewing Co. | C25: C&I | D25: Food & Beverage Mfg | E25: Term + RLOC | F25: 2200000 | G25: 2050000 | H25: Y | I25: Floating | J25: 46934 | K25: 6 | L25: 8 | M25: 32 | N25: 0.92 | O25: 1.2 | P25: 1.04 | Q25: 0.94 | R25: Minimum Liquidity | S25: Min | T25: 150000 | U25: 60000 | V25: 46142 | W25: 46183 | X25: 46248 | Y25: 46267 | Z25: 46223 | AA25: Lost largest distribution contract in Q2; revenue down 22%. 32 days past due and both covenants breached. Downgraded to Substandard. Action: transfer to Special Assets, order equipment appraisal, updated guarantor PFS, evaluate forbearance.
A26: PL-1022 | B26: Lakeside Veterinary Partners, LLC | C26: C&I | D26: Healthcare | E26: Term | F26: 2600000 | G26: 2300000 | H26: N | I26: Fixed | J26: 47573 | K26: 3 | L26: 3 | M26: 0 | N26: 1.4 | O26: 1.25 | P26: 1.85 | Q26: 1.88 | R26: Funded Debt / EBITDA | S26: Max | T26: 3 | U26: 1.9 | V26: 46142 | W26: 46123 | X26: 46248 | Y26: 46240 | Z26: n/a
A27: PL-1023 | B27: Bellaire Industrial Flex, LLC | C27: CRE | D27: CRE - Industrial | E27: CRE Term | F27: 5200000 | G27: 5000000 | H27: N | I27: Fixed | J27: 48182 | K27: 3 | L27: 3 | M27: 0 | N27: 1.5 | O27: 1.25 | P27: 1.56 | Q27: 1.58 | R27: Loan to Value | S27: Max | T27: 0.75 | U27: 0.58 | V27: 46142 | W27: 46129 | X27: 46248 | Y27: 46237 | Z27: n/a
A28: PL-1024 | B28: Texan Precision Plastics, LLC | C28: C&I | D28: Manufacturing | E28: Term + RLOC | F28: 3400000 | G28: 2900000 | H28: Y | I28: Floating | J28: 46996 | K28: 4 | L28: 4 | M28: 0 | N28: 1.35 | O28: 1.25 | P28: 1.72 | Q28: 1.39 | R28: Funded Debt / EBITDA | S28: Max | T28: 3 | U28: 2.4 | V28: 46142 | W28: 46141 | X28: 46248 | Y28: 46246 | Z28: 46283 | AA28: DSCR fell 19% on a resin cost spike and delayed price increase; still compliant. Action: monthly interims through Q1 2027.
A30: Totals | F30: =SUM(F5:F28) -> 125440000 | G30: =SUM(G5:G28) -> 113940000

Sheet Covenant_Test
A1: Covenant Compliance Testing
A2: Cushion = distance from the requirement as a % of the requirement. Negative cushion = breach.
A4: Loan ID | B4: Borrower | C4: DSCR req. | D4: DSCR actual | E4: DSCR cushion | F4: DSCR status | G4: Covenant 2 | H4: Max / Min | I4: Requirement | J4: Actual | K4: Cushion | L4: Cov 2 status | M4: Overall status
A5: =Loan_Register!A5 -> PL-1001 | B5: =Loan_Register!B5 -> Brazos Bend Fabrication, LLC | C5: =Loan_Register!O5 -> 1.25 | D5: =Loan_Register!Q5 -> 2.15 | E5: =(D5-C5)/C5 -> 0.72 | F5: =IF(E5<0,"Breach",IF(E5<Settings!$B$6,"Near Breach","Pass")) -> Pass | G5: =Loan_Register!R5 -> Funded Debt / EBITDA | H5: =Loan_Register!S5 -> Max | I5: =Loan_Register!T5 -> 3 | J5: =Loan_Register!U5 -> 1.14 | K5: =IF(H5="Max",(I5-J5)/I5,(J5-I5)/I5) -> 0.62 | L5: =IF(K5<0,"Breach",IF(K5<Settings!$B$6,"Near Breach","Pass")) -> Pass | M5: =IF(OR(F5="Breach",L5="Breach"),"Breach",IF(OR(F5="Near Breach",L5="Near Breach"),"Near Breach","Pass")) -> Pass
A6: =Loan_Register!A6 -> PL-1002 | B6: =Loan_Register!B6 -> Gulfway Cold Storage Partners, LP | C6: =Loan_Register!O6 -> 1.3 | D6: =Loan_Register!Q6 -> 1.62 | E6: =(D6-C6)/C6 -> 0.24615385 | F6: =IF(E6<0,"Breach",IF(E6<Settings!$B$6,"Near Breach","Pass")) -> Pass | G6: =Loan_Register!R6 -> Loan to Value | H6: =Loan_Register!S6 -> Max | I6: =Loan_Register!T6 -> 0.75 | J6: =Loan_Register!U6 -> 0.66 | K6: =IF(H6="Max",(I6-J6)/I6,(J6-I6)/I6) -> 0.12 | L6: =IF(K6<0,"Breach",IF(K6<Settings!$B$6,"Near Breach","Pass")) -> Pass | M6: =IF(OR(F6="Breach",L6="Breach"),"Breach",IF(OR(F6="Near Breach",L6="Near Breach"),"Near Breach","Pass")) -> Pass
A7: =Loan_Register!A7 -> PL-1003 | B7: =Loan_Register!B7 -> Bayou City Pediatric Associates, PA | C7: =Loan_Register!O7 -> 1.5 | D7: =Loan_Register!Q7 -> 1.85 | E7: =(D7-C7)/C7 -> 0.23333333 | F7: =IF(E7<0,"Breach",IF(E7<Settings!$B$6,"Near Breach","Pass")) -> Pass | G7: =Loan_Register!R7 -> Funded Debt / EBITDA | H7: =Loan_Register!S7 -> Max | I7: =Loan_Register!T7 -> 3 | J7: =Loan_Register!U7 -> 2.1 | K7: =IF(H7="Max",(I7-J7)/I7,(J7-I7)/I7) -> 0.3 | L7: =IF(K7<0,"Breach",IF(K7<Settings!$B$6,"Near Breach","Pass")) -> Pass | M7: =IF(OR(F7="Breach",L7="Breach"),"Breach",IF(OR(F7="Near Breach",L7="Near Breach"),"Near Breach","Pass")) -> Pass
A8: =Loan_Register!A8 -> PL-1004 | B8: =Loan_Register!B8 -> Cypress Ridge Apartments, LP | C8: =Loan_Register!O8 -> 1.2 | D8: =Loan_Register!Q8 -> 1.21 | E8: =(D8-C8)/C8 -> 0.0083333333 | F8: =IF(E8<0,"Breach",IF(E8<Settings!$B$6,"Near Breach","Pass")) -> Near Breach | G8: =Loan_Register!R8 -> Loan to Value | H8: =Loan_Register!S8 -> Max | I8: =Loan_Register!T8 -> 0.75 | J8: =Loan_Register!U8 -> 0.72 | K8: =IF(H8="Max",(I8-J8)/I8,(J8-I8)/I8) -> 0.04 | L8: =IF(K8<0,"Breach",IF(K8<Settings!$B$6,"Near Breach","Pass")) -> Near Breach | M8: =IF(OR(F8="Breach",L8="Breach"),"Breach",IF(OR(F8="Near Breach",L8="Near Breach"),"Near Breach","Pass")) -> Near Breach
A9: =Loan_Register!A9 -> PL-1005 | B9: =Loan_Register!B9 -> Lone Oak Hospitality, Inc. | C9: =Loan_Register!O9 -> 1.25 | D9: =Loan_Register!Q9 -> 1.08 | E9: =(D9-C9)/C9 -> -0.136 | F9: =IF(E9<0,"Breach",IF(E9<Settings!$B$6,"Near Breach","Pass")) -> Breach | G9: =Loan_Register!R9 -> Guarantor Liquidity | H9: =Loan_Register!S9 -> Min | I9: =Loan_Register!T9 -> 500000 | J9: =Loan_Register!U9 -> 610000 | K9: =IF(H9="Max",(I9-J9)/I9,(J9-I9)/I9) -> 0.22 | L9: =IF(K9<0,"Breach",IF(K9<Settings!$B$6,"Near Breach","Pass")) -> Pass | M9: =IF(OR(F9="Breach",L9="Breach"),"Breach",IF(OR(F9="Near Breach",L9="Near Breach"),"Near Breach","Pass")) -> Breach
A10: =Loan_Register!A10 -> PL-1006 | B10: =Loan_Register!B10 -> Copperline Electrical Contractors, Inc. | C10: =Loan_Register!O10 -> 1.25 | D10: =Loan_Register!Q10 -> 1.44 | E10: =(D10-C10)/C10 -> 0.152 | F10: =IF(E10<0,"Breach",IF(E10<Settings!$B$6,"Near Breach","Pass")) -> Pass | G10: =Loan_Register!R10 -> Debt / Worth | H10: =Loan_Register!S10 -> Max | I10: =Loan_Register!T10 -> 3 | J10: =Loan_Register!U10 -> 2.6 | K10: =IF(H10="Max",(I10-J10)/I10,(J10-I10)/I10) -> 0.13333333 | L10: =IF(K10<0,"Breach",IF(K10<Settings!$B$6,"Near Breach","Pass")) -> Pass | M10: =IF(OR(F10="Breach",L10="Breach"),"Breach",IF(OR(F10="Near Breach",L10="Near Breach"),"Near Breach","Pass")) -> Pass
A11: =Loan_Register!A11 -> PL-1007 | B11: =Loan_Register!B11 -> Harbor Point Logistics, LLC | C11: =Loan_Register!O11 -> 1.2 | D11: =Loan_Register!Q11 -> 1.18 | E11: =(D11-C11)/C11 -> -0.016666667 | F11: =IF(E11<0,"Breach",IF(E11<Settings!$B$6,"Near Breach","Pass")) -> Breach | G11: =Loan_Register!R11 -> Funded Debt / EBITDA | H11: =Loan_Register!S11 -> Max | I11: =Loan_Register!T11 -> 3.5 | J11: =Loan_Register!U11 -> 3.3 | K11: =IF(H11="Max",(I11-J11)/I11,(J11-I11)/I11) -> 0.057142857 | L11: =IF(K11<0,"Breach",IF(K11<Settings!$B$6,"Near Breach","Pass")) -> Near Breach | M11: =IF(OR(F11="Breach",L11="Breach"),"Breach",IF(OR(F11="Near Breach",L11="Near Breach"),"Near Breach","Pass")) -> Breach
A12: =Loan_Register!A12 -> PL-1008 | B12: =Loan_Register!B12 -> Summit Pediatric Dental, PLLC | C12: =Loan_Register!O12 -> 1.25 | D12: =Loan_Register!Q12 -> 2.4 | E12: =(D12-C12)/C12 -> 0.92 | F12: =IF(E12<0,"Breach",IF(E12<Settings!$B$6,"Near Breach","Pass")) -> Pass | G12: =Loan_Register!R12 -> Funded Debt / EBITDA | H12: =Loan_Register!S12 -> Max | I12: =Loan_Register!T12 -> 3 | J12: =Loan_Register!U12 -> 1.3 | K12: =IF(H12="Max",(I12-J12)/I12,(J12-I12)/I12) -> 0.56666667 | L12: =IF(K12<0,"Breach",IF(K12<Settings!$B$6,"Near Breach","Pass")) -> Pass | M12: =IF(OR(F12="Breach",L12="Breach"),"Breach",IF(OR(F12="Near Breach",L12="Near Breach"),"Near Breach","Pass")) -> Pass
A13: =Loan_Register!A13 -> PL-1009 | B13: =Loan_Register!B13 -> Westchase Office Plaza, LLC | C13: =Loan_Register!O13 -> 1.25 | D13: =Loan_Register!Q13 -> 1.12 | E13: =(D13-C13)/C13 -> -0.104 | F13: =IF(E13<0,"Breach",IF(E13<Settings!$B$6,"Near Breach","Pass")) -> Breach | G13: =Loan_Register!R13 -> Loan to Value | H13: =Loan_Register!S13 -> Max | I13: =Loan_Register!T13 -> 0.75 | J13: =Loan_Register!U13 -> 0.79 | K13: =IF(H13="Max",(I13-J13)/I13,(J13-I13)/I13) -> -0.053333333 | L13: =IF(K13<0,"Breach",IF(K13<Settings!$B$6,"Near Breach","Pass")) -> Breach | M13: =IF(OR(F13="Breach",L13="Breach"),"Breach",IF(OR(F13="Near Breach",L13="Near Breach"),"Near Breach","Pass")) -> Breach
A14: =Loan_Register!A14 -> PL-1010 | B14: =Loan_Register!B14 -> Prairie Seed & Supply Co. | C14: =Loan_Register!O14 -> 1.25 | D14: =Loan_Register!Q14 -> 1.52 | E14: =(D14-C14)/C14 -> 0.216 | F14: =IF(E14<0,"Breach",IF(E14<Settings!$B$6,"Near Breach","Pass")) -> Pass | G14: =Loan_Register!R14 -> Debt / Worth | H14: =Loan_Register!S14 -> Max | I14: =Loan_Register!T14 -> 2.5 | J14: =Loan_Register!U14 -> 1.8 | K14: =IF(H14="Max",(I14-J14)/I14,(J14-I14)/I14) -> 0.28 | L14: =IF(K14<0,"Breach",IF(K14<Settings!$B$6,"Near Breach","Pass")) -> Pass | M14: =IF(OR(F14="Breach",L14="Breach"),"Breach",IF(OR(F14="Near Breach",L14="Near Breach"),"Near Breach","Pass")) -> Pass
A15: =Loan_Register!A15 -> PL-1011 | B15: =Loan_Register!B15 -> Katy Retail Commons, LLC | C15: =Loan_Register!O15 -> 1.25 | D15: =Loan_Register!Q15 -> 1.55 | E15: =(D15-C15)/C15 -> 0.24 | F15: =IF(E15<0,"Breach",IF(E15<Settings!$B$6,"Near Breach","Pass")) -> Pass | G15: =Loan_Register!R15 -> Loan to Value | H15: =Loan_Register!S15 -> Max | I15: =Loan_Register!T15 -> 0.75 | J15: =Loan_Register!U15 -> 0.62 | K15: =IF(H15="Max",(I15-J15)/I15,(J15-I15)/I15) -> 0.17333333 | L15: =IF(K15<0,"Breach",IF(K15<Settings!$B$6,"Near Breach","Pass")) -> Pass | M15: =IF(OR(F15="Breach",L15="Breach"),"Breach",IF(OR(F15="Near Breach",L15="Near Breach"),"Near Breach","Pass")) -> Pass
A16: =Loan_Register!A16 -> PL-1012 | B16: =Loan_Register!B16 -> Trinity Machine Works, Inc. | C16: =Loan_Register!O16 -> 1.25 | D16: =Loan_Register!Q16 -> 1.95 | E16: =(D16-C16)/C16 -> 0.56 | F16: =IF(E16<0,"Breach",IF(E16<Settings!$B$6,"Near Breach","Pass")) -> Pass | G16: =Loan_Register!R16 -> Funded Debt / EBITDA | H16: =Loan_Register!S16 -> Max | I16: =Loan_Register!T16 -> 3 | J16: =Loan_Register!U16 -> 1.6 | K16: =IF(H16="Max",(I16-J16)/I16,(J16-I16)/I16) -> 0.46666667 | L16: =IF(K16<0,"Breach",IF(K16<Settings!$B$6,"Near Breach","Pass")) -> Pass | M16: =IF(OR(F16="Breach",L16="Breach"),"Breach",IF(OR(F16="Near Breach",L16="Near Breach"),"Near Breach","Pass")) -> Pass
... A28: =Loan_Register!A28 -> PL-1024 | B28: =Loan_Register!B28 -> Texan Precision Plastics, LLC | C28: =Loan_Register!O28 -> 1.25 | D28: =Loan_Register!Q28 -> 1.39 | E28: =(D28-C28)/C28 -> 0.112 | F28: =IF(E28<0,"Breach",IF(E28<Settings!$B$6,"Near Breach","Pass")) -> Pass | G28: =Loan_Register!R28 -> Funded Debt / EBITDA | H28: =Loan_Register!S28 -> Max | I28: =Loan_Register!T28 -> 3 | J28: =Loan_Register!U28 -> 2.4 | K28: =IF(H28="Max",(I28-J28)/I28,(J28-I28)/I28) -> 0.2 | L28: =IF(K28<0,"Breach",IF(K28<Settings!$B$6,"Near Breach","Pass")) -> Pass | M28: =IF(OR(F28="Breach",L28="Breach"),"Breach",IF(OR(F28="Near Breach",L28="Near Breach"),"Near Breach","Pass")) -> Pass
A30: Summary | C30: Count | D30: Outstanding
A31: Pass | C31: =COUNTIF($M$5:$M$28,A31) -> 16 | D31: =SUMIF($M$5:$M$28,A31,Loan_Register!$G$5:$G$28) -> 58240000
A32: Near Breach | C32: =COUNTIF($M$5:$M$28,A32) -> 4 | D32: =SUMIF($M$5:$M$28,A32,Loan_Register!$G$5:$G$28) -> 29300000
A33: Breach | C33: =COUNTIF($M$5:$M$28,A33) -> 4 | D33: =SUMIF($M$5:$M$28,A33,Loan_Register!$G$5:$G$28) -> 26400000

Sheet Early_Warning
A1: Early Warning Scorecard
A2: Points per indicator come from Settings. Watch-list rank orders flagged loans by score.
A4: Loan ID | B4: Borrower | C4: Outstanding | D4: DSCR change | E4: Covenant | F4: DSCR trend | G4: Delinquency | H4: Fin. stmts | I4: BBC | J4: Downgrade | K4: Collateral | L4: Utilization | M4: Total score | N4: Flag level | O4: Watch-list rank | P4: Utilization %
A5: =Loan_Register!A5 -> PL-1001 | B5: =Loan_Register!B5 -> Brazos Bend Fabrication, LLC | C5: =Loan_Register!G5 -> 2380000 | D5: =Loan_Register!Q5/Loan_Register!P5-1 -> 0.13756614 | E5: =IF(Covenant_Test!M5="Breach",Settings!$B$13,IF(Covenant_Test!M5="Near Breach",Settings!$B$14,0)) -> 0 | F5: =IF(D5<=-Settings!$B$7,Settings!$B$15,0) -> 0 | G5: =IF(Loan_Register!M5>=30,Settings!$B$16,IF(Loan_Register!M5>=15,Settings!$B$17,0)) -> 0 | H5: =IF(OR(AND(Loan_Register!W5="",Settings!$B$5>Loan_Register!V5),AND(Loan_Register!W5<>"",Loan_Register!W5>Loan_Register!V5),AND(Loan_Register!Y5="",Settings!$B$5>Loan_Register!X5),AND(Loan_Register!Y5<>"",Loan_Register!Y5>Loan_Register!X5)),Settings!$B$18,0) -> 0 | I5: =IF(Loan_Register!H5="Y",IF(Settings!$B$5-Loan_Register!Z5>Settings!$B$8,Settings!$B$19,0),0) -> 0 | J5: =IF(Loan_Register!L5>Loan_Register!K5,Settings!$B$20,0) -> 0 | K5: =IF(Loan_Register!N5<1,Settings!$B$21,0) -> 0 | L5: =IF(AND(Loan_Register!H5="Y",P5>Settings!$B$9),Settings!$B$22,0) -> 0 | M5: =SUM(E5:L5) -> 0 | N5: =IF(M5>=Settings!$B$25,"Critical",IF(M5>=Settings!$B$26,"Watch",IF(M5>=Settings!$B$27,"Monitor","Green"))) -> Green | O5: =IF(M5>=Settings!$B$26,COUNTIF($M$5:$M$28,">"&M5)+COUNTIF($M$5:M5,M5),"") | P5: =Loan_Register!G5/Loan_Register!F5 -> 0.83802817
A6: =Loan_Register!A6 -> PL-1002 | B6: =Loan_Register!B6 -> Gulfway Cold Storage Partners, LP | C6: =Loan_Register!G6 -> 9120000 | D6: =Loan_Register!Q6/Loan_Register!P6-1 -> 0.0125 | E6: =IF(Covenant_Test!M6="Breach",Settings!$B$13,IF(Covenant_Test!M6="Near Breach",Settings!$B$14,0)) -> 0 | F6: =IF(D6<=-Settings!$B$7,Settings!$B$15,0) -> 0 | G6: =IF(Loan_Register!M6>=30,Settings!$B$16,IF(Loan_Register!M6>=15,Settings!$B$17,0)) -> 0 | H6: =IF(OR(AND(Loan_Register!W6="",Settings!$B$5>Loan_Register!V6),AND(Loan_Register!W6<>"",Loan_Register!W6>Loan_Register!V6),AND(Loan_Register!Y6="",Settings!$B$5>Loan_Register!X6),AND(Loan_Register!Y6<>"",Loan_Register!Y6>Loan_Register!X6)),Settings!$B$18,0) -> 0 | I6: =IF(Loan_Register!H6="Y",IF(Settings!$B$5-Loan_Register!Z6>Settings!$B$8,Settings!$B$19,0),0) -> 0 | J6: =IF(Loan_Register!L6>Loan_Register!K6,Settings!$B$20,0) -> 0 | K6: =IF(Loan_Register!N6<1,Settings!$B$21,0) -> 0 | L6: =IF(AND(Loan_Register!H6="Y",P6>Settings!$B$9),Settings!$B$22,0) -> 0 | M6: =SUM(E6:L6) -> 0 | N6: =IF(M6>=Settings!$B$25,"Critical",IF(M6>=Settings!$B$26,"Watch",IF(M6>=Settings!$B$27,"Monitor","Green"))) -> Green | O6: =IF(M6>=Settings!$B$26,COUNTIF($M$5:$M$28,">"&M6)+COUNTIF($M$5:M6,M6),"") | P6: =Loan_Register!G6/Loan_Register!F6 -> 0.96
A7: =Loan_Register!A7 -> PL-1003 | B7: =Loan_Register!B7 -> Bayou City Pediatric Associates, PA | C7: =Loan_Register!G7 -> 2400000 | D7: =Loan_Register!Q7/Loan_Register!P7-1 -> -0.036458333 | E7: =IF(Covenant_Test!M7="Breach",Settings!$B$13,IF(Covenant_Test!M7="Near Breach",Settings!$B$14,0)) -> 0 | F7: =IF(D7<=-Settings!$B$7,Settings!$B$15,0) -> 0 | G7: =IF(Loan_Register!M7>=30,Settings!$B$16,IF(Loan_Register!M7>=15,Settings!$B$17,0)) -> 0 | H7: =IF(OR(AND(Loan_Register!W7="",Settings!$B$5>Loan_Register!V7),AND(Loan_Register!W7<>"",Loan_Register!W7>Loan_Register!V7),AND(Loan_Register!Y7="",Settings!$B$5>Loan_Register!X7),AND(Loan_Register!Y7<>"",Loan_Register!Y7>Loan_Register!X7)),Settings!$B$18,0) -> 0 | I7: =IF(Loan_Register!H7="Y",IF(Settings!$B$5-Loan_Register!Z7>Settings!$B$8,Settings!$B$19,0),0) -> 0 | J7: =IF(Loan_Register!L7>Loan_Register!K7,Settings!$B$20,0) -> 0 | K7: =IF(Loan_Register!N7<1,Settings!$B$21,0) -> 0 | L7: =IF(AND(Loan_Register!H7="Y",P7>Settings!$B$9),Settings!$B$22,0) -> 0 | M7: =SUM(E7:L7) -> 0 | N7: =IF(M7>=Settings!$B$25,"Critical",IF(M7>=Settings!$B$26,"Watch",IF(M7>=Settings!$B$27,"Monitor","Green"))) -> Green | O7: =IF(M7>=Settings!$B$26,COUNTIF($M$5:$M$28,">"&M7)+COUNTIF($M$5:M7,M7),"") | P7: =Loan_Register!G7/Loan_Register!F7 -> 0.75
A8: =Loan_Register!A8 -> PL-1004 | B8: =Loan_Register!B8 -> Cypress Ridge Apartments, LP | C8: =Loan_Register!G8 -> 13700000 | D8: =Loan_Register!Q8/Loan_Register!P8-1 -> -0.12318841 | E8: =IF(Covenant_Test!M8="Breach",Settings!$B$13,IF(Covenant_Test!M8="Near Breach",Settings!$B$14,0)) -> 1 | F8: =IF(D8<=-Settings!$B$7,Settings!$B$15,0) -> 0 | G8: =IF(Loan_Register!M8>=30,Settings!$B$16,IF(Loan_Register!M8>=15,Settings!$B$17,0)) -> 0 | H8: =IF(OR(AND(Loan_Register!W8="",Settings!$B$5>Loan_Register!V8),AND(Loan_Register!W8<>"",Loan_Register!W8>Loan_Register!V8),AND(Loan_Register!Y8="",Settings!$B$5>Loan_Register!X8),AND(Loan_Register!Y8<>"",Loan_Register!Y8>Loan_Register!X8)),Settings!$B$18,0) -> 0 | I8: =IF(Loan_Register!H8="Y",IF(Settings!$B$5-Loan_Register!Z8>Settings!$B$8,Settings!$B$19,0),0) -> 0 | J8: =IF(Loan_Register!L8>Loan_Register!K8,Settings!$B$20,0) -> 2 | K8: =IF(Loan_Register!N8<1,Settings!$B$21,0) -> 0 | L8: =IF(AND(Loan_Register!H8="Y",P8>Settings!$B$9),Settings!$B$22,0) -> 0 | M8: =SUM(E8:L8) -> 3 | N8: =IF(M8>=Settings!$B$25,"Critical",IF(M8>=Settings!$B$26,"Watch",IF(M8>=Settings!$B$27,"Monitor","Green"))) -> Watch | O8: =IF(M8>=Settings!$B$26,COUNTIF($M$5:$M$28,">"&M8)+COUNTIF($M$5:M8,M8),"") -> 5 | P8: =Loan_Register!G8/Loan_Register!F8 -> 0.97857143
A9: =Loan_Register!A9 -> PL-1005 | B9: =Loan_Register!B9 -> Lone Oak Hospitality, Inc. | C9: =Loan_Register!G9 -> 7950000 | D9: =Loan_Register!Q9/Loan_Register!P9-1 -> -0.092436975 | E9: =IF(Covenant_Test!M9="Breach",Settings!$B$13,IF(Covenant_Test!M9="Near Breach",Settings!$B$14,0)) -> 3 | F9: =IF(D9<=-Settings!$B$7,Settings!$B$15,0) -> 0 | G9: =IF(Loan_Register!M9>=30,Settings!$B$16,IF(Loan_Register!M9>=15,Settings!$B$17,0)) -> 0 | H9: =IF(OR(AND(Loan_Register!W9="",Settings!$B$5>Loan_Register!V9),AND(Loan_Register!W9<>"",Loan_Register!W9>Loan_Register!V9),AND(Loan_Register!Y9="",Settings!$B$5>Loan_Register!X9),AND(Loan_Register!Y9<>"",Loan_Register!Y9>Loan_Register!X9)),Settings!$B$18,0) -> 0 | I9: =IF(Loan_Register!H9="Y",IF(Settings!$B$5-Loan_Register!Z9>Settings!$B$8,Settings!$B$19,0),0) -> 0 | J9: =IF(Loan_Register!L9>Loan_Register!K9,Settings!$B$20,0) -> 2 | K9: =IF(Loan_Register!N9<1,Settings!$B$21,0) -> 0 | L9: =IF(AND(Loan_Register!H9="Y",P9>Settings!$B$9),Settings!$B$22,0) -> 0 | M9: =SUM(E9:L9) -> 5 | N9: =IF(M9>=Settings!$B$25,"Critical",IF(M9>=Settings!$B$26,"Watch",IF(M9>=Settings!$B$27,"Monitor","Green"))) -> Critical | O9: =IF(M9>=Settings!$B$26,COUNTIF($M$5:$M$28,">"&M9)+COUNTIF($M$5:M9,M9),"") -> 4 | P9: =Loan_Register!G9/Loan_Register!F9 -> 0.9695122
A10: =Loan_Register!A10 -> PL-1006 | B10: =Loan_Register!B10 -> Copperline Electrical Contractors, Inc. | C10: =Loan_Register!G10 -> 4140000 | D10: =Loan_Register!Q10/Loan_Register!P10-1 -> -0.020408163 | E10: =IF(Covenant_Test!M10="Breach",Settings!$B$13,IF(Covenant_Test!M10="Near Breach",Settings!$B$14,0)) -> 0 | F10: =IF(D10<=-Settings!$B$7,Settings!$B$15,0) -> 0 | G10: =IF(Loan_Register!M10>=30,Settings!$B$16,IF(Loan_Register!M10>=15,Settings!$B$17,0)) -> 0 | H10: =IF(OR(AND(Loan_Register!W10="",Settings!$B$5>Loan_Register!V10),AND(Loan_Register!W10<>"",Loan_Register!W10>Loan_Register!V10),AND(Loan_Register!Y10="",Settings!$B$5>Loan_Register!X10),AND(Loan_Register!Y10<>"",Loan_Register!Y10>Loan_Register!X10)),Settings!$B$18,0) -> 0 | I10: =IF(Loan_Register!H10="Y",IF(Settings!$B$5-Loan_Register!Z10>Settings!$B$8,Settings!$B$19,0),0) -> 0 | J10: =IF(Loan_Register!L10>Loan_Register!K10,Settings!$B$20,0) -> 0 | K10: =IF(Loan_Register!N10<1,Settings!$B$21,0) -> 0 | L10: =IF(AND(Loan_Register!H10="Y",P10>Settings!$B$9),Settings!$B$22,0) -> 1 | M10: =SUM(E10:L10) -> 1 | N10: =IF(M10>=Settings!$B$25,"Critical",IF(M10>=Settings!$B$26,"Watch",IF(M10>=Settings!$B$27,"Monitor","Green"))) -> Monitor | O10: =IF(M10>=Settings!$B$26,COUNTIF($M$5:$M$28,">"&M10)+COUNTIF($M$5:M10,M10),"") | P10: =Loan_Register!G10/Loan_Register!F10 -> 0.92
A11: =Loan_Register!A11 -> PL-1007 | B11: =Loan_Register!B11 -> Harbor Point Logistics, LLC | C11: =Loan_Register!G11 -> 5200000 | D11: =Loan_Register!Q11/Loan_Register!P11-1 -> -0.099236641 | E11: =IF(Covenant_Test!M11="Breach",Settings!$B$13,IF(Covenant_Test!M11="Near Breach",Settings!$B$14,0)) -> 3 | F11: =IF(D11<=-Settings!$B$7,Settings!$B$15,0) -> 0 | G11: =IF(Loan_Register!M11>=30,Settings!$B$16,IF(Loan_Register!M11>=15,Settings!$B$17,0)) -> 0 | H11: =IF(OR(AND(Loan_Register!W11="",Settings!$B$5>Loan_Register!V11),AND(Loan_Register!W11<>"",Loan_Register!W11>Loan_Register!V11),AND(Loan_Register!Y11="",Settings!$B$5>Loan_Register!X11),AND(Loan_Register!Y11<>"",Loan_Register!Y11>Loan_Register!X11)),Settings!$B$18,0) -> 1 | I11: =IF(Loan_Register!H11="Y",IF(Settings!$B$5-Loan_Register!Z11>Settings!$B$8,Settings!$B$19,0),0) -> 0 | J11: =IF(Loan_Register!L11>Loan_Register!K11,Settings!$B$20,0) -> 2 | K11: =IF(Loan_Register!N11<1,Settings!$B$21,0) -> 0 | L11: =IF(AND(Loan_Register!H11="Y",P11>Settings!$B$9),Settings!$B$22,0) -> 0 | M11: =SUM(E11:L11) -> 6 | N11: =IF(M11>=Settings!$B$25,"Critical",IF(M11>=Settings!$B$26,"Watch",IF(M11>=Settings!$B$27,"Monitor","Green"))) -> Critical | O11: =IF(M11>=Settings!$B$26,COUNTIF($M$5:$M$28,">"&M11)+COUNTIF($M$5:M11,M11),"") -> 3 | P11: =Loan_Register!G11/Loan_Register!F11 -> 0.85245902
A12: =Loan_Register!A12 -> PL-1008 | B12: =Loan_Register!B12 -> Summit Pediatric Dental, PLLC | C12: =Loan_Register!G12 -> 1600000 | D12: =Loan_Register!Q12/Loan_Register!P12-1 -> 0.021276596 | E12: =IF(Covenant_Test!M12="Breach",Settings!$B$13,IF(Covenant_Test!M12="Near Breach",Settings!$B$14,0)) -> 0 | F12: =IF(D12<=-Settings!$B$7,Settings!$B$15,0) -> 0 | G12: =IF(Loan_Register!M12>=30,Settings!$B$16,IF(Loan_Register!M12>=15,Settings!$B$17,0)) -> 0 | H12: =IF(OR(AND(Loan_Register!W12="",Settings!$B$5>Loan_Register!V12),AND(Loan_Register!W12<>"",Loan_Register!W12>Loan_Register!V12),AND(Loan_Register!Y12="",Settings!$B$5>Loan_Register!X12),AND(Loan_Register!Y12<>"",Loan_Register!Y12>Loan_Register!X12)),Settings!$B$18,0) -> 0 | I12: =IF(Loan_Register!H12="Y",IF(Settings!$B$5-Loan_Register!Z12>Settings!$B$8,Settings!$B$19,0),0) -> 0 | J12: =IF(Loan_Register!L12>Loan_Register!K12,Settings!$B$20,0) -> 0 | K12: =IF(Loan_Register!N12<1,Settings!$B$21,0) -> 0 | L12: =IF(AND(Loan_Register!H12="Y",P12>Settings!$B$9),Settings!$B$22,0) -> 0 | M12: =SUM(E12:L12) -> 0 | N12: =IF(M12>=Settings!$B$25,"Critical",IF(M12>=Settings!$B$26,"Watch",IF(M12>=Settings!$B$27,"Monitor","Green"))) -> Green | O12: =IF(M12>=Settings!$B$26,COUNTIF($M$5:$M$28,">"&M12)+COUNTIF($M$5:M12,M12),"") | P12: =Loan_Register!G12/Loan_Register!F12 -> 0.76190476
A13: =Loan_Register!A13 -> PL-1009 | B13: =Loan_Register!B13 -> Westchase Office Plaza, LLC | C13: =Loan_Register!G13 -> 11200000 | D13: =Loan_Register!Q13/Loan_Register!P13-1 -> -0.13846154 | E13: =IF(Covenant_Test!M13="Breach",Settings!$B$13,IF(Covenant_Test!M13="Near Breach",Settings!$B$14,0)) -> 3 | F13: =IF(D13<=-Settings!$B$7,Settings!$B$15,0) -> 0 | G13: =IF(Loan_Register!M13>=30,Settings!$B$16,IF(Loan_Register!M13>=15,Settings!$B$17,0)) -> 0 | H13: =IF(OR(AND(Loan_Register!W13="",Settings!$B$5>Loan_Register!V13),AND(Loan_Register!W13<>"",Loan_Register!W13>Loan_Register!V13),AND(Loan_Register!Y13="",Settings!$B$5>Loan_Register!X13),AND(Loan_Register!Y13<>"",Loan_Register!Y13>Loan_Register!X13)),Settings!$B$18,0) -> 0 | I13: =IF(Loan_Register!H13="Y",IF(Settings!$B$5-Loan_Register!Z13>Settings!$B$8,Settings!$B$19,0),0) -> 0 | J13: =IF(Loan_Register!L13>Loan_Register!K13,Settings!$B$20,0) -> 2 | K13: =IF(Loan_Register!N13<1,Settings!$B$21,0) -> 2 | L13: =IF(AND(Loan_Register!H13="Y",P13>Settings!$B$9),Settings!$B$22,0) -> 0 | M13: =SUM(E13:L13) -> 7 | N13: =IF(M13>=Settings!$B$25,"Critical",IF(M13>=Settings!$B$26,"Watch",IF(M13>=Settings!$B$27,"Monitor","Green"))) -> Critical | O13: =IF(M13>=Settings!$B$26,COUNTIF($M$5:$M$28,">"&M13)+COUNTIF($M$5:M13,M13),"") -> 2 | P13: =Loan_Register!G13/Loan_Register!F13 -> 0.97391304
A14: =Loan_Register!A14 -> PL-1010 | B14: =Loan_Register!B14 -> Prairie Seed & Supply Co. | C14: =Loan_Register!G14 -> 2100000 | D14: =Loan_Register!Q14/Loan_Register!P14-1 -> -0.019354839 | E14: =IF(Covenant_Test!M14="Breach",Settings!$B$13,IF(Covenant_Test!M14="Near Breach",Settings!$B$14,0)) -> 0 | F14: =IF(D14<=-Settings!$B$7,Settings!$B$15,0) -> 0 | G14: =IF(Loan_Register!M14>=30,Settings!$B$16,IF(Loan_Register!M14>=15,Settings!$B$17,0)) -> 0 | H14: =IF(OR(AND(Loan_Register!W14="",Settings!$B$5>Loan_Register!V14),AND(Loan_Register!W14<>"",Loan_Register!W14>Loan_Register!V14),AND(Loan_Register!Y14="",Settings!$B$5>Loan_Register!X14),AND(Loan_Register!Y14<>"",Loan_Register!Y14>Loan_Register!X14)),Settings!$B$18,0) -> 0 | I14: =IF(Loan_Register!H14="Y",IF(Settings!$B$5-Loan_Register!Z14>Settings!$B$8,Settings!$B$19,0),0) -> 0 | J14: =IF(Loan_Register!L14>Loan_Register!K14,Settings!$B$20,0) -> 0 | K14: =IF(Loan_Register!N14<1,Settings!$B$21,0) -> 0 | L14: =IF(AND(Loan_Register!H14="Y",P14>Settings!$B$9),Settings!$B$22,0) -> 0 | M14: =SUM(E14:L14) -> 0 | N14: =IF(M14>=Settings!$B$25,"Critical",IF(M14>=Settings!$B$26,"Watch",IF(M14>=Settings!$B$27,"Monitor","Green"))) -> Green | O14: =IF(M14>=Settings!$B$26,COUNTIF($M$5:$M$28,">"&M14)+COUNTIF($M$5:M14,M14),"") | P14: =Loan_Register!G14/Loan_Register!F14 -> 0.7
A15: =Loan_Register!A15 -> PL-1011 | B15: =Loan_Register!B15 -> Katy Retail Commons, LLC | C15: =Loan_Register!G15 -> 7400000 | D15: =Loan_Register!Q15/Loan_Register!P15-1 -> 0.013071895 | E15: =IF(Covenant_Test!M15="Breach",Settings!$B$13,IF(Covenant_Test!M15="Near Breach",Settings!$B$14,0)) -> 0 | F15: =IF(D15<=-Settings!$B$7,Settings!$B$15,0) -> 0 | G15: =IF(Loan_Register!M15>=30,Settings!$B$16,IF(Loan_Register!M15>=15,Settings!$B$17,0)) -> 0 | H15: =IF(OR(AND(Loan_Register!W15="",Settings!$B$5>Loan_Register!V15),AND(Loan_Register!W15<>"",Loan_Register!W15>Loan_Register!V15),AND(Loan_Register!Y15="",Settings!$B$5>Loan_Register!X15),AND(Loan_Register!Y15<>"",Loan_Register!Y15>Loan_Register!X15)),Settings!$B$18,0) -> 0 | I15: =IF(Loan_Register!H15="Y",IF(Settings!$B$5-Loan_Register!Z15>Settings!$B$8,Settings!$B$19,0),0) -> 0 | J15: =IF(Loan_Register!L15>Loan_Register!K15,Settings!$B$20,0) -> 0 | K15: =IF(Loan_Register!N15<1,Settings!$B$21,0) -> 0 | L15: =IF(AND(Loan_Register!H15="Y",P15>Settings!$B$9),Settings!$B$22,0) -> 0 | M15: =SUM(E15:L15) -> 0 | N15: =IF(M15>=Settings!$B$25,"Critical",IF(M15>=Settings!$B$26,"Watch",IF(M15>=Settings!$B$27,"Monitor","Green"))) -> Green | O15: =IF(M15>=Settings!$B$26,COUNTIF($M$5:$M$28,">"&M15)+COUNTIF($M$5:M15,M15),"") | P15: =Loan_Register!G15/Loan_Register!F15 -> 0.94871795
A16: =Loan_Register!A16 -> PL-1012 | B16: =Loan_Register!B16 -> Trinity Machine Works, Inc. | C16: =Loan_Register!G16 -> 3000000 | D16: =Loan_Register!Q16/Loan_Register!P16-1 -> 0.14705882 | E16: =IF(Covenant_Test!M16="Breach",Settings!$B$13,IF(Covenant_Test!M16="Near Breach",Settings!$B$14,0)) -> 0 | F16: =IF(D16<=-Settings!$B$7,Settings!$B$15,0) -> 0 | G16: =IF(Loan_Register!M16>=30,Settings!$B$16,IF(Loan_Register!M16>=15,Settings!$B$17,0)) -> 0 | H16: =IF(OR(AND(Loan_Register!W16="",Settings!$B$5>Loan_Register!V16),AND(Loan_Register!W16<>"",Loan_Register!W16>Loan_Register!V16),AND(Loan_Register!Y16="",Settings!$B$5>Loan_Register!X16),AND(Loan_Register!Y16<>"",Loan_Register!Y16>Loan_Register!X16)),Settings!$B$18,0) -> 0 | I16: =IF(Loan_Register!H16="Y",IF(Settings!$B$5-Loan_Register!Z16>Settings!$B$8,Settings!$B$19,0),0) -> 0 | J16: =IF(Loan_Register!L16>Loan_Register!K16,Settings!$B$20,0) -> 0 | K16: =IF(Loan_Register!N16<1,Settings!$B$21,0) -> 0 | L16: =IF(AND(Loan_Register!H16="Y",P16>Settings!$B$9),Settings!$B$22,0) -> 0 | M16: =SUM(E16:L16) -> 0 | N16: =IF(M16>=Settings!$B$25,"Critical",IF(M16>=Settings!$B$26,"Watch",IF(M16>=Settings!$B$27,"Monitor","Green"))) -> Green | O16: =IF(M16>=Settings!$B$26,COUNTIF($M$5:$M$28,">"&M16)+COUNTIF($M$5:M16,M16),"") | P16: =Loan_Register!G16/Loan_Register!F16 -> 0.83333333
... A28: =Loan_Register!A28 -> PL-1024 | B28: =Loan_Register!B28 -> Texan Precision Plastics, LLC | C28: =Loan_Register!G28 -> 2900000 | D28: =Loan_Register!Q28/Loan_Register!P28-1 -> -0.19186047 | E28: =IF(Covenant_Test!M28="Breach",Settings!$B$13,IF(Covenant_Test!M28="Near Breach",Settings!$B$14,0)) -> 0 | F28: =IF(D28<=-Settings!$B$7,Settings!$B$15,0) -> 2 | G28: =IF(Loan_Register!M28>=30,Settings!$B$16,IF(Loan_Register!M28>=15,Settings!$B$17,0)) -> 0 | H28: =IF(OR(AND(Loan_Register!W28="",Settings!$B$5>Loan_Register!V28),AND(Loan_Register!W28<>"",Loan_Register!W28>Loan_Register!V28),AND(Loan_Register!Y28="",Settings!$B$5>Loan_Register!X28),AND(Loan_Register!Y28<>"",Loan_Register!Y28>Loan_Register!X28)),Settings!$B$18,0) -> 0 | I28: =IF(Loan_Register!H28="Y",IF(Settings!$B$5-Loan_Register!Z28>Settings!$B$8,Settings!$B$19,0),0) -> 0 | J28: =IF(Loan_Register!L28>Loan_Register!K28,Settings!$B$20,0) -> 0 | K28: =IF(Loan_Register!N28<1,Settings!$B$21,0) -> 0 | L28: =IF(AND(Loan_Register!H28="Y",P28>Settings!$B$9),Settings!$B$22,0) -> 0 | M28: =SUM(E28:L28) -> 2 | N28: =IF(M28>=Settings!$B$25,"Critical",IF(M28>=Settings!$B$26,"Watch",IF(M28>=Settings!$B$27,"Monitor","Green"))) -> Monitor | O28: =IF(M28>=Settings!$B$26,COUNTIF($M$5:$M$28,">"&M28)+COUNTIF($M$5:M28,M28),"") | P28: =Loan_Register!G28/Loan_Register!F28 -> 0.85294118
B30: Flag level | C30: Outstanding | D30: Count
B31: Critical | C31: =SUMIF($N$5:$N$28,B31,$C$5:$C$28) -> 26400000 | D31: =COUNTIF($N$5:$N$28,B31) -> 4
B32: Watch | C32: =SUMIF($N$5:$N$28,B32,$C$5:$C$28) -> 13700000 | D32: =COUNTIF($N$5:$N$28,B32) -> 1
B33: Monitor | C33: =SUMIF($N$5:$N$28,B33,$C$5:$C$28) -> 22640000 | D33: =COUNTIF($N$5:$N$28,B33) -> 5
B34: Green | C34: =SUMIF($N$5:$N$28,B34,$C$5:$C$28) -> 51200000 | D34: =COUNTIF($N$5:$N$28,B34) -> 14

Sheet Watch_List
A1: Watch List
A2: Populates automatically from Early_Warning: every relationship scoring at or above the Watch threshold, highest score first.
A4: Rank | B4: Loan ID | C4: Borrower | D4: Industry | E4: Outstanding | F4: Prior grade | G4: Current grade | H4: Score | I4: Flag | J4: Covenants | K4: Action plan
A5: 1 | B5: =IFERROR(INDEX(Loan_Register!$A$5:$A$28,MATCH(A5,Early_Warning!$O$5:$O$28,0)),"") -> PL-1021 | C5: =IFERROR(INDEX(Loan_Register!$B$5:$B$28,MATCH(A5,Early_Warning!$O$5:$O$28,0)),"") -> Heights Craft Brewing Co. | D5: =IFERROR(INDEX(Loan_Register!$D$5:$D$28,MATCH(A5,Early_Warning!$O$5:$O$28,0)),"") -> Food & Beverage Mfg | E5: =IFERROR(INDEX(Loan_Register!$G$5:$G$28,MATCH(A5,Early_Warning!$O$5:$O$28,0)),"") -> 2050000 | F5: =IFERROR(INDEX(Loan_Register!$K$5:$K$28,MATCH(A5,Early_Warning!$O$5:$O$28,0)),"") -> 6 | G5: =IFERROR(INDEX(Loan_Register!$L$5:$L$28,MATCH(A5,Early_Warning!$O$5:$O$28,0)),"") -> 8 | H5: =IFERROR(INDEX(Early_Warning!$M$5:$M$28,MATCH(A5,Early_Warning!$O$5:$O$28,0)),"") -> 13 | I5: =IFERROR(INDEX(Early_Warning!$N$5:$N$28,MATCH(A5,Early_Warning!$O$5:$O$28,0)),"") -> Critical | J5: =IFERROR(INDEX(Covenant_Test!$M$5:$M$28,MATCH(A5,Early_Warning!$O$5:$O$28,0)),"") -> Breach | K5: =IFERROR(INDEX(Loan_Register!$AA$5:$AA$28,MATCH(A5,Early_Warning!$O$5:$O$28,0)),"") -> Lost largest distribution contract in Q2; revenue down 22%. 32 days past due and both covenants breached. Downgraded to Substandard. Action: transfer to Special Assets, order equipment appraisal, updated guarantor PFS, evaluate forbearance.
A6: 2 | B6: =IFERROR(INDEX(Loan_Register!$A$5:$A$28,MATCH(A6,Early_Warning!$O$5:$O$28,0)),"") -> PL-1009 | C6: =IFERROR(INDEX(Loan_Register!$B$5:$B$28,MATCH(A6,Early_Warning!$O$5:$O$28,0)),"") -> Westchase Office Plaza, LLC | D6: =IFERROR(INDEX(Loan_Register!$D$5:$D$28,MATCH(A6,Early_Warning!$O$5:$O$28,0)),"") -> CRE - Office | E6: =IFERROR(INDEX(Loan_Register!$G$5:$G$28,MATCH(A6,Early_Warning!$O$5:$O$28,0)),"") -> 11200000 | F6: =IFERROR(INDEX(Loan_Register!$K$5:$K$28,MATCH(A6,Early_Warning!$O$5:$O$28,0)),"") -> 5 | G6: =IFERROR(INDEX(Loan_Register!$L$5:$L$28,MATCH(A6,Early_Warning!$O$5:$O$28,0)),"") -> 7 | H6: =IFERROR(INDEX(Early_Warning!$M$5:$M$28,MATCH(A6,Early_Warning!$O$5:$O$28,0)),"") -> 7 | I6: =IFERROR(INDEX(Early_Warning!$N$5:$N$28,MATCH(A6,Early_Warning!$O$5:$O$28,0)),"") -> Critical | J6: =IFERROR(INDEX(Covenant_Test!$M$5:$M$28,MATCH(A6,Early_Warning!$O$5:$O$28,0)),"") -> Breach | K6: =IFERROR(INDEX(Loan_Register!$AA$5:$AA$28,MATCH(A6,Early_Warning!$O$5:$O$28,0)),"") -> Occupancy fell from 86% to 71% after the anchor tenant vacated; new appraisal puts LTV at 79%. Both covenants breached. Downgraded to Special Mention. Action: require $600K curtailment or added collateral, monthly leasing reports, start refinance planning for Dec 2027 maturity.
A7: 3 | B7: =IFERROR(INDEX(Loan_Register!$A$5:$A$28,MATCH(A7,Early_Warning!$O$5:$O$28,0)),"") -> PL-1007 | C7: =IFERROR(INDEX(Loan_Register!$B$5:$B$28,MATCH(A7,Early_Warning!$O$5:$O$28,0)),"") -> Harbor Point Logistics, LLC | D7: =IFERROR(INDEX(Loan_Register!$D$5:$D$28,MATCH(A7,Early_Warning!$O$5:$O$28,0)),"") -> Transportation | E7: =IFERROR(INDEX(Loan_Register!$G$5:$G$28,MATCH(A7,Early_Warning!$O$5:$O$28,0)),"") -> 5200000 | F7: =IFERROR(INDEX(Loan_Register!$K$5:$K$28,MATCH(A7,Early_Warning!$O$5:$O$28,0)),"") -> 4 | G7: =IFERROR(INDEX(Loan_Register!$L$5:$L$28,MATCH(A7,Early_Warning!$O$5:$O$28,0)),"") -> 5 | H7: =IFERROR(INDEX(Early_Warning!$M$5:$M$28,MATCH(A7,Early_Warning!$O$5:$O$28,0)),"") -> 6 | I7: =IFERROR(INDEX(Early_Warning!$N$5:$N$28,MATCH(A7,Early_Warning!$O$5:$O$28,0)),"") -> Critical | J7: =IFERROR(INDEX(Covenant_Test!$M$5:$M$28,MATCH(A7,Early_Warning!$O$5:$O$28,0)),"") -> Breach | K7: =IFERROR(INDEX(Loan_Register!$AA$5:$AA$28,MATCH(A7,Early_Warning!$O$5:$O$28,0)),"") -> Freight rate softness cut EBITDA 14%; DSCR breached and 6/30 interims past due. Downgraded to 5. Action: default notice issued, interims within 15 days, evaluate sale of excess tractors to deleverage.
A8: 4 | B8: =IFERROR(INDEX(Loan_Register!$A$5:$A$28,MATCH(A8,Early_Warning!$O$5:$O$28,0)),"") -> PL-1005 | C8: =IFERROR(INDEX(Loan_Register!$B$5:$B$28,MATCH(A8,Early_Warning!$O$5:$O$28,0)),"") -> Lone Oak Hospitality, Inc. | D8: =IFERROR(INDEX(Loan_Register!$D$5:$D$28,MATCH(A8,Early_Warning!$O$5:$O$28,0)),"") -> CRE - Hospitality | E8: =IFERROR(INDEX(Loan_Register!$G$5:$G$28,MATCH(A8,Early_Warning!$O$5:$O$28,0)),"") -> 7950000 | F8: =IFERROR(INDEX(Loan_Register!$K$5:$K$28,MATCH(A8,Early_Warning!$O$5:$O$28,0)),"") -> 5 | G8: =IFERROR(INDEX(Loan_Register!$L$5:$L$28,MATCH(A8,Early_Warning!$O$5:$O$28,0)),"") -> 6 | H8: =IFERROR(INDEX(Early_Warning!$M$5:$M$28,MATCH(A8,Early_Warning!$O$5:$O$28,0)),"") -> 5 | I8: =IFERROR(INDEX(Early_Warning!$N$5:$N$28,MATCH(A8,Early_Warning!$O$5:$O$28,0)),"") -> Critical | J8: =IFERROR(INDEX(Covenant_Test!$M$5:$M$28,MATCH(A8,Early_Warning!$O$5:$O$28,0)),"") -> Breach | K8: =IFERROR(INDEX(Loan_Register!$AA$5:$AA$28,MATCH(A8,Early_Warning!$O$5:$O$28,0)),"") -> RevPAR down 9% after a competing hotel opened nearby; DSCR covenant breached. Downgraded to 6 (Watch). Action: waiver with fee, 6-month debt service reserve, 90-day business plan, monthly STR reports.
A9: 5 | B9: =IFERROR(INDEX(Loan_Register!$A$5:$A$28,MATCH(A9,Early_Warning!$O$5:$O$28,0)),"") -> PL-1004 | C9: =IFERROR(INDEX(Loan_Register!$B$5:$B$28,MATCH(A9,Early_Warning!$O$5:$O$28,0)),"") -> Cypress Ridge Apartments, LP | D9: =IFERROR(INDEX(Loan_Register!$D$5:$D$28,MATCH(A9,Early_Warning!$O$5:$O$28,0)),"") -> CRE - Multifamily | E9: =IFERROR(INDEX(Loan_Register!$G$5:$G$28,MATCH(A9,Early_Warning!$O$5:$O$28,0)),"") -> 13700000 | F9: =IFERROR(INDEX(Loan_Register!$K$5:$K$28,MATCH(A9,Early_Warning!$O$5:$O$28,0)),"") -> 4 | G9: =IFERROR(INDEX(Loan_Register!$L$5:$L$28,MATCH(A9,Early_Warning!$O$5:$O$28,0)),"") -> 5 | H9: =IFERROR(INDEX(Early_Warning!$M$5:$M$28,MATCH(A9,Early_Warning!$O$5:$O$28,0)),"") -> 3 | I9: =IFERROR(INDEX(Early_Warning!$N$5:$N$28,MATCH(A9,Early_Warning!$O$5:$O$28,0)),"") -> Watch | J9: =IFERROR(INDEX(Covenant_Test!$M$5:$M$28,MATCH(A9,Early_Warning!$O$5:$O$28,0)),"") -> Near Breach | K9: =IFERROR(INDEX(Loan_Register!$AA$5:$AA$28,MATCH(A9,Early_Warning!$O$5:$O$28,0)),"") -> Insurance premiums up 38% and new-lease concessions compressed NOI; DSCR within 1% of covenant. Downgraded to 5. Action: monthly rent rolls, sponsor-funded insurance reserve, rate cap renewal before Mar 2027 expiry.
A10: 6 | B10: =IFERROR(INDEX(Loan_Register!$A$5:$A$28,MATCH(A10,Early_Warning!$O$5:$O$28,0)),"") | C10: =IFERROR(INDEX(Loan_Register!$B$5:$B$28,MATCH(A10,Early_Warning!$O$5:$O$28,0)),"") | D10: =IFERROR(INDEX(Loan_Register!$D$5:$D$28,MATCH(A10,Early_Warning!$O$5:$O$28,0)),"") | E10: =IFERROR(INDEX(Loan_Register!$G$5:$G$28,MATCH(A10,Early_Warning!$O$5:$O$28,0)),"") | F10: =IFERROR(INDEX(Loan_Register!$K$5:$K$28,MATCH(A10,Early_Warning!$O$5:$O$28,0)),"") | G10: =IFERROR(INDEX(Loan_Register!$L$5:$L$28,MATCH(A10,Early_Warning!$O$5:$O$28,0)),"") | H10: =IFERROR(INDEX(Early_Warning!$M$5:$M$28,MATCH(A10,Early_Warning!$O$5:$O$28,0)),"") | I10: =IFERROR(INDEX(Early_Warning!$N$5:$N$28,MATCH(A10,Early_Warning!$O$5:$O$28,0)),"") | J10: =IFERROR(INDEX(Covenant_Test!$M$5:$M$28,MATCH(A10,Early_Warning!$O$5:$O$28,0)),"") | K10: =IFERROR(INDEX(Loan_Register!$AA$5:$AA$28,MATCH(A10,Early_Warning!$O$5:$O$28,0)),"")
A11: 7 | B11: =IFERROR(INDEX(Loan_Register!$A$5:$A$28,MATCH(A11,Early_Warning!$O$5:$O$28,0)),"") | C11: =IFERROR(INDEX(Loan_Register!$B$5:$B$28,MATCH(A11,Early_Warning!$O$5:$O$28,0)),"") | D11: =IFERROR(INDEX(Loan_Register!$D$5:$D$28,MATCH(A11,Early_Warning!$O$5:$O$28,0)),"") | E11: =IFERROR(INDEX(Loan_Register!$G$5:$G$28,MATCH(A11,Early_Warning!$O$5:$O$28,0)),"") | F11: =IFERROR(INDEX(Loan_Register!$K$5:$K$28,MATCH(A11,Early_Warning!$O$5:$O$28,0)),"") | G11: =IFERROR(INDEX(Loan_Register!$L$5:$L$28,MATCH(A11,Early_Warning!$O$5:$O$28,0)),"") | H11: =IFERROR(INDEX(Early_Warning!$M$5:$M$28,MATCH(A11,Early_Warning!$O$5:$O$28,0)),"") | I11: =IFERROR(INDEX(Early_Warning!$N$5:$N$28,MATCH(A11,Early_Warning!$O$5:$O$28,0)),"") | J11: =IFERROR(INDEX(Covenant_Test!$M$5:$M$28,MATCH(A11,Early_Warning!$O$5:$O$28,0)),"") | K11: =IFERROR(INDEX(Loan_Register!$AA$5:$AA$28,MATCH(A11,Early_Warning!$O$5:$O$28,0)),"")
A12: 8 | B12: =IFERROR(INDEX(Loan_Register!$A$5:$A$28,MATCH(A12,Early_Warning!$O$5:$O$28,0)),"") | C12: =IFERROR(INDEX(Loan_Register!$B$5:$B$28,MATCH(A12,Early_Warning!$O$5:$O$28,0)),"") | D12: =IFERROR(INDEX(Loan_Register!$D$5:$D$28,MATCH(A12,Early_Warning!$O$5:$O$28,0)),"") | E12: =IFERROR(INDEX(Loan_Register!$G$5:$G$28,MATCH(A12,Early_Warning!$O$5:$O$28,0)),"") | F12: =IFERROR(INDEX(Loan_Register!$K$5:$K$28,MATCH(A12,Early_Warning!$O$5:$O$28,0)),"") | G12: =IFERROR(INDEX(Loan_Register!$L$5:$L$28,MATCH(A12,Early_Warning!$O$5:$O$28,0)),"") | H12: =IFERROR(INDEX(Early_Warning!$M$5:$M$28,MATCH(A12,Early_Warning!$O$5:$O$28,0)),"") | I12: =IFERROR(INDEX(Early_Warning!$N$5:$N$28,MATCH(A12,Early_Warning!$O$5:$O$28,0)),"") | J12: =IFERROR(INDEX(Covenant_Test!$M$5:$M$28,MATCH(A12,Early_Warning!$O$5:$O$28,0)),"") | K12: =IFERROR(INDEX(Loan_Register!$AA$5:$AA$28,MATCH(A12,Early_Warning!$O$5:$O$28,0)),"")
A13: 9 | B13: =IFERROR(INDEX(Loan_Register!$A$5:$A$28,MATCH(A13,Early_Warning!$O$5:$O$28,0)),"") | C13: =IFERROR(INDEX(Loan_Register!$B$5:$B$28,MATCH(A13,Early_Warning!$O$5:$O$28,0)),"") | D13: =IFERROR(INDEX(Loan_Register!$D$5:$D$28,MATCH(A13,Early_Warning!$O$5:$O$28,0)),"") | E13: =IFERROR(INDEX(Loan_Register!$G$5:$G$28,MATCH(A13,Early_Warning!$O$5:$O$28,0)),"") | F13: =IFERROR(INDEX(Loan_Register!$K$5:$K$28,MATCH(A13,Early_Warning!$O$5:$O$28,0)),"") | G13: =IFERROR(INDEX(Loan_Register!$L$5:$L$28,MATCH(A13,Early_Warning!$O$5:$O$28,0)),"") | H13: =IFERROR(INDEX(Early_Warning!$M$5:$M$28,MATCH(A13,Early_Warning!$O$5:$O$28,0)),"") | I13: =IFERROR(INDEX(Early_Warning!$N$5:$N$28,MATCH(A13,Early_Warning!$O$5:$O$28,0)),"") | J13: =IFERROR(INDEX(Covenant_Test!$M$5:$M$28,MATCH(A13,Early_Warning!$O$5:$O$28,0)),"") | K13: =IFERROR(INDEX(Loan_Register!$AA$5:$AA$28,MATCH(A13,Early_Warning!$O$5:$O$28,0)),"")
A14: 10 | B14: =IFERROR(INDEX(Loan_Register!$A$5:$A$28,MATCH(A14,Early_Warning!$O$5:$O$28,0)),"") | C14: =IFERROR(INDEX(Loan_Register!$B$5:$B$28,MATCH(A14,Early_Warning!$O$5:$O$28,0)),"") | D14: =IFERROR(INDEX(Loan_Register!$D$5:$D$28,MATCH(A14,Early_Warning!$O$5:$O$28,0)),"") | E14: =IFERROR(INDEX(Loan_Register!$G$5:$G$28,MATCH(A14,Early_Warning!$O$5:$O$28,0)),"") | F14: =IFERROR(INDEX(Loan_Register!$K$5:$K$28,MATCH(A14,Early_Warning!$O$5:$O$28,0)),"") | G14: =IFERROR(INDEX(Loan_Register!$L$5:$L$28,MATCH(A14,Early_Warning!$O$5:$O$28,0)),"") | H14: =IFERROR(INDEX(Early_Warning!$M$5:$M$28,MATCH(A14,Early_Warning!$O$5:$O$28,0)),"") | I14: =IFERROR(INDEX(Early_Warning!$N$5:$N$28,MATCH(A14,Early_Warning!$O$5:$O$28,0)),"") | J14: =IFERROR(INDEX(Covenant_Test!$M$5:$M$28,MATCH(A14,Early_Warning!$O$5:$O$28,0)),"") | K14: =IFERROR(INDEX(Loan_Register!$AA$5:$AA$28,MATCH(A14,Early_Warning!$O$5:$O$28,0)),"")
A15: 11 | B15: =IFERROR(INDEX(Loan_Register!$A$5:$A$28,MATCH(A15,Early_Warning!$O$5:$O$28,0)),"") | C15: =IFERROR(INDEX(Loan_Register!$B$5:$B$28,MATCH(A15,Early_Warning!$O$5:$O$28,0)),"") | D15: =IFERROR(INDEX(Loan_Register!$D$5:$D$28,MATCH(A15,Early_Warning!$O$5:$O$28,0)),"") | E15: =IFERROR(INDEX(Loan_Register!$G$5:$G$28,MATCH(A15,Early_Warning!$O$5:$O$28,0)),"") | F15: =IFERROR(INDEX(Loan_Register!$K$5:$K$28,MATCH(A15,Early_Warning!$O$5:$O$28,0)),"") | G15: =IFERROR(INDEX(Loan_Register!$L$5:$L$28,MATCH(A15,Early_Warning!$O$5:$O$28,0)),"") | H15: =IFERROR(INDEX(Early_Warning!$M$5:$M$28,MATCH(A15,Early_Warning!$O$5:$O$28,0)),"") | I15: =IFERROR(INDEX(Early_Warning!$N$5:$N$28,MATCH(A15,Early_Warning!$O$5:$O$28,0)),"") | J15: =IFERROR(INDEX(Covenant_Test!$M$5:$M$28,MATCH(A15,Early_Warning!$O$5:$O$28,0)),"") | K15: =IFERROR(INDEX(Loan_Register!$AA$5:$AA$28,MATCH(A15,Early_Warning!$O$5:$O$28,0)),"")
A16: 12 | B16: =IFERROR(INDEX(Loan_Register!$A$5:$A$28,MATCH(A16,Early_Warning!$O$5:$O$28,0)),"") | C16: =IFERROR(INDEX(Loan_Register!$B$5:$B$28,MATCH(A16,Early_Warning!$O$5:$O$28,0)),"") | D16: =IFERROR(INDEX(Loan_Register!$D$5:$D$28,MATCH(A16,Early_Warning!$O$5:$O$28,0)),"") | E16: =IFERROR(INDEX(Loan_Register!$G$5:$G$28,MATCH(A16,Early_Warning!$O$5:$O$28,0)),"") | F16: =IFERROR(INDEX(Loan_Register!$K$5:$K$28,MATCH(A16,Early_Warning!$O$5:$O$28,0)),"") | G16: =IFERROR(INDEX(Loan_Register!$L$5:$L$28,MATCH(A16,Early_Warning!$O$5:$O$28,0)),"") | H16: =IFERROR(INDEX(Early_Warning!$M$5:$M$28,MATCH(A16,Early_Warning!$O$5:$O$28,0)),"") | I16: =IFERROR(INDEX(Early_Warning!$N$5:$N$28,MATCH(A16,Early_Warning!$O$5:$O$28,0)),"") | J16: =IFERROR(INDEX(Covenant_Test!$M$5:$M$28,MATCH(A16,Early_Warning!$O$5:$O$28,0)),"") | K16: =IFERROR(INDEX(Loan_Register!$AA$5:$AA$28,MATCH(A16,Early_Warning!$O$5:$O$28,0)),"")
C18: Watch list total | E18: =SUM(E5:E16) -> 40100000
C19: % of portfolio outstanding | E19: =E18/Loan_Register!G30 -> 0.35193962
C20: Relationships on watch list | E20: =COUNT(H5:H16) -> 5

Sheet Grade_Migration
A1: Risk Grade Migration
A2: Rows = prior quarter grade (Q2 2026). Columns = current grade (Q3 2026). Diagonal = unchanged; right of diagonal = downgrade.
A4: Count | B4: Grade 1 | C4: Grade 2 | D4: Grade 3 | E4: Grade 4 | F4: Grade 5 | G4: Grade 6 | H4: Grade 7 | I4: Grade 8 | J4: Grade 9 | K4: Total
A5: Prior grade 1 | B5: =COUNTIFS(Loan_Register!$K$5:$K$28,1,Loan_Register!$L$5:$L$28,1) -> 0 | C5: =COUNTIFS(Loan_Register!$K$5:$K$28,1,Loan_Register!$L$5:$L$28,2) -> 0 | D5: =COUNTIFS(Loan_Register!$K$5:$K$28,1,Loan_Register!$L$5:$L$28,3) -> 0 | E5: =COUNTIFS(Loan_Register!$K$5:$K$28,1,Loan_Register!$L$5:$L$28,4) -> 0 | F5: =COUNTIFS(Loan_Register!$K$5:$K$28,1,Loan_Register!$L$5:$L$28,5) -> 0 | G5: =COUNTIFS(Loan_Register!$K$5:$K$28,1,Loan_Register!$L$5:$L$28,6) -> 0 | H5: =COUNTIFS(Loan_Register!$K$5:$K$28,1,Loan_Register!$L$5:$L$28,7) -> 0 | I5: =COUNTIFS(Loan_Register!$K$5:$K$28,1,Loan_Register!$L$5:$L$28,8) -> 0 | J5: =COUNTIFS(Loan_Register!$K$5:$K$28,1,Loan_Register!$L$5:$L$28,9) -> 0 | K5: =SUM(B5:J5) -> 0
A6: Prior grade 2 | B6: =COUNTIFS(Loan_Register!$K$5:$K$28,2,Loan_Register!$L$5:$L$28,1) -> 0 | C6: =COUNTIFS(Loan_Register!$K$5:$K$28,2,Loan_Register!$L$5:$L$28,2) -> 1 | D6: =COUNTIFS(Loan_Register!$K$5:$K$28,2,Loan_Register!$L$5:$L$28,3) -> 0 | E6: =COUNTIFS(Loan_Register!$K$5:$K$28,2,Loan_Register!$L$5:$L$28,4) -> 0 | F6: =COUNTIFS(Loan_Register!$K$5:$K$28,2,Loan_Register!$L$5:$L$28,5) -> 0 | G6: =COUNTIFS(Loan_Register!$K$5:$K$28,2,Loan_Register!$L$5:$L$28,6) -> 0 | H6: =COUNTIFS(Loan_Register!$K$5:$K$28,2,Loan_Register!$L$5:$L$28,7) -> 0 | I6: =COUNTIFS(Loan_Register!$K$5:$K$28,2,Loan_Register!$L$5:$L$28,8) -> 0 | J6: =COUNTIFS(Loan_Register!$K$5:$K$28,2,Loan_Register!$L$5:$L$28,9) -> 0 | K6: =SUM(B6:J6) -> 1
A7: Prior grade 3 | B7: =COUNTIFS(Loan_Register!$K$5:$K$28,3,Loan_Register!$L$5:$L$28,1) -> 0 | C7: =COUNTIFS(Loan_Register!$K$5:$K$28,3,Loan_Register!$L$5:$L$28,2) -> 0 | D7: =COUNTIFS(Loan_Register!$K$5:$K$28,3,Loan_Register!$L$5:$L$28,3) -> 7 | E7: =COUNTIFS(Loan_Register!$K$5:$K$28,3,Loan_Register!$L$5:$L$28,4) -> 0 | F7: =COUNTIFS(Loan_Register!$K$5:$K$28,3,Loan_Register!$L$5:$L$28,5) -> 0 | G7: =COUNTIFS(Loan_Register!$K$5:$K$28,3,Loan_Register!$L$5:$L$28,6) -> 0 | H7: =COUNTIFS(Loan_Register!$K$5:$K$28,3,Loan_Register!$L$5:$L$28,7) -> 0 | I7: =COUNTIFS(Loan_Register!$K$5:$K$28,3,Loan_Register!$L$5:$L$28,8) -> 0 | J7: =COUNTIFS(Loan_Register!$K$5:$K$28,3,Loan_Register!$L$5:$L$28,9) -> 0 | K7: =SUM(B7:J7) -> 7
A8: Prior grade 4 | B8: =COUNTIFS(Loan_Register!$K$5:$K$28,4,Loan_Register!$L$5:$L$28,1) -> 0 | C8: =COUNTIFS(Loan_Register!$K$5:$K$28,4,Loan_Register!$L$5:$L$28,2) -> 0 | D8: =COUNTIFS(Loan_Register!$K$5:$K$28,4,Loan_Register!$L$5:$L$28,3) -> 1 | E8: =COUNTIFS(Loan_Register!$K$5:$K$28,4,Loan_Register!$L$5:$L$28,4) -> 8 | F8: =COUNTIFS(Loan_Register!$K$5:$K$28,4,Loan_Register!$L$5:$L$28,5) -> 2 | G8: =COUNTIFS(Loan_Register!$K$5:$K$28,4,Loan_Register!$L$5:$L$28,6) -> 0 | H8: =COUNTIFS(Loan_Register!$K$5:$K$28,4,Loan_Register!$L$5:$L$28,7) -> 0 | I8: =COUNTIFS(Loan_Register!$K$5:$K$28,4,Loan_Register!$L$5:$L$28,8) -> 0 | J8: =COUNTIFS(Loan_Register!$K$5:$K$28,4,Loan_Register!$L$5:$L$28,9) -> 0 | K8: =SUM(B8:J8) -> 11
A9: Prior grade 5 | B9: =COUNTIFS(Loan_Register!$K$5:$K$28,5,Loan_Register!$L$5:$L$28,1) -> 0 | C9: =COUNTIFS(Loan_Register!$K$5:$K$28,5,Loan_Register!$L$5:$L$28,2) -> 0 | D9: =COUNTIFS(Loan_Register!$K$5:$K$28,5,Loan_Register!$L$5:$L$28,3) -> 0 | E9: =COUNTIFS(Loan_Register!$K$5:$K$28,5,Loan_Register!$L$5:$L$28,4) -> 0 | F9: =COUNTIFS(Loan_Register!$K$5:$K$28,5,Loan_Register!$L$5:$L$28,5) -> 1 | G9: =COUNTIFS(Loan_Register!$K$5:$K$28,5,Loan_Register!$L$5:$L$28,6) -> 1 | H9: =COUNTIFS(Loan_Register!$K$5:$K$28,5,Loan_Register!$L$5:$L$28,7) -> 1 | I9: =COUNTIFS(Loan_Register!$K$5:$K$28,5,Loan_Register!$L$5:$L$28,8) -> 0 | J9: =COUNTIFS(Loan_Register!$K$5:$K$28,5,Loan_Register!$L$5:$L$28,9) -> 0 | K9: =SUM(B9:J9) -> 3
