Workbook

Sheet Cover
B2: 13-Week Cash Flow Forecast
B3: Brazos Bend Fabrication, LLC | Weeks ending October 30, 2026 to January 22, 2027
B4: Prepared by Matthew Dial | Portfolio work sample | October 2026
B6: DISCLAIMER: Brazos Bend Fabrication, LLC and all figures are fictional and were created for portfolio demonstration only. No real company or employer data is used.
B8: Tab | C8: What it shows
B9: Assumptions | C9: Opening balances, collection curve, payment timing, revolver policy, and borrowing base rates
B10: 13_Week_CF | C10: Weekly receipts, disbursements, revolver draws and repayments, borrowing base, and liquidity
B11: Summary | C11: Liquidity by week, low point, and key funding events
B13: How it works
C14: Collections come from a lag curve applied to weekly billings, including nine weeks of billing history.
C15: Materials payments lag billings by the DPO-based number of weeks.
C16: The revolver draws to protect minimum cash and sweeps cash above the target, limited by the lesser of commitment and borrowing base.
B18: Color legend
B19: Blue text | C19: Input or assumption
B20: Black text | C20: Formula on the same sheet
B21: Green text | C21: Formula linking to another sheet
B22: Yellow fill | C22: Key output or check

Sheet Assumptions
A1: 13-Week Assumptions
A2: Blue cells are inputs
A4: Opening balances (October 23, 2026) | B4: Value | C4: Notes
A5: Opening cash | B5: 585000 | C5: Bank balance less outstanding checks, 10/23/2026
A6: Opening revolver balance | B6: 960000 | C6: Unchanged since 9/30 (ties to Package 02)
A7: Opening accounts receivable | B7: 2470000 | C7: 10/23 aging
A9: Collection curve (% of a week's billings collected) | B9: Value | C9: Notes
A10: Collected 3 weeks after billing | B10: 0.05 | C10: From trailing 6-month payment history
A11: Collected 4 weeks after billing | B11: 0.15
A12: Collected 5 weeks after billing | B12: 0.3
A13: Collected 6 weeks after billing | B13: 0.28
A14: Collected 7 weeks after billing | B14: 0.12
A15: Collected 8 weeks after billing | B15: 0.07
A16: Collected 9 weeks after billing | B16: 0.03
A17: Total (must be 100%) | B17: =SUM(B10:B16) -> 1
A19: Disbursement timing | B19: Value | C19: Notes
A20: Materials purchases % of billings | B20: 0.36 | C20: Steel, consumables, outside processing
A21: Materials paid (weeks after billing) | B21: 5 | C21: DPO of about 34 days
A22: Biweekly payroll incl. taxes and benefits | B22: 250000 | C22: Paid on odd weeks
A23: Weekly operating expenses | B23: 40000 | C23: Utilities, freight, supplies, repairs, insurance installments
A24: Monthly rent | B24: 42000 | C24: Paid first week of month
A25: Existing term loan monthly P&I | B25: 54000 | C25: Paid mid-month
A26: Weekly scrap metal receipts | B26: 5000
A28: Revolver policy | B28: Value | C28: Notes
A29: Minimum cash (draw below this) | B29: 400000 | C29: Treasury policy
A30: Target cash (sweep above this) | B30: 650000 | C30: Excess repays the line
A31: Draw / repay increment | B31: 25000 | C31: Bank minimum advance
A32: Revolver rate | B32: 0.0675 | C32: SOFR + 2.75%, illustrative
A33: Eligible A/R % of total | B33: 0.88 | C33: Excludes over-90 and contra accounts
A34: A/R advance rate | B34: 0.8
A35: Inventory availability (capped) | B35: 600000 | C35: Inventory sublimit
A36: Liquidity floor for escalation | B36: 750000 | C36: Cash + availability; below this, notify CFO

Sheet 13_Week_CF
A1: 13-Week Cash Flow
A2: History columns (grey headers) feed the collection and payment lags. Forecast weeks 1 to 13.
A4: Week | C4: -8 | D4: -7 | E4: -6 | F4: -5 | G4: -4 | H4: -3 | I4: -2 | J4: -1 | K4: 0 | L4: 1 | M4: 2 | N4: 3 | O4: 4 | P4: 5 | Q4: 6 | R4: 7 | S4: 8 | T4: 9 | U4: 10 | V4: 11 | W4: 12 | X4: 13 | Y4: 13-wk total
A5: Week ending | C5: 46262 | D5: 46269 | E5: 46276 | F5: 46283 | G5: 46290 | H5: 46297 | I5: 46304 | J5: 46311 | K5: 46318 | L5: 46325 | M5: 46332 | N5: 46339 | O5: 46346 | P5: 46353 | Q5: 46360 | R5: 46367 | S5: 46374 | T5: 46381 | U5: 46388 | V5: 46395 | W5: 46402 | X5: 46409
A7: Weekly billings (invoices issued)
A8: Billings | C8: 366000 | D8: 361000 | E8: 374000 | F8: 358000 | G8: 359000 | H8: 377000 | I8: 362000 | J8: 374000 | K8: 379000 | L8: 385000 | M8: 330000 | N8: 337000 | O8: 330000 | P8: 301000 | Q8: 394000 | R8: 369000 | S8: 406000 | T8: 223000 | U8: 232000 | V8: 355000 | W8: 339000 | X8: 334000 | Y8: =SUM(L8:X8) -> 4335000
A9: Weeks 5, 9, and 10 reflect Thanksgiving and the year-end shutdown.
A11: Receipts
A12: Collections on billings | L12: =Assumptions!$B$10*I8+Assumptions!$B$11*H8+Assumptions!$B$12*G8+Assumptions!$B$13*F8+Assumptions!$B$14*E8+Assumptions!$B$15*D8+Assumptions!$B$16*C8 -> 363720 | M12: =Assumptions!$B$10*J8+Assumptions!$B$11*I8+Assumptions!$B$12*H8+Assumptions!$B$13*G8+Assumptions!$B$14*F8+Assumptions!$B$15*E8+Assumptions!$B$16*D8 -> 366590 | N12: =Assumptions!$B$10*K8+Assumptions!$B$11*J8+Assumptions!$B$12*I8+Assumptions!$B$13*H8+Assumptions!$B$14*G8+Assumptions!$B$15*F8+Assumptions!$B$16*E8 -> 368570 | O12: =Assumptions!$B$10*L8+Assumptions!$B$11*K8+Assumptions!$B$12*J8+Assumptions!$B$13*I8+Assumptions!$B$14*H8+Assumptions!$B$15*G8+Assumptions!$B$16*F8 -> 370770 | P12: =Assumptions!$B$10*M8+Assumptions!$B$11*L8+Assumptions!$B$12*K8+Assumptions!$B$13*J8+Assumptions!$B$14*I8+Assumptions!$B$15*H8+Assumptions!$B$16*G8 -> 373270 | Q12: =Assumptions!$B$10*N8+Assumptions!$B$11*M8+Assumptions!$B$12*L8+Assumptions!$B$13*K8+Assumptions!$B$14*J8+Assumptions!$B$15*I8+Assumptions!$B$16*H8 -> 369500 | R12: =Assumptions!$B$10*O8+Assumptions!$B$11*N8+Assumptions!$B$12*M8+Assumptions!$B$13*L8+Assumptions!$B$14*K8+Assumptions!$B$15*J8+Assumptions!$B$16*I8 -> 356370 | S12: =Assumptions!$B$10*P8+Assumptions!$B$11*O8+Assumptions!$B$12*N8+Assumptions!$B$13*M8+Assumptions!$B$14*L8+Assumptions!$B$15*K8+Assumptions!$B$16*J8 -> 342000 | ... X12: =Assumptions!$B$10*U8+Assumptions!$B$11*T8+Assumptions!$B$12*S8+Assumptions!$B$13*R8+Assumptions!$B$14*Q8+Assumptions!$B$15*P8+Assumptions!$B$16*O8 -> 348420 | Y12: =SUM(L12:X12) -> 4644300
A13: Scrap metal sales | L13: =Assumptions!$B$26 -> 5000 | M13: =Assumptions!$B$26 -> 5000 | N13: =Assumptions!$B$26 -> 5000 | O13: =Assumptions!$B$26 -> 5000 | P13: =Assumptions!$B$26 -> 5000 | Q13: =Assumptions!$B$26 -> 5000 | R13: =Assumptions!$B$26 -> 5000 | S13: =Assumptions!$B$26 -> 5000 | ... X13: =Assumptions!$B$26 -> 5000 | Y13: =SUM(L13:X13) -> 65000
A14: New equipment term loan proceeds | L14: 0 | M14: 0 | N14: 0 | O14: 0 | P14: 0 | Q14: 0 | R14: 0 | S14: 0 | T14: 0 | U14: 0 | V14: 2800000 | W14: 0 | X14: 0 | Y14: =SUM(L14:X14) -> 2800000
A15: Guarantor equity contribution | L15: 0 | M15: 0 | N15: 0 | O15: 0 | P15: 0 | Q15: 0 | R15: 0 | S15: 0 | T15: 0 | U15: 0 | V15: 400000 | W15: 0 | X15: 0 | Y15: =SUM(L15:X15) -> 400000
A16: Total receipts | L16: =SUM(L12:L15) -> 368720 | M16: =SUM(M12:M15) -> 371590 | N16: =SUM(N12:N15) -> 373570 | O16: =SUM(O12:O15) -> 375770 | P16: =SUM(P12:P15) -> 378270 | Q16: =SUM(Q12:Q15) -> 374500 | R16: =SUM(R12:R15) -> 361370 | S16: =SUM(S12:S15) -> 347000 | ... X16: =SUM(X12:X15) -> 353420 | Y16: =SUM(L16:X16) -> 7909300
A18: Disbursements
A19: Materials and outside processing | L19: =Assumptions!$B$20*G8 -> 129240 | M19: =Assumptions!$B$20*H8 -> 135720 | N19: =Assumptions!$B$20*I8 -> 130320 | O19: =Assumptions!$B$20*J8 -> 134640 | P19: =Assumptions!$B$20*K8 -> 136440 | Q19: =Assumptions!$B$20*L8 -> 138600 | R19: =Assumptions!$B$20*M8 -> 118800 | S19: =Assumptions!$B$20*N8 -> 121320 | ... X19: =Assumptions!$B$20*S8 -> 146160 | Y19: =SUM(L19:X19) -> 1693080
A20: Payroll, taxes, and benefits | L20: =IF(MOD(L$4,2)=1,Assumptions!$B$22,0) -> 250000 | M20: =IF(MOD(M$4,2)=1,Assumptions!$B$22,0) -> 0 | N20: =IF(MOD(N$4,2)=1,Assumptions!$B$22,0) -> 250000 | O20: =IF(MOD(O$4,2)=1,Assumptions!$B$22,0) -> 0 | P20: =IF(MOD(P$4,2)=1,Assumptions!$B$22,0) -> 250000 | Q20: =IF(MOD(Q$4,2)=1,Assumptions!$B$22,0) -> 0 | R20: =IF(MOD(R$4,2)=1,Assumptions!$B$22,0) -> 250000 | S20: =IF(MOD(S$4,2)=1,Assumptions!$B$22,0) -> 0 | ... X20: =IF(MOD(X$4,2)=1,Assumptions!$B$22,0) -> 250000 | Y20: =SUM(L20:X20) -> 1750000
A21: Rent | L21: =IF(OR(L$4=2,L$4=6,L$4=10),Assumptions!$B$24,0) -> 0 | M21: =IF(OR(M$4=2,M$4=6,M$4=10),Assumptions!$B$24,0) -> 42000 | N21: =IF(OR(N$4=2,N$4=6,N$4=10),Assumptions!$B$24,0) -> 0 | O21: =IF(OR(O$4=2,O$4=6,O$4=10),Assumptions!$B$24,0) -> 0 | P21: =IF(OR(P$4=2,P$4=6,P$4=10),Assumptions!$B$24,0) -> 0 | Q21: =IF(OR(Q$4=2,Q$4=6,Q$4=10),Assumptions!$B$24,0) -> 42000 | R21: =IF(OR(R$4=2,R$4=6,R$4=10),Assumptions!$B$24,0) -> 0 | S21: =IF(OR(S$4=2,S$4=6,S$4=10),Assumptions!$B$24,0) -> 0 | ... X21: =IF(OR(X$4=2,X$4=6,X$4=10),Assumptions!$B$24,0) -> 0 | Y21: =SUM(L21:X21) -> 126000
A22: Operating expenses | L22: =Assumptions!$B$23 -> 40000 | M22: =Assumptions!$B$23 -> 40000 | N22: =Assumptions!$B$23 -> 40000 | O22: =Assumptions!$B$23 -> 40000 | P22: =Assumptions!$B$23 -> 40000 | Q22: =Assumptions!$B$23 -> 40000 | R22: =Assumptions!$B$23 -> 40000 | S22: =Assumptions!$B$23 -> 40000 | ... X22: =Assumptions!$B$23 -> 40000 | Y22: =SUM(L22:X22) -> 520000
A23: Existing term loan P&I | L23: =IF(OR(L$4=3,L$4=8,L$4=12),Assumptions!$B$25,0) -> 0 | M23: =IF(OR(M$4=3,M$4=8,M$4=12),Assumptions!$B$25,0) -> 0 | N23: =IF(OR(N$4=3,N$4=8,N$4=12),Assumptions!$B$25,0) -> 54000 | O23: =IF(OR(O$4=3,O$4=8,O$4=12),Assumptions!$B$25,0) -> 0 | P23: =IF(OR(P$4=3,P$4=8,P$4=12),Assumptions!$B$25,0) -> 0 | Q23: =IF(OR(Q$4=3,Q$4=8,Q$4=12),Assumptions!$B$25,0) -> 0 | R23: =IF(OR(R$4=3,R$4=8,R$4=12),Assumptions!$B$25,0) -> 0 | S23: =IF(OR(S$4=3,S$4=8,S$4=12),Assumptions!$B$25,0) -> 54000 | ... X23: =IF(OR(X$4=3,X$4=8,X$4=12),Assumptions!$B$25,0) -> 0 | Y23: =SUM(L23:X23) -> 162000
A24: Revolver interest | L24: =IF(OR(L$4=2,L$4=6,L$4=10),ROUND(L37*Assumptions!$B$32/12,0),0) -> 0 | M24: =IF(OR(M$4=2,M$4=6,M$4=10),ROUND(M37*Assumptions!$B$32/12,0),0) -> 5400 | N24: =IF(OR(N$4=2,N$4=6,N$4=10),ROUND(N37*Assumptions!$B$32/12,0),0) -> 0 | O24: =IF(OR(O$4=2,O$4=6,O$4=10),ROUND(O37*Assumptions!$B$32/12,0),0) -> 0 | P24: =IF(OR(P$4=2,P$4=6,P$4=10),ROUND(P37*Assumptions!$B$32/12,0),0) -> 0 | Q24: =IF(OR(Q$4=2,Q$4=6,Q$4=10),ROUND(Q37*Assumptions!$B$32/12,0),0) -> 5541 | R24: =IF(OR(R$4=2,R$4=6,R$4=10),ROUND(R37*Assumptions!$B$32/12,0),0) -> 0 | S24: =IF(OR(S$4=2,S$4=6,S$4=10),ROUND(S37*Assumptions!$B$32/12,0),0) -> 0 | ... X24: =IF(OR(X$4=2,X$4=6,X$4=10),ROUND(X37*Assumptions!$B$32/12,0),0) -> 0 | Y24: =SUM(L24:X24) -> 16482
A25: Maintenance capex | L25: 0 | M25: 0 | N25: 0 | O25: 45000 | P25: 0 | Q25: 0 | R25: 0 | S25: 0 | T25: 60000 | U25: 0 | V25: 0 | W25: 0 | X25: 0 | Y25: =SUM(L25:X25) -> 105000
A26: New equipment (deposit, then balance at delivery) | L26: 0 | M26: 0 | N26: 0 | O26: 300000 | P26: 0 | Q26: 0 | R26: 0 | S26: 0 | T26: 0 | U26: 0 | V26: 3200000 | W26: 0 | X26: 0 | Y26: =SUM(L26:X26) -> 3500000
A27: Year-end bonuses | L27: 0 | M27: 0 | N27: 0 | O27: 0 | P27: 0 | Q27: 0 | R27: 0 | S27: 95000 | T27: 0 | U27: 0 | V27: 0 | W27: 0 | X27: 0 | Y27: =SUM(L27:X27) -> 95000
A28: Insurance renewal | L28: 0 | M28: 0 | N28: 0 | O28: 0 | P28: 0 | Q28: 0 | R28: 0 | S28: 0 | T28: 0 | U28: 85000 | V28: 0 | W28: 0 | X28: 0 | Y28: =SUM(L28:X28) -> 85000
A29: Q4 tax distributions to members | L29: 0 | M29: 0 | N29: 0 | O29: 0 | P29: 0 | Q29: 0 | R29: 0 | S29: 0 | T29: 0 | U29: 0 | V29: 0 | W29: 200000 | X29: 0 | Y29: =SUM(L29:X29) -> 200000
A30: Total disbursements | L30: =SUM(L19:L29) -> 419240 | M30: =SUM(M19:M29) -> 223120 | N30: =SUM(N19:N29) -> 474320 | O30: =SUM(O19:O29) -> 519640 | P30: =SUM(P19:P29) -> 426440 | Q30: =SUM(Q19:Q29) -> 226141 | R30: =SUM(R19:R29) -> 408800 | S30: =SUM(S19:S29) -> 310320 | ... X30: =SUM(X19:X29) -> 436160 | Y30: =SUM(L30:X30) -> 8252562
A32: Cash and revolver
A33: Net cash flow before revolver | L33: =L16-L30 -> -50520 | M33: =M16-M30 -> 148470 | N33: =N16-N30 -> -100750 | O33: =O16-O30 -> -143870 | P33: =P16-P30 -> -48170 | Q33: =Q16-Q30 -> 148359 | R33: =R16-R30 -> -47430 | S33: =S16-S30 -> 36680 | ... X33: =X16-X30 -> -82740 | Y33: =SUM(L33:X33) -> -343262
A34: Beginning cash | L34: =Assumptions!$B$5 -> 585000 | M34: =L45 -> 534480 | N34: =M45 -> 657950 | O34: =N45 -> 557200 | P34: =O45 -> 413330 | Q34: =P45 -> 415160 | R34: =Q45 -> 563519 | S34: =R45 -> 516089 | T34: =S45 -> 552769 | ... X34: =W45 -> 424478
A35: Cash before revolver | L35: =L34+L33 -> 534480 | M35: =M34+M33 -> 682950 | N35: =N34+N33 -> 557200 | O35: =O34+O33 -> 413330 | P35: =P34+P33 -> 365160 | Q35: =Q34+Q33 -> 563519 | R35: =R34+R33 -> 516089 | S35: =S34+S33 -> 552769 | ... X35: =X34+X33 -> 341738
A37: Revolver beginning balance | L37: =Assumptions!$B$6 -> 960000 | M37: =L43 -> 960000 | N37: =M43 -> 935000 | O37: =N43 -> 935000 | P37: =O43 -> 935000 | Q37: =P43 -> 985000 | R37: =Q43 -> 985000 | S37: =R43 -> 985000 | T37: =S43 -> 985000 | ... X37: =W43 -> 1060000
A38: Revolver commitment | L38: 1000000 | M38: 1000000 | N38: 1500000 | O38: 1500000 | P38: 1500000 | Q38: 1500000 | R38: 1500000 | S38: 1500000 | T38: 1500000 | U38: 1500000 | V38: 1500000 | W38: 1500000 | X38: 1500000 | Z38: Line increase to $1.5MM effective at loan closing, week 3
A39: Accounts receivable (end of week) | L39: =Assumptions!$B$7+L8-L12 -> 2491280 | M39: =L39+M8-M12 -> 2454690 | N39: =M39+N8-N12 -> 2423120 | O39: =N39+O8-O12 -> 2382350 | P39: =O39+P8-P12 -> 2310080 | Q39: =P39+Q8-Q12 -> 2334580 | R39: =Q39+R8-R12 -> 2347210 | S39: =R39+S8-S12 -> 2411210 | T39: =S39+T8-T12 -> 2298080 | ... X39: =W39+X8-X12 -> 2160700
A40: Borrowing base | L40: =L39*Assumptions!$B$33*Assumptions!$B$34+Assumptions!$B$35 -> 2353861.1 | M40: =M39*Assumptions!$B$33*Assumptions!$B$34+Assumptions!$B$35 -> 2328101.8 | N40: =N39*Assumptions!$B$33*Assumptions!$B$34+Assumptions!$B$35 -> 2305876.5 | O40: =O39*Assumptions!$B$33*Assumptions!$B$34+Assumptions!$B$35 -> 2277174.4 | P40: =P39*Assumptions!$B$33*Assumptions!$B$34+Assumptions!$B$35 -> 2226296.3 | Q40: =Q39*Assumptions!$B$33*Assumptions!$B$34+Assumptions!$B$35 -> 2243544.3 | R40: =R39*Assumptions!$B$33*Assumptions!$B$34+Assumptions!$B$35 -> 2252435.8 | S40: =S39*Assumptions!$B$33*Assumptions!$B$34+Assumptions!$B$35 -> 2297491.8 | ... X40: =X39*Assumptions!$B$33*Assumptions!$B$34+Assumptions!$B$35 -> 2121132.8
A41: Availability before draw | L41: =MAX(0,MIN(L38,L40)-L37) -> 40000 | M41: =MAX(0,MIN(M38,M40)-M37) -> 40000 | N41: =MAX(0,MIN(N38,N40)-N37) -> 565000 | O41: =MAX(0,MIN(O38,O40)-O37) -> 565000 | P41: =MAX(0,MIN(P38,P40)-P37) -> 565000 | Q41: =MAX(0,MIN(Q38,Q40)-Q37) -> 515000 | R41: =MAX(0,MIN(R38,R40)-R37) -> 515000 | S41: =MAX(0,MIN(S38,S40)-S37) -> 515000 | ... X41: =MAX(0,MIN(X38,X40)-X37) -> 440000
A42: Revolver draw (repayment) | L42: =IF(L35<Assumptions!$B$29,MIN(L41,CEILING((Assumptions!$B$29-L35)/Assumptions!$B$31,1)*Assumptions!$B$31),-MIN(L37,MAX(0,FLOOR((L35-Assumptions!$B$30)/Assumptions!$B$31,1)*Assumptions!$B$31))) -> 0 | M42: =IF(M35<Assumptions!$B$29,MIN(M41,CEILING((Assumptions!$B$29-M35)/Assumptions!$B$31,1)*Assumptions!$B$31),-MIN(M37,MAX(0,FLOOR((M35-Assumptions!$B$30)/Assumptions!$B$31,1)*Assumptions!$B$31))) -> -25000 | N42: =IF(N35<Assumptions!$B$29,MIN(N41,CEILING((Assumptions!$B$29-N35)/Assumptions!$B$31,1)*Assumptions!$B$31),-MIN(N37,MAX(0,FLOOR((N35-Assumptions!$B$30)/Assumptions!$B$31,1)*Assumptions!$B$31))) -> 0 | O42: =IF(O35<Assumptions!$B$29,MIN(O41,CEILING((Assumptions!$B$29-O35)/Assumptions!$B$31,1)*Assumptions!$B$31),-MIN(O37,MAX(0,FLOOR((O35-Assumptions!$B$30)/Assumptions!$B$31,1)*Assumptions!$B$31))) -> 0 | P42: =IF(P35<Assumptions!$B$29,MIN(P41,CEILING((Assumptions!$B$29-P35)/Assumptions!$B$31,1)*Assumptions!$B$31),-MIN(P37,MAX(0,FLOOR((P35-Assumptions!$B$30)/Assumptions!$B$31,1)*Assumptions!$B$31))) -> 50000 | Q42: =IF(Q35<Assumptions!$B$29,MIN(Q41,CEILING((Assumptions!$B$29-Q35)/Assumptions!$B$31,1)*Assumptions!$B$31),-MIN(Q37,MAX(0,FLOOR((Q35-Assumptions!$B$30)/Assumptions!$B$31,1)*Assumptions!$B$31))) -> 0 | R42: =IF(R35<Assumptions!$B$29,MIN(R41,CEILING((Assumptions!$B$29-R35)/Assumptions!$B$31,1)*Assumptions!$B$31),-MIN(R37,MAX(0,FLOOR((R35-Assumptions!$B$30)/Assumptions!$B$31,1)*Assumptions!$B$31))) -> 0 | S42: =IF(S35<Assumptions!$B$29,MIN(S41,CEILING((Assumptions!$B$29-S35)/Assumptions!$B$31,1)*Assumptions!$B$31),-MIN(S37,MAX(0,FLOOR((S35-Assumptions!$B$30)/Assumptions!$B$31,1)*Assumptions!$B$31))) -> 0 | ... X42: =IF(X35<Assumptions!$B$29,MIN(X41,CEILING((Assumptions!$B$29-X35)/Assumptions!$B$31,1)*Assumptions!$B$31),-MIN(X37,MAX(0,FLOOR((X35-Assumptions!$B$30)/Assumptions!$B$31,1)*Assumptions!$B$31))) -> 75000 | Y42: =SUM(L42:X42) -> 175000
A43: Revolver ending balance | L43: =L37+L42 -> 960000 | M43: =M37+M42 -> 935000 | N43: =N37+N42 -> 935000 | O43: =O37+O42 -> 935000 | P43: =P37+P42 -> 985000 | Q43: =Q37+Q42 -> 985000 | R43: =R37+R42 -> 985000 | S43: =S37+S42 -> 985000 | ... X43: =X37+X42 -> 1135000
A45: Ending cash | L45: =L35+L42 -> 534480 | M45: =M35+M42 -> 657950 | N45: =N35+N42 -> 557200 | O45: =O35+O42 -> 413330 | P45: =P35+P42 -> 415160 | Q45: =Q35+Q42 -> 563519 | R45: =R35+R42 -> 516089 | S45: =S35+S42 -> 552769 | ... X45: =X35+X42 -> 416738
A46: Ending availability | L46: =MAX(0,MIN(L38,L40)-L43) -> 40000 | M46: =MAX(0,MIN(M38,M40)-M43) -> 65000 | N46: =MAX(0,MIN(N38,N40)-N43) -> 565000 | O46: =MAX(0,MIN(O38,O40)-O43) -> 565000 | P46: =MAX(0,MIN(P38,P40)-P43) -> 515000 | Q46: =MAX(0,MIN(Q38,Q40)-Q43) -> 515000 | R46: =MAX(0,MIN(R38,R40)-R43) -> 515000 | S46: =MAX(0,MIN(S38,S40)-S43) -> 515000 | ... X46: =MAX(0,MIN(X38,X40)-X43) -> 365000
A47: Total liquidity (cash + availability) | L47: =L45+L46 -> 574480 | M47: =M45+M46 -> 722950 | N47: =N45+N46 -> 1122200 | O47: =O45+O46 -> 978330 | P47: =P45+P46 -> 930160 | Q47: =Q45+Q46 -> 1078519 | R47: =R45+R46 -> 1031089 | S47: =S45+S46 -> 1067769 | ... X47: =X45+X46 -> 781738
...

Sheet Summary
A1: 13-Week Summary
A2: Links to 13_Week_CF
A3: Key results | B3: Value | D3: Notes
A4: Opening cash (10/23/2026) | B4: =Assumptions!$B$5 -> 585000
A5: Total receipts | B5: =13_Week_CF!Y16 -> 7909300
A6: Total disbursements | B6: =-13_Week_CF!Y30 -> -8252562
A7: Net revolver draws (repayments) | B7: =13_Week_CF!Y42 -> 175000
A8: Ending cash (1/22/2027) | B8: =13_Week_CF!X45 -> 416738 | D8: Week 11 equipment balance ($3.2MM) is fully funded by the $2.8MM loan and $400K guarantor contribution; the $300K deposit in week 4 is the company's equity
A9: Cash proof (must be zero) | B9: =B4+B5+B6+B7-B8 -> 0
A11: Opening revolver balance | B11: =Assumptions!$B$6 -> 960000
A12: Ending revolver balance | B12: =13_Week_CF!X43 -> 1135000
A13: Peak revolver balance | B13: =MAX(13_Week_CF!L43:X43) -> 1135000 | D13: Year-end shutdown and January tax distributions drive peak usage
A15: Lowest weekly liquidity | B15: =MIN(13_Week_CF!L47:X47) -> 574480 | D15: Escalate to CFO if liquidity falls below the floor
A16: Week of lowest liquidity | B16: =INDEX(13_Week_CF!L5:X5,MATCH(B15,13_Week_CF!L47:X47,0)) -> 46325
A17: Liquidity floor | B17: =Assumptions!$B$36 -> 750000
A18: Weeks below floor | B18: =COUNTIF(13_Week_CF!L48:X48,"Below floor")+COUNTIF(13_Week_CF!L48:X48,"Shortfall") -> 2
A19: Total collections | B19: =13_Week_CF!Y12 -> 4644300
A20: Total billings | B20: =13_Week_CF!Y8 -> 4335000
A22: Week ending | B22: Ending cash | D22: Liquidity
A23: =13_Week_CF!L5 -> 46325 | B23: =13_Week_CF!L45 -> 534480 | D23: =13_Week_CF!L47 -> 574480
A24: =13_Week_CF!M5 -> 46332 | B24: =13_Week_CF!M45 -> 657950 | D24: =13_Week_CF!M47 -> 722950
A25: =13_Week_CF!N5 -> 46339 | B25: =13_Week_CF!N45 -> 557200 | D25: =13_Week_CF!N47 -> 1122200
A26: =13_Week_CF!O5 -> 46346 | B26: =13_Week_CF!O45 -> 413330 | D26: =13_Week_CF!O47 -> 978330
A27: =13_Week_CF!P5 -> 46353 | B27: =13_Week_CF!P45 -> 415160 | D27: =13_Week_CF!P47 -> 930160
A28: =13_Week_CF!Q5 -> 46360 | B28: =13_Week_CF!Q45 -> 563519 | D28: =13_Week_CF!Q47 -> 1078519
A29: =13_Week_CF!R5 -> 46367 | B29: =13_Week_CF!R45 -> 516089 | D29: =13_Week_CF!R47 -> 1031089
A30: =13_Week_CF!S5 -> 46374 | B30: =13_Week_CF!S45 -> 552769 | D30: =13_Week_CF!S47 -> 1067769
A31: =13_Week_CF!T5 -> 46381 | B31: =13_Week_CF!T45 -> 425099 | D31: =13_Week_CF!T47 -> 940099
A32: =13_Week_CF!U5 -> 46388 | B32: =13_Week_CF!U45 -> 484538 | D32: =13_Week_CF!U47 -> 999538
A33: =13_Week_CF!V5 -> 46395 | B33: =13_Week_CF!V45 -> 408918 | D33: =13_Week_CF!V47 -> 923918
A34: =13_Week_CF!W5 -> 46402 | B34: =13_Week_CF!W45 -> 424478 | D34: =13_Week_CF!W47 -> 864478
A35: =13_Week_CF!X5 -> 46409 | B35: =13_Week_CF!X45 -> 416738 | D35: =13_Week_CF!X47 -> 781738
