Workbook

Sheet Cover
B2: Monthly Close Pack: September 2026
B3: Brazos Bend Fabrication, LLC | Budget vs. actual, full-year forecast, bank reconciliation, and KPIs
B4: Prepared by Matthew Dial | Portfolio work sample | October 2026
B6: DISCLAIMER: Brazos Bend Fabrication, LLC and all figures are fictional and were created for portfolio demonstration only. No real company or employer data is used.
B8: Tab | C8: What it shows
B9: Monthly_Data | C9: Monthly budget, actual (Jan to Sep), and Q4 forecast by line and end market (inputs)
B10: BvA | C10: September and year-to-date budget vs. actual with favorable / unfavorable flags
B11: Margin_Bridge | C11: YTD gross profit split into volume and margin-rate variance by end market, plus an EBITDA bridge
B12: FY_Forecast | C12: Full-year forecast (9 months actual + Q4 forecast) against the FY2026 budget
B13: Bank_Rec | C13: September 30 bank reconciliation with proposed adjusting entries
B14: GL_Cash / Bank_Stmt | C14: Transaction detail with automatic matching on reference and amount
B15: KPI_Trend | C15: Monthly KPIs: revenue vs. budget, margins, DSO / DIO / DPO, backlog, cash, revolver, liquidity
B17: Color legend
B18: Blue text | C18: Input or assumption
B19: Black text | C19: Formula on the same sheet
B20: Green text | C20: Formula linking to another sheet
B21: Yellow fill | C21: Key output or check

Sheet Monthly_Data
A1: Monthly Data (Inputs)
A2: Budget approved December 2025. Actuals from the GL. Q4 is the September forecast.
A4: Line | B4: Type | C4: Jan-26 | D4: Feb-26 | E4: Mar-26 | F4: Apr-26 | G4: May-26 | H4: Jun-26 | I4: Jul-26 | J4: Aug-26 | K4: Sep-26 | L4: Oct-26 | M4: Nov-26 | N4: Dec-26 | O4: Total
A5: Budget
A6: Revenue: Commercial construction | B6: Revenue | C6: 562000 | D6: 585000 | E6: 646000 | F6: 631000 | G6: 661000 | H6: 654000 | I6: 616000 | J6: 654000 | K6: 638000 | L6: 661000 | M6: 608000 | N6: 683000 | O6: =SUM(C6:N6) -> 7599000
A7: Revenue: Midstream energy | B7: Revenue | C7: 492000 | D7: 512000 | E7: 565000 | F7: 552000 | G7: 579000 | H7: 572000 | I7: 539000 | J7: 572000 | K7: 559000 | L7: 579000 | M7: 532000 | N7: 598000 | O7: =SUM(C7:N7) -> 6651000
A8: Revenue: Industrial OEM | B8: Revenue | C8: 352000 | D8: 366000 | E8: 404000 | F8: 394000 | G8: 413000 | H8: 408000 | I8: 385000 | J8: 408000 | K8: 399000 | L8: 413000 | M8: 380000 | N8: 428000 | O8: =SUM(C8:N8) -> 4750000
A9: COGS: Commercial construction | B9: Cost | C9: 419000 | D9: 436000 | E9: 481000 | F9: 470000 | G9: 492000 | H9: 487000 | I9: 459000 | J9: 487000 | K9: 475000 | L9: 492000 | M9: 453000 | N9: 509000 | O9: =SUM(C9:N9) -> 5660000
A10: COGS: Midstream energy | B10: Cost | C10: 344000 | D10: 358000 | E10: 396000 | F10: 386000 | G10: 405000 | H10: 400000 | I10: 377000 | J10: 400000 | K10: 391000 | L10: 405000 | M10: 372000 | N10: 419000 | O10: =SUM(C10:N10) -> 4653000
A11: COGS: Industrial OEM | B11: Cost | C11: 256000 | D11: 266000 | E11: 294000 | F11: 287000 | G11: 301000 | H11: 297000 | I11: 280000 | J11: 297000 | K11: 290000 | L11: 301000 | M11: 277000 | N11: 312000 | O11: =SUM(C11:N11) -> 3458000
A12: Officer compensation | B12: Cost | C12: 38333 | D12: 38333 | E12: 38333 | F12: 38333 | G12: 38333 | H12: 38333 | I12: 38333 | J12: 38333 | K12: 38333 | L12: 38333 | M12: 38333 | N12: 38337 | O12: =SUM(C12:N12) -> 460000
A13: Other SG&A | B13: Cost | C13: 179000 | D13: 179000 | E13: 179000 | F13: 179000 | G13: 179000 | H13: 179000 | I13: 179000 | J13: 179000 | K13: 179000 | L13: 179000 | M13: 179000 | N13: 181000 | O13: =SUM(C13:N13) -> 2150000
A14: Depreciation & amortization | B14: Cost | C14: 60000 | D14: 60000 | E14: 60000 | F14: 60000 | G14: 60000 | H14: 60000 | I14: 60000 | J14: 60000 | K14: 60000 | L14: 60000 | M14: 60000 | N14: 60000 | O14: =SUM(C14:N14) -> 720000
A15: Interest expense | B15: Cost | C15: 14500 | D15: 14500 | E15: 14500 | F15: 14500 | G15: 14500 | H15: 14500 | I15: 14500 | J15: 14500 | K15: 14500 | L15: 14500 | M15: 14500 | N15: 14500 | O15: =SUM(C15:N15) -> 174000
A17: Actual (Jan to Sep) + Forecast (Oct to Dec, shaded)
A18: Revenue: Commercial construction | B18: Revenue | C18: 485000 | D18: 498000 | E18: 572000 | F18: 533000 | G18: 580000 | H18: 566000 | I18: 520000 | J18: 573000 | K18: 538000 | L18: 577000 | M18: 530000 | N18: 597000 | O18: =SUM(C18:N18) -> 6569000
A19: Revenue: Midstream energy | B19: Revenue | C19: 531000 | D19: 536000 | E19: 593000 | F19: 595000 | G19: 645000 | H19: 602000 | I19: 572000 | J19: 627000 | K19: 628000 | L19: 632000 | M19: 581000 | N19: 654000 | O19: =SUM(C19:N19) -> 7196000
A20: Revenue: Industrial OEM | B20: Revenue | C20: 351000 | D20: 359000 | E20: 415000 | F20: 376000 | G20: 421000 | H20: 397000 | I20: 370000 | J20: 392000 | K20: 389000 | L20: 411000 | M20: 378000 | N20: 426000 | O20: =SUM(C20:N20) -> 4685000
A21: COGS: Commercial construction | B21: Cost | C21: 368000 | D21: 381000 | E21: 435000 | F21: 405000 | G21: 443000 | H21: 431000 | I21: 399000 | J21: 440000 | K21: 412000 | L21: 425000 | M21: 390000 | N21: 440000 | O21: =SUM(C21:N21) -> 4969000
A22: COGS: Midstream energy | B22: Cost | C22: 367000 | D22: 372000 | E22: 413000 | F22: 412000 | G22: 448000 | H22: 419000 | I22: 395000 | J22: 434000 | K22: 438000 | L22: 465000 | M22: 428000 | N22: 481500 | O22: =SUM(C22:N22) -> 5072500
A23: COGS: Industrial OEM | B23: Cost | C23: 256000 | D23: 262000 | E23: 301000 | F23: 274000 | G23: 309000 | H23: 288000 | I23: 272000 | J23: 287000 | K23: 283000 | L23: 303000 | M23: 278000 | N23: 314000 | O23: =SUM(C23:N23) -> 3427000
A24: Officer compensation | B24: Cost | C24: 38333 | D24: 38333 | E24: 38333 | F24: 38333 | G24: 38333 | H24: 38333 | I24: 38333 | J24: 38333 | K24: 38333 | L24: 38333 | M24: 38333 | N24: 38334 | O24: =SUM(C24:N24) -> 459997
A25: Other SG&A | B25: Cost | C25: 172000 | D25: 177000 | E25: 171000 | F25: 180000 | G25: 181000 | H25: 178000 | I25: 183000 | J25: 175000 | K25: 180000 | L25: 174000 | M25: 174000 | N25: 175000 | O25: =SUM(C25:N25) -> 2120000
A26: Depreciation & amortization | B26: Cost | C26: 58000 | D26: 58000 | E26: 58500 | F26: 58500 | G26: 59000 | H26: 59000 | I26: 59000 | J26: 59500 | K26: 59500 | L26: 59500 | M26: 59500 | N26: 59500 | O26: =SUM(C26:N26) -> 707500
A27: Interest expense | B27: Cost | C27: 14300 | D27: 14200 | E27: 14250 | F27: 14300 | G27: 14200 | H27: 14150 | I27: 14100 | J27: 14200 | K27: 14150 | L27: 14200 | M27: 14200 | N27: 14200 | O27: =SUM(C27:N27) -> 170450
A29: Month-end balances (actual)
A30: Accounts receivable | C30: 2180000 | D30: 2230000 | E30: 2310000 | F30: 2290000 | G30: 2350000 | H30: 2410000 | I30: 2330000 | J30: 2420000 | K30: 2460000
A31: Inventory | C31: 1650000 | D31: 1690000 | E31: 1720000 | F31: 1700000 | G31: 1760000 | H31: 1780000 | I31: 1740000 | J31: 1790000 | K31: 1810000
A32: Accounts payable | C32: 1150000 | D32: 1170000 | E32: 1210000 | F32: 1190000 | G32: 1230000 | H32: 1250000 | I32: 1200000 | J32: 1240000 | K32: 1260000
A33: Backlog | C33: 6900000 | D33: 7100000 | E33: 7300000 | F33: 7200000 | G33: 7500000 | H33: 7700000 | I33: 7600000 | J33: 7800000 | K33: 7900000
A34: Cash (adjusted book) | C34: 598000 | D34: 571000 | E34: 552000 | F34: 610000 | G34: 566000 | H34: 548000 | I34: 602000 | J34: 598240 | K34: =Bank_Rec!C20 -> 566427.25
A35: Revolver balance | C35: 820000 | D35: 860000 | E35: 900000 | F35: 880000 | G35: 930000 | H35: 950000 | I35: 920000 | J35: 940000 | K35: 960000
A36: Term loan balance | C36: 1793000 | D36: 1747000 | E36: 1700000 | F36: 1653000 | G36: 1607000 | H36: 1560000 | I36: 1513000 | J36: 1467000 | K36: 1420000
A37: Revolver commitment | C37: 1000000 | D37: 1000000 | E37: 1000000 | F37: 1000000 | G37: 1000000 | H37: 1000000 | I37: 1000000 | J37: 1000000 | K37: 1000000

Sheet BvA
A1: Budget vs. Actual: September 2026
A2: Favorable = revenue or profit above budget, or cost below budget
B4: September | H4: Year to date
A5: Line | B5: Budget | C5: Actual | D5: Variance $ | E5: Var % | F5: F/U | H5: Budget | I5: Actual | J5: Variance $ | K5: Var % | L5: F/U
A6: Commercial construction | B6: =Monthly_Data!K6 -> 638000 | C6: =Monthly_Data!K18 -> 538000 | D6: =C6-B6 -> -100000 | E6: =IFERROR(D6/ABS(B6),0) -> -0.15673981 | F6: =IF(D6>=0,"F","U") -> U | H6: =SUM(Monthly_Data!C6:K6) -> 5647000 | I6: =SUM(Monthly_Data!C18:K18) -> 4865000 | J6: =I6-H6 -> -782000 | K6: =IFERROR(J6/ABS(H6),0) -> -0.13848061 | L6: =IF(J6>=0,"F","U") -> U
A7: Midstream energy | B7: =Monthly_Data!K7 -> 559000 | C7: =Monthly_Data!K19 -> 628000 | D7: =C7-B7 -> 69000 | E7: =IFERROR(D7/ABS(B7),0) -> 0.1234347 | F7: =IF(D7>=0,"F","U") -> F | H7: =SUM(Monthly_Data!C7:K7) -> 4942000 | I7: =SUM(Monthly_Data!C19:K19) -> 5329000 | J7: =I7-H7 -> 387000 | K7: =IFERROR(J7/ABS(H7),0) -> 0.078308377 | L7: =IF(J7>=0,"F","U") -> F
A8: Industrial OEM | B8: =Monthly_Data!K8 -> 399000 | C8: =Monthly_Data!K20 -> 389000 | D8: =C8-B8 -> -10000 | E8: =IFERROR(D8/ABS(B8),0) -> -0.025062657 | F8: =IF(D8>=0,"F","U") -> U | H8: =SUM(Monthly_Data!C8:K8) -> 3529000 | I8: =SUM(Monthly_Data!C20:K20) -> 3470000 | J8: =I8-H8 -> -59000 | K8: =IFERROR(J8/ABS(H8),0) -> -0.016718617 | L8: =IF(J8>=0,"F","U") -> U
A9: Total revenue | B9: =SUM(B6:B8) -> 1596000 | C9: =SUM(C6:C8) -> 1555000 | D9: =C9-B9 -> -41000 | E9: =IFERROR(D9/ABS(B9),0) -> -0.025689223 | F9: =IF(D9>=0,"F","U") -> U | H9: =SUM(H6:H8) -> 14118000 | I9: =SUM(I6:I8) -> 13664000 | J9: =I9-H9 -> -454000 | K9: =IFERROR(J9/ABS(H9),0) -> -0.032157529 | L9: =IF(J9>=0,"F","U") -> U
A10: COGS: Commercial construction | B10: =Monthly_Data!K9 -> 475000 | C10: =Monthly_Data!K21 -> 412000 | D10: =C10-B10 -> -63000 | E10: =IFERROR(D10/ABS(B10),0) -> -0.13263158 | F10: =IF(D10<=0,"F","U") -> F | H10: =SUM(Monthly_Data!C9:K9) -> 4206000 | I10: =SUM(Monthly_Data!C21:K21) -> 3714000 | J10: =I10-H10 -> -492000 | K10: =IFERROR(J10/ABS(H10),0) -> -0.11697575 | L10: =IF(J10<=0,"F","U") -> F
A11: COGS: Midstream energy | B11: =Monthly_Data!K10 -> 391000 | C11: =Monthly_Data!K22 -> 438000 | D11: =C11-B11 -> 47000 | E11: =IFERROR(D11/ABS(B11),0) -> 0.1202046 | F11: =IF(D11<=0,"F","U") -> U | H11: =SUM(Monthly_Data!C10:K10) -> 3457000 | I11: =SUM(Monthly_Data!C22:K22) -> 3698000 | J11: =I11-H11 -> 241000 | K11: =IFERROR(J11/ABS(H11),0) -> 0.069713625 | L11: =IF(J11<=0,"F","U") -> U
A12: COGS: Industrial OEM | B12: =Monthly_Data!K11 -> 290000 | C12: =Monthly_Data!K23 -> 283000 | D12: =C12-B12 -> -7000 | E12: =IFERROR(D12/ABS(B12),0) -> -0.024137931 | F12: =IF(D12<=0,"F","U") -> F | H12: =SUM(Monthly_Data!C11:K11) -> 2568000 | I12: =SUM(Monthly_Data!C23:K23) -> 2532000 | J12: =I12-H12 -> -36000 | K12: =IFERROR(J12/ABS(H12),0) -> -0.014018692 | L12: =IF(J12<=0,"F","U") -> F
A13: Total cost of goods sold | B13: =SUM(B10:B12) -> 1156000 | C13: =SUM(C10:C12) -> 1133000 | D13: =C13-B13 -> -23000 | E13: =IFERROR(D13/ABS(B13),0) -> -0.019896194 | F13: =IF(D13<=0,"F","U") -> F | H13: =SUM(H10:H12) -> 10231000 | I13: =SUM(I10:I12) -> 9944000 | J13: =I13-H13 -> -287000 | K13: =IFERROR(J13/ABS(H13),0) -> -0.028051999 | L13: =IF(J13<=0,"F","U") -> F
A14: Gross profit | B14: =B9-B13 -> 440000 | C14: =C9-C13 -> 422000 | D14: =C14-B14 -> -18000 | E14: =IFERROR(D14/ABS(B14),0) -> -0.040909091 | F14: =IF(D14>=0,"F","U") -> U | H14: =H9-H13 -> 3887000 | I14: =I9-I13 -> 3720000 | J14: =I14-H14 -> -167000 | K14: =IFERROR(J14/ABS(H14),0) -> -0.042963725 | L14: =IF(J14>=0,"F","U") -> U
A15: Gross margin % | B15: =B14/B9 -> 0.27568922 | C15: =C14/C9 -> 0.27138264 | D15: =C15-B15 -> -0.0043065864 | F15: =IF(D15>=0,"F","U") -> U | H15: =H14/H9 -> 0.27532228 | I15: =I14/I9 -> 0.27224824 | J15: =I15-H15 -> -0.00307404 | L15: =IF(J15>=0,"F","U") -> U
A16: Officer compensation | B16: =Monthly_Data!K12 -> 38333 | C16: =Monthly_Data!K24 -> 38333 | D16: =C16-B16 -> 0 | E16: =IFERROR(D16/ABS(B16),0) -> 0 | F16: =IF(D16<=0,"F","U") -> F | H16: =SUM(Monthly_Data!C12:K12) -> 344997 | I16: =SUM(Monthly_Data!C24:K24) -> 344997 | J16: =I16-H16 -> 0 | K16: =IFERROR(J16/ABS(H16),0) -> 0 | L16: =IF(J16<=0,"F","U") -> F
A17: Other SG&A | B17: =Monthly_Data!K13 -> 179000 | C17: =Monthly_Data!K25 -> 180000 | D17: =C17-B17 -> 1000 | E17: =IFERROR(D17/ABS(B17),0) -> 0.0055865922 | F17: =IF(D17<=0,"F","U") -> U | H17: =SUM(Monthly_Data!C13:K13) -> 1611000 | I17: =SUM(Monthly_Data!C25:K25) -> 1597000 | J17: =I17-H17 -> -14000 | K17: =IFERROR(J17/ABS(H17),0) -> -0.0086902545 | L17: =IF(J17<=0,"F","U") -> F
A18: EBITDA | B18: =B14-B16-B17 -> 222667 | C18: =C14-C16-C17 -> 203667 | D18: =C18-B18 -> -19000 | E18: =IFERROR(D18/ABS(B18),0) -> -0.085329214 | F18: =IF(D18>=0,"F","U") -> U | H18: =H14-H16-H17 -> 1931003 | I18: =I14-I16-I17 -> 1778003 | J18: =I18-H18 -> -153000 | K18: =IFERROR(J18/ABS(H18),0) -> -0.079233435 | L18: =IF(J18>=0,"F","U") -> U
A19: EBITDA margin % | B19: =B18/B9 -> 0.13951566 | C19: =C18/C9 -> 0.13097556 | D19: =C19-B19 -> -0.0085401015 | F19: =IF(D19>=0,"F","U") -> U | H19: =H18/H9 -> 0.13677596 | I19: =I18/I9 -> 0.13012317 | J19: =I19-H19 -> -0.0066527894 | L19: =IF(J19>=0,"F","U") -> U
A20: Depreciation & amortization | B20: =Monthly_Data!K14 -> 60000 | C20: =Monthly_Data!K26 -> 59500 | D20: =C20-B20 -> -500 | E20: =IFERROR(D20/ABS(B20),0) -> -0.0083333333 | F20: =IF(D20<=0,"F","U") -> F | H20: =SUM(Monthly_Data!C14:K14) -> 540000 | I20: =SUM(Monthly_Data!C26:K26) -> 529000 | J20: =I20-H20 -> -11000 | K20: =IFERROR(J20/ABS(H20),0) -> -0.02037037 | L20: =IF(J20<=0,"F","U") -> F
A21: Interest expense | B21: =Monthly_Data!K15 -> 14500 | C21: =Monthly_Data!K27 -> 14150 | D21: =C21-B21 -> -350 | E21: =IFERROR(D21/ABS(B21),0) -> -0.024137931 | F21: =IF(D21<=0,"F","U") -> F | H21: =SUM(Monthly_Data!C15:K15) -> 130500 | I21: =SUM(Monthly_Data!C27:K27) -> 127850 | J21: =I21-H21 -> -2650 | K21: =IFERROR(J21/ABS(H21),0) -> -0.020306513 | L21: =IF(J21<=0,"F","U") -> F
A22: Net income | B22: =B18-B20-B21 -> 148167 | C22: =C18-C20-C21 -> 130017 | D22: =C22-B22 -> -18150 | E22: =IFERROR(D22/ABS(B22),0) -> -0.12249691 | F22: =IF(D22>=0,"F","U") -> U | H22: =H18-H20-H21 -> 1260503 | I22: =I18-I20-I21 -> 1121153 | J22: =I22-H22 -> -139350 | K22: =IFERROR(J22/ABS(H22),0) -> -0.11055111 | L22: =IF(J22>=0,"F","U") -> U
A24: Commentary (YTD)
A25: Revenue is 3.2% below budget. Commercial construction is the shortfall (-13.8%) as higher rates and steel prices delayed two warehouse projects; midstream energy is ahead of budget (+7.8%) on pipe support and skid work.
A26: Gross margin is 30 bps below budget. Construction margin fell to 23.7% on fixed-price jobs bid before steel prices rose; energy margin beat budget.
A27: Other SG&A is slightly under budget from hiring timing. EBITDA is below budget, driven almost entirely by construction volume and margin.

Sheet Margin_Bridge
A1: YTD Gross Profit and EBITDA Bridge
A2: Volume variance = revenue variance x budget margin. Rate variance = margin variance x actual revenue.
A4: End market | B4: Budget revenue | C4: Actual revenue | D4: Budget GM % | E4: Actual GM % | F4: Budget GP | G4: Actual GP | H4: Volume variance | I4: Rate variance
A5: Commercial construction | B5: =BvA!H6 -> 5647000 | C5: =BvA!I6 -> 4865000 | D5: =F5/B5 -> 0.25517974 | E5: =G5/C5 -> 0.23658787 | F5: =BvA!H6-BvA!H10 -> 1441000 | G5: =BvA!I6-BvA!I10 -> 1151000 | H5: =(C5-B5)*D5 -> -199550.56 | I5: =(E5-D5)*C5 -> -90449.442
A6: Midstream energy | B6: =BvA!H7 -> 4942000 | C6: =BvA!I7 -> 5329000 | D6: =F6/B6 -> 0.30048563 | E6: =G6/C6 -> 0.30606117 | F6: =BvA!H7-BvA!H11 -> 1485000 | G6: =BvA!I7-BvA!I11 -> 1631000 | H6: =(C6-B6)*D6 -> 116287.94 | I6: =(E6-D6)*C6 -> 29712.06
A7: Industrial OEM | B7: =BvA!H8 -> 3529000 | C7: =BvA!I8 -> 3470000 | D7: =F7/B7 -> 0.2723151 | E7: =G7/C7 -> 0.270317 | F7: =BvA!H8-BvA!H12 -> 961000 | G7: =BvA!I8-BvA!I12 -> 938000 | H7: =(C7-B7)*D7 -> -16066.591 | I7: =(E7-D7)*C7 -> -6933.4089
A8: Total | B8: =SUM(B5:B7) -> 14118000 | C8: =SUM(C5:C7) -> 13664000 | D8: =F8/B8 -> 0.27532228 | E8: =G8/C8 -> 0.27224824 | F8: =SUM(F5:F7) -> 3887000 | G8: =SUM(G5:G7) -> 3720000 | H8: =SUM(H5:H7) -> -99329.209 | I8: =SUM(I5:I7) -> -67670.791
A9: Check: volume + rate = GP variance (must be zero) | I9: =H8+I8-(G8-F8) -> 0
A11: EBITDA bridge (YTD) | B11: Amount
A12: Budget EBITDA | B12: =BvA!H18 -> 1931003
A13: Revenue volume | B13: =H8 -> -99329.209
A14: Gross margin rate | B14: =I8 -> -67670.791
A15: Officer compensation | B15: =-BvA!J16 -> 0
A16: Other SG&A | B16: =-BvA!J17 -> 14000
A17: Actual EBITDA | B17: =SUM(B12:B16) -> 1778003
A18: Check vs BvA (must be zero) | B18: =B17-BvA!I18 -> 0
A20: Construction volume is the largest single driver; energy volume partly offsets it. Margin rate is negative overall because construction's rate loss outweighs energy's gain.

Sheet FY_Forecast
A1: Full-Year Forecast vs. Budget
A2: Forecast = January to September actual + October to December forecast
A4: Line | B4: FY budget | C4: YTD actual | D4: Q4 forecast | E4: FY forecast | F4: Variance $ | G4: Var % | H4: F/U
A5: Revenue | B5: =SUM(Monthly_Data!C6:N6)+SUM(Monthly_Data!C7:N7)+SUM(Monthly_Data!C8:N8) -> 19000000 | C5: =SUM(Monthly_Data!C18:K18)+SUM(Monthly_Data!C19:K19)+SUM(Monthly_Data!C20:K20) -> 13664000 | D5: =SUM(Monthly_Data!L18:N18)+SUM(Monthly_Data!L19:N19)+SUM(Monthly_Data!L20:N20) -> 4786000 | E5: =C5+D5 -> 18450000 | F5: =E5-B5 -> -550000 | G5: =IFERROR(F5/ABS(B5),0) -> -0.028947368 | H5: =IF(F5>=0,"F","U") -> U
A6: Cost of goods sold | B6: =SUM(Monthly_Data!C9:N9)+SUM(Monthly_Data!C10:N10)+SUM(Monthly_Data!C11:N11) -> 13771000 | C6: =SUM(Monthly_Data!C21:K21)+SUM(Monthly_Data!C22:K22)+SUM(Monthly_Data!C23:K23) -> 9944000 | D6: =SUM(Monthly_Data!L21:N21)+SUM(Monthly_Data!L22:N22)+SUM(Monthly_Data!L23:N23) -> 3524500 | E6: =C6+D6 -> 13468500 | F6: =E6-B6 -> -302500 | G6: =IFERROR(F6/ABS(B6),0) -> -0.021966451 | H6: =IF(F6<=0,"F","U") -> F
A7: Gross profit | B7: =B5-B6 -> 5229000 | C7: =C5-C6 -> 3720000 | D7: =D5-D6 -> 1261500 | E7: =C7+D7 -> 4981500 | F7: =E7-B7 -> -247500 | G7: =IFERROR(F7/ABS(B7),0) -> -0.047332186 | H7: =IF(F7>=0,"F","U") -> U
A8: Gross margin % | B8: =B7/B5 -> 0.27521053 | C8: =C7/C5 -> 0.27224824 | D8: =D7/D5 -> 0.26358128 | E8: =E7/E5 -> 0.27 | F8: =E8-B8 -> -0.0052105263 | H8: =IF(F8>=0,"F","U") -> U
A9: Officer compensation | B9: =SUM(Monthly_Data!C12:N12) -> 460000 | C9: =SUM(Monthly_Data!C24:K24) -> 344997 | D9: =SUM(Monthly_Data!L24:N24) -> 115000 | E9: =C9+D9 -> 459997 | F9: =E9-B9 -> -3 | G9: =IFERROR(F9/ABS(B9),0) -> -6.5217391e-06 | H9: =IF(F9<=0,"F","U") -> F
A10: Other SG&A | B10: =SUM(Monthly_Data!C13:N13) -> 2150000 | C10: =SUM(Monthly_Data!C25:K25) -> 1597000 | D10: =SUM(Monthly_Data!L25:N25) -> 523000 | E10: =C10+D10 -> 2120000 | F10: =E10-B10 -> -30000 | G10: =IFERROR(F10/ABS(B10),0) -> -0.013953488 | H10: =IF(F10<=0,"F","U") -> F
A11: EBITDA | B11: =B7-B9-B10 -> 2619000 | C11: =C7-C9-C10 -> 1778003 | D11: =D7-D9-D10 -> 623500 | E11: =C11+D11 -> 2401503 | F11: =E11-B11 -> -217497 | G11: =IFERROR(F11/ABS(B11),0) -> -0.083045819 | H11: =IF(F11>=0,"F","U") -> U
A12: Depreciation & amortization | B12: =SUM(Monthly_Data!C14:N14) -> 720000 | C12: =SUM(Monthly_Data!C26:K26) -> 529000 | D12: =SUM(Monthly_Data!L26:N26) -> 178500 | E12: =C12+D12 -> 707500 | F12: =E12-B12 -> -12500 | G12: =IFERROR(F12/ABS(B12),0) -> -0.017361111 | H12: =IF(F12<=0,"F","U") -> F
A13: Interest expense | B13: =SUM(Monthly_Data!C15:N15) -> 174000 | C13: =SUM(Monthly_Data!C27:K27) -> 127850 | D13: =SUM(Monthly_Data!L27:N27) -> 42600 | E13: =C13+D13 -> 170450 | F13: =E13-B13 -> -3550 | G13: =IFERROR(F13/ABS(B13),0) -> -0.020402299 | H13: =IF(F13<=0,"F","U") -> F
A14: Net income | B14: =B11-B12-B13 -> 1725000 | C14: =C11-C12-C13 -> 1121153 | D14: =D11-D12-D13 -> 402400 | E14: =C14+D14 -> 1523553 | F14: =E14-B14 -> -201447 | G14: =IFERROR(F14/ABS(B14),0) -> -0.11678087 | H14: =IF(F14>=0,"F","U") -> U
A16: FY forecast revenue growth vs FY2025 ($17.6MM) | E16: =E5/17600000-1 -> 0.048295455
A17: Q4 forecast assumes steel stays near a four-year high, so Q4 gross margin is held at about 26.4%. These figures feed FY2026E in Three_Statement_Model.xlsx.

Sheet GL_Cash
A1: General Ledger: Operating Cash, September 2026
A2: Match = same reference and amount found on the other side. Unmatched items need a reconciling item type.
A4: Date | B4: Reference | C4: Description | D4: Amount | E4: Match | F4: Reconciling item type
A5: 46266 | B5: ACH-RENT | C5: Rent: Bayou Industrial Properties | D5: -42000 | E5: =IF(COUNTIFS(Bank_Stmt!$B$5:$B$70,B5,Bank_Stmt!$D$5:$D$70,D5)>0,"Matched","Unmatched") -> Matched
A6: 46266 | B6: ACH-RLINT | C6: Revolver interest, August | D6: -5290 | E6: =IF(COUNTIFS(Bank_Stmt!$B$5:$B$70,B6,Bank_Stmt!$D$5:$D$70,D6)>0,"Matched","Unmatched") -> Matched
A7: 46266 | B7: DEP-010 | C7: Customer payment: Gulf Ridge Builders | D7: 47181.59 | E7: =IF(COUNTIFS(Bank_Stmt!$B$5:$B$70,B7,Bank_Stmt!$D$5:$D$70,D7)>0,"Matched","Unmatched") -> Matched
A8: 46267 | B8: DEP-021 | C8: Customer payment: Ironclad Midstream | D8: 68007.59 | E8: =IF(COUNTIFS(Bank_Stmt!$B$5:$B$70,B8,Bank_Stmt!$D$5:$D$70,D8)>0,"Matched","Unmatched") -> Matched
A9: 46268 | B9: CHK-10450 | C9: Check 10450: Airgas | D9: -11250 | E9: =IF(COUNTIFS(Bank_Stmt!$B$5:$B$70,B9,Bank_Stmt!$D$5:$D$70,D9)>0,"Matched","Unmatched") -> Matched
A10: 46268 | B10: DEP-032 | C10: Customer payment: Sabine Process Systems | D10: 56156.95 | E10: =IF(COUNTIFS(Bank_Stmt!$B$5:$B$70,B10,Bank_Stmt!$D$5:$D$70,D10)>0,"Matched","Unmatched") -> Matched
A11: 46269 | B11: ACH-NUC1 | C11: Steel purchase: Gulf States Steel | D11: -148600 | E11: =IF(COUNTIFS(Bank_Stmt!$B$5:$B$70,B11,Bank_Stmt!$D$5:$D$70,D11)>0,"Matched","Unmatched") -> Matched
A12: 46269 | B12: CHK-10451 | C12: Check 10451: Grainger | D12: -8930.4 | E12: =IF(COUNTIFS(Bank_Stmt!$B$5:$B$70,B12,Bank_Stmt!$D$5:$D$70,D12)>0,"Matched","Unmatched") -> Matched
A13: 46269 | B13: DEP-040 | C13: Customer payment: Westfield Contractors | D13: 72066.56 | E13: =IF(COUNTIFS(Bank_Stmt!$B$5:$B$70,B13,Bank_Stmt!$D$5:$D$70,D13)>0,"Matched","Unmatched") -> Matched
A14: 46270 | B14: CHK-10452 | C14: Check 10452: Fastenal | D14: -23410 | E14: =IF(COUNTIFS(Bank_Stmt!$B$5:$B$70,B14,Bank_Stmt!$D$5:$D$70,D14)>0,"Matched","Unmatched") -> Matched
A15: 46271 | B15: CHK-10453 | C15: Check 10453: Lincoln Electric | D15: -4120.75 | E15: =IF(COUNTIFS(Bank_Stmt!$B$5:$B$70,B15,Bank_Stmt!$D$5:$D$70,D15)>0,"Matched","Unmatched") -> Matched
A16: 46272 | B16: CHK-10454 | C16: Check 10454: Hilti | D16: -15600 | E16: =IF(COUNTIFS(Bank_Stmt!$B$5:$B$70,B16,Bank_Stmt!$D$5:$D$70,D16)>0,"Matched","Unmatched") -> Matched
... A21: 46275 | B21: ACH-UTIL | C21: Electric: CenterPoint / retail provider | D21: -18420 | E21: =IF(COUNTIFS(Bank_Stmt!$B$5:$B$70,B21,Bank_Stmt!$D$5:$D$70,D21)>0,"Matched","Unmatched") -> Matched
A22: 46275 | B22: CHK-10457 | C22: Check 10457: Western Hydraulics (recorded as $4,850.00) | D22: -4850 | E22: =IF(COUNTIFS(Bank_Stmt!$B$5:$B$70,B22,Bank_Stmt!$D$5:$D$70,D22)>0,"Matched","Unmatched") -> Unmatched | F22: Book error
A23: 46275 | B23: DEP-100 | C23: Customer payment: Lonestar OEM Components | D23: 31895.42 | E23: =IF(COUNTIFS(Bank_Stmt!$B$5:$B$70,B23,Bank_Stmt!$D$5:$D$70,D23)>0,"Matched","Unmatched") -> Matched
A24: 46276 | B24: CHK-10458 | C24: Check 10458: Sunbelt Rentals | D24: -6240 | E24: =IF(COUNTIFS(Bank_Stmt!$B$5:$B$70,B24,Bank_Stmt!$D$5:$D$70,D24)>0,"Matched","Unmatched") -> Matched
A25: 46276 | B25: DEP-111 | C25: Customer payment: Tri-County Erectors | D25: 87947.9 | E25: =IF(COUNTIFS(Bank_Stmt!$B$5:$B$70,B25,Bank_Stmt!$D$5:$D$70,D25)>0,"Matched","Unmatched") -> Matched
A26: 46276 | B26: PAY-0911 | C26: Payroll funding (Paychex) | D26: -249850 | E26: =IF(COUNTIFS(Bank_Stmt!$B$5:$B$70,B26,Bank_Stmt!$D$5:$D$70,D26)>0,"Matched","Unmatched") -> Matched
A27: 46277 | B27: CHK-10459 | C27: Check 10459: Machine Tool Services | D27: -12880 | E27: =IF(COUNTIFS(Bank_Stmt!$B$5:$B$70,B27,Bank_Stmt!$D$5:$D$70,D27)>0,"Matched","Unmatched") -> Matched
A28: 46278 | B28: CHK-10460 | C28: Check 10460: Texas Laser Cutting Co. | D28: -18990.25 | E28: =IF(COUNTIFS(Bank_Stmt!$B$5:$B$70,B28,Bank_Stmt!$D$5:$D$70,D28)>0,"Matched","Unmatched") -> Matched
A29: 46279 | B29: ACH-NUC2 | C29: Steel purchase: Gulf States Steel | D29: -162300 | E29: =IF(COUNTIFS(Bank_Stmt!$B$5:$B$70,B29,Bank_Stmt!$D$5:$D$70,D29)>0,"Matched","Unmatched") -> Matched
A30: 46279 | B30: CHK-10461 | C30: Check 10461: Uline | D30: -7450 | E30: =IF(COUNTIFS(Bank_Stmt!$B$5:$B$70,B30,Bank_Stmt!$D$5:$D$70,D30)>0,"Matched","Unmatched") -> Matched
A31: 46279 | B31: DEP-142 | C31: Customer payment: Harbor Industrial Supply | D31: 48636.07 | E31: =IF(COUNTIFS(Bank_Stmt!$B$5:$B$70,B31,Bank_Stmt!$D$5:$D$70,D31)>0,"Matched","Unmatched") -> Matched
A32: 46280 | B32: ACH-TERM | C32: Term loan payment | D32: -54000 | E32: =IF(COUNTIFS(Bank_Stmt!$B$5:$B$70,B32,Bank_Stmt!$D$5:$D$70,D32)>0,"Matched","Unmatched") -> Matched
A33: 46280 | B33: CHK-10462 | C33: Check 10462: Industrial Paint Supply | D33: -26300 | E33: =IF(COUNTIFS(Bank_Stmt!$B$5:$B$70,B33,Bank_Stmt!$D$5:$D$70,D33)>0,"Matched","Unmatched") -> Matched
A34: 46280 | B34: DEP-150 | C34: Customer payment: Redline Compression | D34: 46934.51 | E34: =IF(COUNTIFS(Bank_Stmt!$B$5:$B$70,B34,Bank_Stmt!$D$5:$D$70,D34)>0,"Matched","Unmatched") -> Matched
... A47: 46290 | B47: PAY-0925 | C47: Payroll funding (Paychex) | D47: -251420 | E47: =IF(COUNTIFS(Bank_Stmt!$B$5:$B$70,B47,Bank_Stmt!$D$5:$D$70,D47)>0,"Matched","Unmatched") -> Matched
A48: 46291 | B48: CHK-10464 | C48: Check 10464: Texas Laser Cutting Co. | D48: -38215 | E48: =IF(COUNTIFS(Bank_Stmt!$B$5:$B$70,B48,Bank_Stmt!$D$5:$D$70,D48)>0,"Matched","Unmatched") -> Unmatched | F48: Outstanding check
A49: 46293 | B49: ACH-NUC3 | C49: Steel purchase: Gulf States Steel | D49: -139750 | E49: =IF(COUNTIFS(Bank_Stmt!$B$5:$B$70,B49,Bank_Stmt!$D$5:$D$70,D49)>0,"Matched","Unmatched") -> Matched
A50: 46293 | B50: CHK-10465 | C50: Check 10465: Fastenal | D50: -12480.5 | E50: =IF(COUNTIFS(Bank_Stmt!$B$5:$B$70,B50,Bank_Stmt!$D$5:$D$70,D50)>0,"Matched","Unmatched") -> Unmatched | F50: Outstanding check
A51: 46293 | B51: DEP-280 | C51: Customer payment: Harbor Industrial Supply | D51: 66576.32 | E51: =IF(COUNTIFS(Bank_Stmt!$B$5:$B$70,B51,Bank_Stmt!$D$5:$D$70,D51)>0,"Matched","Unmatched") -> Matched
A52: 46294 | B52: CHK-10466 | C52: Check 10466: Precision Galvanizing | D52: -55300 | E52: =IF(COUNTIFS(Bank_Stmt!$B$5:$B$70,B52,Bank_Stmt!$D$5:$D$70,D52)>0,"Matched","Unmatched") -> Unmatched | F52: Outstanding check
A53: 46294 | B53: CHK-10467 | C53: Check 10467: Airgas | D53: -9875.42 | E53: =IF(COUNTIFS(Bank_Stmt!$B$5:$B$70,B53,Bank_Stmt!$D$5:$D$70,D53)>0,"Matched","Unmatched") -> Unmatched | F53: Outstanding check
A54: 46294 | B54: DEP-291 | C54: Customer payment: Redline Compression | D54: 81405.13 | E54: =IF(COUNTIFS(Bank_Stmt!$B$5:$B$70,B54,Bank_Stmt!$D$5:$D$70,D54)>0,"Matched","Unmatched") -> Matched
A55: 46295 | B55: CHK-10468 | C55: Check 10468: Coastal Powder Coat | D55: -32444.5 | E55: =IF(COUNTIFS(Bank_Stmt!$B$5:$B$70,B55,Bank_Stmt!$D$5:$D$70,D55)>0,"Matched","Unmatched") -> Unmatched | F55: Outstanding check
A56: 46295 | B56: DEP-0930 | C56: Customer payment: Ironclad Midstream (deposited 9/30 after cutoff) | D56: 86420 | E56: =IF(COUNTIFS(Bank_Stmt!$B$5:$B$70,B56,Bank_Stmt!$D$5:$D$70,D56)>0,"Matched","Unmatched") -> Unmatched | F56: Deposit in transit
C58: Total activity | D58: =SUM(D5:D56) -> -19710.12
...

Sheet Bank_Stmt
A1: Bank Statement: Prairie Lantern Bank Operating Account, September 2026
A2: Match = same reference and amount found on the other side. Unmatched items need a reconciling item type.
A4: Date | B4: Reference | C4: Description | D4: Amount | E4: Match | F4: Reconciling item type
A5: 46266 | B5: ACH-RENT | C5: Rent: Bayou Industrial Properties | D5: -42000 | E5: =IF(COUNTIFS(GL_Cash!$B$5:$B$70,B5,GL_Cash!$D$5:$D$70,D5)>0,"Matched","Unmatched") -> Matched
A6: 46266 | B6: ACH-RLINT | C6: Revolver interest, August | D6: -5290 | E6: =IF(COUNTIFS(GL_Cash!$B$5:$B$70,B6,GL_Cash!$D$5:$D$70,D6)>0,"Matched","Unmatched") -> Matched
A7: 46266 | B7: DEP-010 | C7: Customer payment: Gulf Ridge Builders | D7: 47181.59 | E7: =IF(COUNTIFS(GL_Cash!$B$5:$B$70,B7,GL_Cash!$D$5:$D$70,D7)>0,"Matched","Unmatched") -> Matched
A8: 46267 | B8: DEP-021 | C8: Customer payment: Ironclad Midstream | D8: 68007.59 | E8: =IF(COUNTIFS(GL_Cash!$B$5:$B$70,B8,GL_Cash!$D$5:$D$70,D8)>0,"Matched","Unmatched") -> Matched
A9: 46268 | B9: CHK-10450 | C9: Check 10450: Airgas | D9: -11250 | E9: =IF(COUNTIFS(GL_Cash!$B$5:$B$70,B9,GL_Cash!$D$5:$D$70,D9)>0,"Matched","Unmatched") -> Matched
A10: 46268 | B10: DEP-032 | C10: Customer payment: Sabine Process Systems | D10: 56156.95 | E10: =IF(COUNTIFS(GL_Cash!$B$5:$B$70,B10,GL_Cash!$D$5:$D$70,D10)>0,"Matched","Unmatched") -> Matched
A11: 46269 | B11: ACH-NUC1 | C11: Steel purchase: Gulf States Steel | D11: -148600 | E11: =IF(COUNTIFS(GL_Cash!$B$5:$B$70,B11,GL_Cash!$D$5:$D$70,D11)>0,"Matched","Unmatched") -> Matched
A12: 46269 | B12: CHK-10451 | C12: Check 10451: Grainger | D12: -8930.4 | E12: =IF(COUNTIFS(GL_Cash!$B$5:$B$70,B12,GL_Cash!$D$5:$D$70,D12)>0,"Matched","Unmatched") -> Matched
A13: 46269 | B13: DEP-040 | C13: Customer payment: Westfield Contractors | D13: 72066.56 | E13: =IF(COUNTIFS(GL_Cash!$B$5:$B$70,B13,GL_Cash!$D$5:$D$70,D13)>0,"Matched","Unmatched") -> Matched
A14: 46270 | B14: CHK-10452 | C14: Check 10452: Fastenal | D14: -23410 | E14: =IF(COUNTIFS(GL_Cash!$B$5:$B$70,B14,GL_Cash!$D$5:$D$70,D14)>0,"Matched","Unmatched") -> Matched
A15: 46271 | B15: CHK-10453 | C15: Check 10453: Lincoln Electric | D15: -4120.75 | E15: =IF(COUNTIFS(GL_Cash!$B$5:$B$70,B15,GL_Cash!$D$5:$D$70,D15)>0,"Matched","Unmatched") -> Matched
A16: 46272 | B16: CHK-10454 | C16: Check 10454: Hilti | D16: -15600 | E16: =IF(COUNTIFS(GL_Cash!$B$5:$B$70,B16,GL_Cash!$D$5:$D$70,D16)>0,"Matched","Unmatched") -> Matched
... A25: 46276 | B25: PAY-0911 | C25: Payroll funding (Paychex) | D25: -249850 | E25: =IF(COUNTIFS(GL_Cash!$B$5:$B$70,B25,GL_Cash!$D$5:$D$70,D25)>0,"Matched","Unmatched") -> Matched
A26: 46277 | B26: CHK-10457 | C26: Check 10457: Western Hydraulics | D26: -4580 | E26: =IF(COUNTIFS(GL_Cash!$B$5:$B$70,B26,GL_Cash!$D$5:$D$70,D26)>0,"Matched","Unmatched") -> Unmatched | F26: Book error
A27: 46277 | B27: CHK-10459 | C27: Check 10459: Machine Tool Services | D27: -12880 | E27: =IF(COUNTIFS(GL_Cash!$B$5:$B$70,B27,GL_Cash!$D$5:$D$70,D27)>0,"Matched","Unmatched") -> Matched
A28: 46278 | B28: CHK-10460 | C28: Check 10460: Texas Laser Cutting Co. | D28: -18990.25 | E28: =IF(COUNTIFS(GL_Cash!$B$5:$B$70,B28,GL_Cash!$D$5:$D$70,D28)>0,"Matched","Unmatched") -> Matched
A29: 46279 | B29: ACH-NUC2 | C29: Steel purchase: Gulf States Steel | D29: -162300 | E29: =IF(COUNTIFS(GL_Cash!$B$5:$B$70,B29,GL_Cash!$D$5:$D$70,D29)>0,"Matched","Unmatched") -> Matched
A30: 46279 | B30: CHK-10461 | C30: Check 10461: Uline | D30: -7450 | E30: =IF(COUNTIFS(GL_Cash!$B$5:$B$70,B30,GL_Cash!$D$5:$D$70,D30)>0,"Matched","Unmatched") -> Matched
A31: 46279 | B31: DEP-142 | C31: Customer payment: Harbor Industrial Supply | D31: 48636.07 | E31: =IF(COUNTIFS(GL_Cash!$B$5:$B$70,B31,GL_Cash!$D$5:$D$70,D31)>0,"Matched","Unmatched") -> Matched
A32: 46280 | B32: ACH-TERM | C32: Term loan payment | D32: -54000 | E32: =IF(COUNTIFS(GL_Cash!$B$5:$B$70,B32,GL_Cash!$D$5:$D$70,D32)>0,"Matched","Unmatched") -> Matched
A33: 46280 | B33: CHK-10462 | C33: Check 10462: Industrial Paint Supply | D33: -26300 | E33: =IF(COUNTIFS(GL_Cash!$B$5:$B$70,B33,GL_Cash!$D$5:$D$70,D33)>0,"Matched","Unmatched") -> Matched
A34: 46280 | B34: DEP-150 | C34: Customer payment: Redline Compression | D34: 46934.51 | E34: =IF(COUNTIFS(GL_Cash!$B$5:$B$70,B34,GL_Cash!$D$5:$D$70,D34)>0,"Matched","Unmatched") -> Matched
A35: 46281 | B35: CHK-10463 | C35: Check 10463: Safety-Kleen | D35: -5310.6 | E35: =IF(COUNTIFS(GL_Cash!$B$5:$B$70,B35,GL_Cash!$D$5:$D$70,D35)>0,"Matched","Unmatched") -> Matched
A36: 46281 | B36: DEP-161 | C36: Customer payment: Gulf Ridge Builders | D36: 98703.85 | E36: =IF(COUNTIFS(GL_Cash!$B$5:$B$70,B36,GL_Cash!$D$5:$D$70,D36)>0,"Matched","Unmatched") -> Matched
A37: 46282 | B37: DEP-172 | C37: Customer payment: Ironclad Midstream | D37: 62977.92 | E37: =IF(COUNTIFS(GL_Cash!$B$5:$B$70,B37,GL_Cash!$D$5:$D$70,D37)>0,"Matched","Unmatched") -> Matched
A38: 46282 | B38: RTN-0917 | C38: Returned item: Gulf Ridge Builders check (NSF) | D38: -12600 | E38: =IF(COUNTIFS(GL_Cash!$B$5:$B$70,B38,GL_Cash!$D$5:$D$70,D38)>0,"Matched","Unmatched") -> Unmatched | F38: NSF check
A39: 46283 | B39: ACH-INS | C39: Insurance installment | D39: -21600 | E39: =IF(COUNTIFS(GL_Cash!$B$5:$B$70,B39,GL_Cash!$D$5:$D$70,D39)>0,"Matched","Unmatched") -> Matched
A40: 46283 | B40: DEP-180 | C40: Customer payment: Sabine Process Systems | D40: 87879.38 | E40: =IF(COUNTIFS(GL_Cash!$B$5:$B$70,B40,GL_Cash!$D$5:$D$70,D40)>0,"Matched","Unmatched") -> Matched
A41: 46285 | B41: ACH-FUEL | C41: Fuel cards | D41: -6840 | E41: =IF(COUNTIFS(GL_Cash!$B$5:$B$70,B41,GL_Cash!$D$5:$D$70,D41)>0,"Matched","Unmatched") -> Matched
A42: 46286 | B42: DEP-211 | C42: Customer payment: Westfield Contractors | D42: 63392.02 | E42: =IF(COUNTIFS(GL_Cash!$B$5:$B$70,B42,GL_Cash!$D$5:$D$70,D42)>0,"Matched","Unmatched") -> Matched
A43: 46287 | B43: ADV-0922 | C43: Revolver advance | D43: 20000 | E43: =IF(COUNTIFS(GL_Cash!$B$5:$B$70,B43,GL_Cash!$D$5:$D$70,D43)>0,"Matched","Unmatched") -> Matched
A44: 46287 | B44: DEP-222 | C44: Customer payment: Pinnacle Pipeline Services | D44: 74456.63 | E44: =IF(COUNTIFS(GL_Cash!$B$5:$B$70,B44,GL_Cash!$D$5:$D$70,D44)>0,"Matched","Unmatched") -> Matched
A45: 46288 | B45: DEP-230 | C45: Customer payment: Coastal Mechanical | D45: 41241.92 | E45: =IF(COUNTIFS(GL_Cash!$B$5:$B$70,B45,GL_Cash!$D$5:$D$70,D45)>0,"Matched","Unmatched") -> Matched
A46: 46289 | B46: DEP-241 | C46: Customer payment: Lonestar OEM Components | D46: 74170.52 | E46: =IF(COUNTIFS(GL_Cash!$B$5:$B$70,B46,GL_Cash!$D$5:$D$70,D46)>0,"Matched","Unmatched") -> Matched
A47: 46290 | B47: DEP-252 | C47: Customer payment: Tri-County Erectors | D47: 90027.08 | E47: =IF(COUNTIFS(GL_Cash!$B$5:$B$70,B47,GL_Cash!$D$5:$D$70,D47)>0,"Matched","Unmatched") -> Matched
A48: 46290 | B48: PAY-0925 | C48: Payroll funding (Paychex) | D48: -251420 | E48: =IF(COUNTIFS(GL_Cash!$B$5:$B$70,B48,GL_Cash!$D$5:$D$70,D48)>0,"Matched","Unmatched") -> Matched
A49: 46293 | B49: ACH-NUC3 | C49: Steel purchase: Gulf States Steel | D49: -139750 | E49: =IF(COUNTIFS(GL_Cash!$B$5:$B$70,B49,GL_Cash!$D$5:$D$70,D49)>0,"Matched","Unmatched") -> Matched
...

Sheet Bank_Rec
A1: Bank Reconciliation: September 30, 2026
A2: Operating account at Prairie Lantern Bank. Prepared by M. Dial, reviewed by Controller.
A4: Beginning balance, August 31 (bank and book agreed) | C4: 598240
A6: Bank side | C6: Amount | E6: Notes
A7: Balance per bank statement, 9/30 | C7: =C4+Bank_Stmt!D55 -> 628322.67
A8: Add: deposits in transit | C8: =SUMIFS(GL_Cash!$D$5:$D$56,GL_Cash!$F$5:$F$56,"Deposit in transit") -> 86420 | E8: 9/30 deposit made after bank cutoff; cleared 10/1
A9: Less: outstanding checks | C9: =SUMIFS(GL_Cash!$D$5:$D$56,GL_Cash!$F$5:$F$56,"Outstanding check") -> -148315.42 | E9: Checks 10464 to 10468
A10: Adjusted bank balance | C10: =SUM(C7:C9) -> 566427.25
A12: Book side | C12: Amount | E12: Notes
A13: Balance per general ledger, 9/30 | C13: =C4+GL_Cash!D58 -> 578529.88
A14: Add: interest earned not recorded | C14: =SUMIFS(Bank_Stmt!$D$5:$D$53,Bank_Stmt!$F$5:$F$53,"Interest income") -> 412.37
A15: Less: bank service charges | C15: =SUMIFS(Bank_Stmt!$D$5:$D$53,Bank_Stmt!$F$5:$F$53,"Bank fee") -> -185
A16: Less: NSF customer check returned | C16: =SUMIFS(Bank_Stmt!$D$5:$D$53,Bank_Stmt!$F$5:$F$53,"NSF check") -> -12600 | E16: Gulf Ridge Builders; re-billed and placed on credit hold
A17: Add: correction of check 10457 recorded in error | C17: =SUMIFS(Bank_Stmt!$D$5:$D$53,Bank_Stmt!$F$5:$F$53,"Book error")-SUMIFS(GL_Cash!$D$5:$D$56,GL_Cash!$F$5:$F$56,"Book error") -> 270 | E17: Recorded $4,850.00; cleared bank at $4,580.00 (transposition)
A18: Adjusted book balance | C18: =SUM(C13:C17) -> 566427.25
A20: Reconciled cash balance | C20: =C18 -> 566427.25
A21: Difference (must be zero) | C21: =C10-C18 -> 0
A22: Unmatched items without a type (must be zero) | C22: =GL_Cash!D59+Bank_Stmt!D56 -> 0
A24: Proposed adjusting journal entries | C24: Debit | E24: Credit
A25: JE 1: Dr Cash / Cr Interest income | C25: =C14 -> 412.37 | E25: =C14 -> 412.37
A26: JE 2: Dr Bank fees expense / Cr Cash | C26: =-C15 -> 185 | E26: =-C15 -> 185
A27: JE 3: Dr Accounts receivable (Gulf Ridge) / Cr Cash | C27: =-C16 -> 12600 | E27: =-C16 -> 12600
A28: JE 4: Dr Cash / Cr Accounts payable (Western Hydraulics) | C28: =C17 -> 270 | E28: =C17 -> 270
A29: Net change to book cash from entries | C29: =C14+C15+C16+C17 -> -12102.63

Sheet KPI_Trend
A1: KPI Trend: January to September 2026
A2: DSO and DIO use trailing three months annualized (months 1 and 2 use available months)
A4: KPI | C4: Jan-26 | D4: Feb-26 | E4: Mar-26 | F4: Apr-26 | G4: May-26 | H4: Jun-26 | I4: Jul-26 | J4: Aug-26 | K4: Sep-26 | M4: How to read it
A5: Revenue (actual) | C5: =Monthly_Data!C18+Monthly_Data!C19+Monthly_Data!C20 -> 1367000 | D5: =Monthly_Data!D18+Monthly_Data!D19+Monthly_Data!D20 -> 1393000 | E5: =Monthly_Data!E18+Monthly_Data!E19+Monthly_Data!E20 -> 1580000 | F5: =Monthly_Data!F18+Monthly_Data!F19+Monthly_Data!F20 -> 1504000 | G5: =Monthly_Data!G18+Monthly_Data!G19+Monthly_Data!G20 -> 1646000 | H5: =Monthly_Data!H18+Monthly_Data!H19+Monthly_Data!H20 -> 1565000 | I5: =Monthly_Data!I18+Monthly_Data!I19+Monthly_Data!I20 -> 1462000 | J5: =Monthly_Data!J18+Monthly_Data!J19+Monthly_Data!J20 -> 1592000 | K5: =Monthly_Data!K18+Monthly_Data!K19+Monthly_Data!K20 -> 1555000
A6: Revenue (budget) | C6: =Monthly_Data!C6+Monthly_Data!C7+Monthly_Data!C8 -> 1406000 | D6: =Monthly_Data!D6+Monthly_Data!D7+Monthly_Data!D8 -> 1463000 | E6: =Monthly_Data!E6+Monthly_Data!E7+Monthly_Data!E8 -> 1615000 | F6: =Monthly_Data!F6+Monthly_Data!F7+Monthly_Data!F8 -> 1577000 | G6: =Monthly_Data!G6+Monthly_Data!G7+Monthly_Data!G8 -> 1653000 | H6: =Monthly_Data!H6+Monthly_Data!H7+Monthly_Data!H8 -> 1634000 | I6: =Monthly_Data!I6+Monthly_Data!I7+Monthly_Data!I8 -> 1540000 | J6: =Monthly_Data!J6+Monthly_Data!J7+Monthly_Data!J8 -> 1634000 | K6: =Monthly_Data!K6+Monthly_Data!K7+Monthly_Data!K8 -> 1596000
A7: Revenue vs budget | C7: =C5/C6-1 -> -0.027738265 | D7: =D5/D6-1 -> -0.04784689 | E7: =E5/E6-1 -> -0.021671827 | F7: =F5/F6-1 -> -0.046290425 | G7: =G5/G6-1 -> -0.0042347247 | H7: =H5/H6-1 -> -0.042227662 | I7: =I5/I6-1 -> -0.050649351 | J7: =J5/J6-1 -> -0.025703794 | K7: =K5/K6-1 -> -0.025689223 | M7: Construction weakness since spring
A8: Gross margin % | C8: =1-(Monthly_Data!C21+Monthly_Data!C22+Monthly_Data!C23)/C5 -> 0.27505486 | D8: =1-(Monthly_Data!D21+Monthly_Data!D22+Monthly_Data!D23)/D5 -> 0.27135678 | E8: =1-(Monthly_Data!E21+Monthly_Data!E22+Monthly_Data!E23)/E5 -> 0.27278481 | F8: =1-(Monthly_Data!F21+Monthly_Data!F22+Monthly_Data!F23)/F5 -> 0.27460106 | G8: =1-(Monthly_Data!G21+Monthly_Data!G22+Monthly_Data!G23)/G5 -> 0.2709599 | H8: =1-(Monthly_Data!H21+Monthly_Data!H22+Monthly_Data!H23)/H5 -> 0.27284345 | I8: =1-(Monthly_Data!I21+Monthly_Data!I22+Monthly_Data!I23)/I5 -> 0.27086183 | J8: =1-(Monthly_Data!J21+Monthly_Data!J22+Monthly_Data!J23)/J5 -> 0.27072864 | K8: =1-(Monthly_Data!K21+Monthly_Data!K22+Monthly_Data!K23)/K5 -> 0.27138264
A9: EBITDA | C9: =C5-(Monthly_Data!C21+Monthly_Data!C22+Monthly_Data!C23)-Monthly_Data!C24-Monthly_Data!C25 -> 165667 | D9: =D5-(Monthly_Data!D21+Monthly_Data!D22+Monthly_Data!D23)-Monthly_Data!D24-Monthly_Data!D25 -> 162667 | E9: =E5-(Monthly_Data!E21+Monthly_Data!E22+Monthly_Data!E23)-Monthly_Data!E24-Monthly_Data!E25 -> 221667 | F9: =F5-(Monthly_Data!F21+Monthly_Data!F22+Monthly_Data!F23)-Monthly_Data!F24-Monthly_Data!F25 -> 194667 | G9: =G5-(Monthly_Data!G21+Monthly_Data!G22+Monthly_Data!G23)-Monthly_Data!G24-Monthly_Data!G25 -> 226667 | H9: =H5-(Monthly_Data!H21+Monthly_Data!H22+Monthly_Data!H23)-Monthly_Data!H24-Monthly_Data!H25 -> 210667 | I9: =I5-(Monthly_Data!I21+Monthly_Data!I22+Monthly_Data!I23)-Monthly_Data!I24-Monthly_Data!I25 -> 174667 | J9: =J5-(Monthly_Data!J21+Monthly_Data!J22+Monthly_Data!J23)-Monthly_Data!J24-Monthly_Data!J25 -> 217667 | K9: =K5-(Monthly_Data!K21+Monthly_Data!K22+Monthly_Data!K23)-Monthly_Data!K24-Monthly_Data!K25 -> 203667
A10: EBITDA margin % | C10: =C9/C5 -> 0.1211902 | D10: =D9/D5 -> 0.11677459 | E10: =E9/E5 -> 0.14029557 | F10: =F9/F5 -> 0.12943285 | G10: =G9/G5 -> 0.13770778 | H10: =H9/H5 -> 0.1346115 | I10: =I9/I5 -> 0.11947127 | J10: =J9/J5 -> 0.1367255 | K10: =K9/K5 -> 0.13097556
A11: Accounts receivable | C11: =Monthly_Data!C30 -> 2180000 | D11: =Monthly_Data!D30 -> 2230000 | E11: =Monthly_Data!E30 -> 2310000 | F11: =Monthly_Data!F30 -> 2290000 | G11: =Monthly_Data!G30 -> 2350000 | H11: =Monthly_Data!H30 -> 2410000 | I11: =Monthly_Data!I30 -> 2330000 | J11: =Monthly_Data!J30 -> 2420000 | K11: =Monthly_Data!K30 -> 2460000
A12: DSO (days) | C12: =C11/AVERAGE(C5:C5)*365/12 -> 48.506462 | D12: =D11/AVERAGE(C5:D5)*365/12 -> 49.15157 | E12: =E11/AVERAGE(C5:E5)*365/12 -> 48.568548 | F12: =F11/AVERAGE(D5:F5)*365/12 -> 46.674671 | G12: =G11/AVERAGE(E5:G5)*365/12 -> 45.335624 | H12: =H11/AVERAGE(F5:H5)*365/12 -> 46.641039 | I12: =I11/AVERAGE(G5:I5)*365/12 -> 45.498074 | J12: =J11/AVERAGE(H5:J5)*365/12 -> 47.807967 | K12: =K11/AVERAGE(I5:K5)*365/12 -> 48.703623 | M12: Drifting up since summer as construction GCs pay slower
A13: Inventory | C13: =Monthly_Data!C31 -> 1650000 | D13: =Monthly_Data!D31 -> 1690000 | E13: =Monthly_Data!E31 -> 1720000 | F13: =Monthly_Data!F31 -> 1700000 | G13: =Monthly_Data!G31 -> 1760000 | H13: =Monthly_Data!H31 -> 1780000 | I13: =Monthly_Data!I31 -> 1740000 | J13: =Monthly_Data!J31 -> 1790000 | K13: =Monthly_Data!K31 -> 1810000
A14: DIO (days) | C14: =C13/AVERAGE(C25:C25)*365/12 -> 50.64329 | D14: =D13/AVERAGE(C25:D25)*365/12 -> 51.250415 | E14: =E13/AVERAGE(C25:E25)*365/12 -> 49.746434 | F14: =F13/AVERAGE(D25:F25)*365/12 -> 47.65745 | G14: =G13/AVERAGE(E25:G25)*365/12 -> 46.686047 | H14: =H13/AVERAGE(F25:H25)*365/12 -> 47.368037 | I14: =I13/AVERAGE(G25:I25)*365/12 -> 46.643655 | J14: =J13/AVERAGE(H25:J25)*365/12 -> 48.540119 | K14: =K13/AVERAGE(I25:K25)*365/12 -> 49.155506
A15: Accounts payable | C15: =Monthly_Data!C32 -> 1150000 | D15: =Monthly_Data!D32 -> 1170000 | E15: =Monthly_Data!E32 -> 1210000 | F15: =Monthly_Data!F32 -> 1190000 | G15: =Monthly_Data!G32 -> 1230000 | H15: =Monthly_Data!H32 -> 1250000 | I15: =Monthly_Data!I32 -> 1200000 | J15: =Monthly_Data!J32 -> 1240000 | K15: =Monthly_Data!K32 -> 1260000
A16: DPO (days) | C16: =C15/AVERAGE(C25:C25)*365/12 -> 35.296838 | D16: =D15/AVERAGE(C25:D25)*365/12 -> 35.481057 | E16: =E15/AVERAGE(C25:E25)*365/12 -> 34.996038 | F16: =F15/AVERAGE(D25:F25)*365/12 -> 33.360215 | G16: =G15/AVERAGE(E25:G25)*365/12 -> 32.62718 | H16: =H15/AVERAGE(F25:H25)*365/12 -> 33.264071 | I16: =I15/AVERAGE(G25:I25)*365/12 -> 32.168038 | J16: =J15/AVERAGE(H25:J25)*365/12 -> 33.625557 | K16: =K15/AVERAGE(I25:K25)*365/12 -> 34.21875
A17: Cash conversion cycle (days) | C17: =C12+C14-C16 -> 63.852913 | D17: =D12+D14-D16 -> 64.920929 | E17: =E12+E14-E16 -> 63.318945 | F17: =F12+F14-F16 -> 60.971906 | G17: =G12+G14-G16 -> 59.39449 | H17: =H12+H14-H16 -> 60.745005 | I17: =I12+I14-I16 -> 59.973691 | J17: =J12+J14-J16 -> 62.722529 | K17: =K12+K14-K16 -> 63.640379
A18: Backlog | C18: =Monthly_Data!C33 -> 6900000 | D18: =Monthly_Data!D33 -> 7100000 | E18: =Monthly_Data!E33 -> 7300000 | F18: =Monthly_Data!F33 -> 7200000 | G18: =Monthly_Data!G33 -> 7500000 | H18: =Monthly_Data!H33 -> 7700000 | I18: =Monthly_Data!I33 -> 7600000 | J18: =Monthly_Data!J33 -> 7800000 | K18: =Monthly_Data!K33 -> 7900000 | M18: Highest of the year; energy-led
A19: Backlog / trailing 3-month revenue (months) | C19: =C18/AVERAGE(C5:C5) -> 5.0475494 | D19: =D18/AVERAGE(C5:D5) -> 5.1449275 | E19: =E18/AVERAGE(C5:E5) -> 5.0460829 | F19: =F18/AVERAGE(D5:F5) -> 4.8246594 | G19: =G18/AVERAGE(E5:G5) -> 4.756871 | H19: =H18/AVERAGE(F5:H5) -> 4.8992577 | I19: =I18/AVERAGE(G5:I5) -> 4.8790927 | J19: =J18/AVERAGE(H5:J5) -> 5.0660316 | K19: =K18/AVERAGE(I5:K5) -> 5.1421133
A20: Cash | C20: =Monthly_Data!C34 -> 598000 | D20: =Monthly_Data!D34 -> 571000 | E20: =Monthly_Data!E34 -> 552000 | F20: =Monthly_Data!F34 -> 610000 | G20: =Monthly_Data!G34 -> 566000 | H20: =Monthly_Data!H34 -> 548000 | I20: =Monthly_Data!I34 -> 602000 | J20: =Monthly_Data!J34 -> 598240 | K20: =Monthly_Data!K34 -> 566427.25 | M20: September = reconciled balance
A21: Revolver balance | C21: =Monthly_Data!C35 -> 820000 | D21: =Monthly_Data!D35 -> 860000 | E21: =Monthly_Data!E35 -> 900000 | F21: =Monthly_Data!F35 -> 880000 | G21: =Monthly_Data!G35 -> 930000 | H21: =Monthly_Data!H35 -> 950000 | I21: =Monthly_Data!I35 -> 920000 | J21: =Monthly_Data!J35 -> 940000 | K21: =Monthly_Data!K35 -> 960000
A22: Revolver availability | C22: =MIN(Monthly_Data!C37,C11*0.88*0.8+600000)-C21 -> 180000 | D22: =MIN(Monthly_Data!D37,D11*0.88*0.8+600000)-D21 -> 140000 | E22: =MIN(Monthly_Data!E37,E11*0.88*0.8+600000)-E21 -> 100000 | F22: =MIN(Monthly_Data!F37,F11*0.88*0.8+600000)-F21 -> 120000 | G22: =MIN(Monthly_Data!G37,G11*0.88*0.8+600000)-G21 -> 70000 | H22: =MIN(Monthly_Data!H37,H11*0.88*0.8+600000)-H21 -> 50000 | I22: =MIN(Monthly_Data!I37,I11*0.88*0.8+600000)-I21 -> 80000 | J22: =MIN(Monthly_Data!J37,J11*0.88*0.8+600000)-J21 -> 60000 | K22: =MIN(Monthly_Data!K37,K11*0.88*0.8+600000)-K21 -> 40000 | M22: Commitment $1.0MM until increase closes
A23: Total liquidity | C23: =C20+C22 -> 778000 | D23: =D20+D22 -> 711000 | E23: =E20+E22 -> 652000 | F23: =F20+F22 -> 730000 | G23: =G20+G22 -> 636000 | H23: =H20+H22 -> 598000 | I23: =I20+I22 -> 682000 | J23: =J20+J22 -> 658240 | K23: =K20+K22 -> 606427.25
A25: Helper: total COGS | C25: =Monthly_Data!C21+Monthly_Data!C22+Monthly_Data!C23 -> 991000 | D25: =Monthly_Data!D21+Monthly_Data!D22+Monthly_Data!D23 -> 1015000 | E25: =Monthly_Data!E21+Monthly_Data!E22+Monthly_Data!E23 -> 1149000 | F25: =Monthly_Data!F21+Monthly_Data!F22+Monthly_Data!F23 -> 1091000 | G25: =Monthly_Data!G21+Monthly_Data!G22+Monthly_Data!G23 -> 1200000 | H25: =Monthly_Data!H21+Monthly_Data!H22+Monthly_Data!H23 -> 1138000 | I25: =Monthly_Data!I21+Monthly_Data!I22+Monthly_Data!I23 -> 1066000 | J25: =Monthly_Data!J21+Monthly_Data!J22+Monthly_Data!J23 -> 1161000 | K25: =Monthly_Data!K21+Monthly_Data!K22+Monthly_Data!K23 -> 1133000
