Workbook

Sheet Cover
B2: Three-Statement Financial Model
B3: Brazos Bend Fabrication, LLC | FY2023A to FY2029P | Integrated income statement, balance sheet, and cash flow
B4: Prepared by Matthew Dial | Portfolio work sample | October 2026
B6: DISCLAIMER: Brazos Bend Fabrication, LLC and all figures are fictional and were created for portfolio demonstration only. No real company or employer data is used.
B8: Tab | C8: What it shows
B9: Assumptions | C9: Scenario selector (Base / Upside / Downside) and every driver by year
B10: Model | C10: Integrated income statement, balance sheet, and cash flow with PP&E roll-forward and balance checks
B11: Debt_Schedule | C11: Existing term loan, new $2.8MM equipment loan, and revolver with automatic draw / repay to hold minimum cash
B12: Covenants | C12: Bank covenant tests each projected year (DSCR, funded debt / EBITDA) and the distribution restriction trigger
B13: Scenario_Compare | C13: Side-by-side results for all three scenarios
B15: How to use
C16: 1. Pick a scenario in Assumptions!B4 (1 = Base, 2 = Upside, 3 = Downside).
C17: 2. Edit any blue driver. All three statements, the debt schedule, and covenants recalculate.
C18: 3. Balance sheet and cash checks on the Model tab must stay at zero.
B20: Color legend
B21: Blue text | C21: Input or assumption
B22: Black text | C22: Formula on the same sheet
B23: Green text | C23: Formula linking to another sheet
B24: Yellow fill | C24: Key output or check

Sheet Assumptions
A1: Assumptions & Scenarios
A2: FY2026E reflects the September 2026 full-year forecast (Monthly_Close_Pack). Projection years switch with the scenario selector.
A4: Active scenario (1 = Base, 2 = Upside, 3 = Downside) | B4: 1
A5: Scenario name | B5: =CHOOSE(B4,"Base","Upside","Downside") -> Base
A7: Revenue growth | G7: FY2026E | H7: FY2027P | I7: FY2028P | J7: FY2029P | K7: Notes
A8: Base | G8: =18450000/17600000-1 -> 0.048295455 | H8: 0.06 | I8: 0.05 | J8: 0.04 | K8: FY2026E per Sept forecast ($18.45MM). Downside = construction and energy recession in FY2027
A9: Upside | G9: =18450000/17600000-1 -> 0.048295455 | H9: 0.1 | I9: 0.08 | J9: 0.06
A10: Downside | G10: =18450000/17600000-1 -> 0.048295455 | H10: -0.15 | I10: -0.03 | J10: 0.04
A11: Selected | G11: =CHOOSE($B$4,G8,G9,G10) -> 0.048295455 | H11: =CHOOSE($B$4,H8,H9,H10) -> 0.06 | I11: =CHOOSE($B$4,I8,I9,I10) -> 0.05 | J11: =CHOOSE($B$4,J8,J9,J10) -> 0.04
A13: Gross margin | G13: FY2026E | H13: FY2027P | I13: FY2028P | J13: FY2029P | K13: Notes
A14: Base | G14: 0.27 | H14: 0.285 | I14: 0.287 | J14: 0.288 | K14: In-sourced laser cutting lifts margin from FY2027; downside assumes steel squeeze and lost volume
A15: Upside | G15: 0.27 | H15: 0.289 | I15: 0.292 | J15: 0.293
A16: Downside | G16: 0.27 | H16: 0.255 | I16: 0.26 | J16: 0.268
A17: Selected | G17: =CHOOSE($B$4,G14,G15,G16) -> 0.27 | H17: =CHOOSE($B$4,H14,H15,H16) -> 0.285 | I17: =CHOOSE($B$4,I14,I15,I16) -> 0.287 | J17: =CHOOSE($B$4,J14,J15,J16) -> 0.288
A19: Other SG&A % of revenue | G19: FY2026E | H19: FY2027P | I19: FY2028P | J19: FY2029P | K19: Notes
A20: Base | G20: =2120000/18450000 -> 0.11490515 | H20: 0.113 | I20: 0.112 | J20: 0.111 | K20: FY2026E per Sept forecast ($2.12MM)
A21: Upside | G21: =2120000/18450000 -> 0.11490515 | H21: 0.11 | I21: 0.108 | J21: 0.107
A22: Downside | G22: =2120000/18450000 -> 0.11490515 | H22: 0.123 | I22: 0.12 | J22: 0.118
A23: Selected | G23: =CHOOSE($B$4,G20,G21,G22) -> 0.11490515 | H23: =CHOOSE($B$4,H20,H21,H22) -> 0.113 | I23: =CHOOSE($B$4,I20,I21,I22) -> 0.112 | J23: =CHOOSE($B$4,J20,J21,J22) -> 0.111
A25: Officer compensation growth | G25: FY2026E | H25: FY2027P | I25: FY2028P | J25: FY2029P | K25: Notes
A26: Base | G26: 0 | H26: 0.03 | I26: 0.03 | J26: 0.03 | K26: Owners freeze pay in downside
A27: Upside | G27: 0 | H27: 0.03 | I27: 0.03 | J27: 0.03
A28: Downside | G28: 0 | H28: 0 | I28: 0 | J28: 0.03
A29: Selected | G29: =CHOOSE($B$4,G26,G27,G28) -> 0 | H29: =CHOOSE($B$4,H26,H27,H28) -> 0.03 | I29: =CHOOSE($B$4,I26,I27,I28) -> 0.03 | J29: =CHOOSE($B$4,J26,J27,J28) -> 0.03
A31: Days sales outstanding | G31: FY2026E | H31: FY2027P | I31: FY2028P | J31: FY2029P | K31: Notes
A32: Base | G32: 48 | H32: 47 | I32: 47 | J32: 47 | K32: On revenue
A33: Upside | G33: 48 | H33: 46 | I33: 45 | J33: 45
A34: Downside | G34: 48 | H34: 54 | I34: 52 | J34: 50
A35: Selected | G35: =CHOOSE($B$4,G32,G33,G34) -> 48 | H35: =CHOOSE($B$4,H32,H33,H34) -> 47 | I35: =CHOOSE($B$4,I32,I33,I34) -> 47 | J35: =CHOOSE($B$4,J32,J33,J34) -> 47
A37: Days inventory outstanding | G37: FY2026E | H37: FY2027P | I37: FY2028P | J37: FY2029P | K37: Notes
A38: Base | G38: 48 | H38: 47 | I38: 47 | J38: 47 | K38: On cost of goods sold
A39: Upside | G39: 48 | H39: 46 | I39: 46 | J39: 46
A40: Downside | G40: 48 | H40: 52 | I40: 50 | J40: 49
A41: Selected | G41: =CHOOSE($B$4,G38,G39,G40) -> 48 | H41: =CHOOSE($B$4,H38,H39,H40) -> 47 | I41: =CHOOSE($B$4,I38,I39,I40) -> 47 | J41: =CHOOSE($B$4,J38,J39,J40) -> 47
A43: Days payables outstanding | G43: FY2026E | H43: FY2027P | I43: FY2028P | J43: FY2029P | K43: Notes
A44: Base | G44: 34 | H44: 34 | I44: 34 | J44: 34 | K44: On cost of goods sold
A45: Upside | G45: 34 | H45: 34 | I45: 34 | J45: 34
A46: Downside | G46: 34 | H46: 32 | I46: 33 | J46: 33
A47: Selected | G47: =CHOOSE($B$4,G44,G45,G46) -> 34 | H47: =CHOOSE($B$4,H44,H45,H46) -> 34 | I47: =CHOOSE($B$4,I44,I45,I46) -> 34 | J47: =CHOOSE($B$4,J44,J45,J46) -> 34
A49: Maintenance capex % of revenue | G49: FY2026E | H49: FY2027P | I49: FY2028P | J49: FY2029P | K49: Notes
...

Sheet Model
A1: Integrated Financial Statements
A2: $ in dollars | FYE December 31 | Scenario: see Assumptions!B4 | E2: ="Scenario: "&Assumptions!B5 -> Scenario: Base
A4: Income Statement | D4: FY2023A | E4: FY2024A | F4: FY2025A | G4: FY2026E | H4: FY2027P | I4: FY2028P | J4: FY2029P
A5: Revenue | D5: 14200000 | E5: 15900000 | F5: 17600000 | G5: =F5*(1+Assumptions!G11) -> 18450000 | H5: =G5*(1+Assumptions!H11) -> 19557000 | I5: =H5*(1+Assumptions!I11) -> 20534850 | J5: =I5*(1+Assumptions!J11) -> 21356244
A6: Cost of goods sold | D6: 10508000 | E6: 11686500 | F6: 12812800 | G6: =G5*(1-Assumptions!G17) -> 13468500 | H6: =H5*(1-Assumptions!H17) -> 13983255 | I6: =I5*(1-Assumptions!I17) -> 14641348 | J6: =J5*(1-Assumptions!J17) -> 15205646
A7: Gross profit | D7: =D5-D6 -> 3692000 | E7: =E5-E6 -> 4213500 | F7: =F5-F6 -> 4787200 | G7: =G5-G6 -> 4981500 | H7: =H5-H6 -> 5573745 | I7: =I5-I6 -> 5893502 | J7: =J5-J6 -> 6150598.3
A8: Officer compensation | D8: 420000 | E8: 440000 | F8: 460000 | G8: =F8*(1+Assumptions!G29) -> 460000 | H8: =G8*(1+Assumptions!H29) -> 473800 | I8: =H8*(1+Assumptions!I29) -> 488014 | J8: =I8*(1+Assumptions!J29) -> 502654.42
A9: Other SG&A | D9: 1710000 | E9: 1870000 | F9: 2020000 | G9: =G5*Assumptions!G23 -> 2120000 | H9: =H5*Assumptions!H23 -> 2209941 | I9: =I5*Assumptions!I23 -> 2299903.2 | J9: =J5*Assumptions!J23 -> 2370543.1
A10: EBITDA | D10: =D7-D8-D9 -> 1562000 | E10: =E7-E8-E9 -> 1903500 | F10: =F7-F8-F9 -> 2307200 | G10: =G7-G8-G9 -> 2401500 | H10: =H7-H8-H9 -> 2890004 | I10: =I7-I8-I9 -> 3105584.8 | J10: =J7-J8-J9 -> 3277400.8
A11: Depreciation & amortization | D11: 610000 | E11: 640000 | F11: 690000 | G11: =G68+G69 -> 708300 | H11: =H68+H69 -> 1259120.5 | I11: =I68+I69 -> 1309912 | J11: =J68+J69 -> 1366475.3
A12: EBIT | D12: =D10-D11 -> 952000 | E12: =E10-E11 -> 1263500 | F12: =F10-F11 -> 1617200 | G12: =G10-G11 -> 1693200 | H12: =H10-H11 -> 1630883.5 | I12: =I10-I11 -> 1795672.7 | J12: =J10-J11 -> 1910925.5
A13: Interest expense | D13: 245000 | E13: 228000 | F13: 214000 | G13: =Debt_Schedule!G25 -> 170410 | H13: =Debt_Schedule!H25 -> 331468.19 | I13: =Debt_Schedule!I25 -> 245782.4 | J13: =Debt_Schedule!J25 -> 156989.69
A14: Other income (expense) | D14: 15000 | E14: -8000 | F14: 12000 | G14: =0 -> 0 | H14: =0 -> 0 | I14: =0 -> 0 | J14: =0 -> 0
A15: Net income (pass-through, pre-tax) | D15: =D12-D13+D14 -> 722000 | E15: =E12-E13+E14 -> 1027500 | F15: =F12-F13+F14 -> 1415200 | G15: =G12-G13+G14 -> 1522790 | H15: =H12-H13+H14 -> 1299415.3 | I15: =I12-I13+I14 -> 1549890.3 | J15: =J12-J13+J14 -> 1753935.8
A16: Distributions to members | D16: 400000 | E16: 480000 | F16: 700000 | G16: =MAX(0,G15*Assumptions!G59) -> 685255.5 | H16: =MAX(0,H15*Assumptions!H59) -> 584736.88 | I16: =MAX(0,I15*Assumptions!I59) -> 697450.65 | J16: =MAX(0,J15*Assumptions!J59) -> 789271.12
A17: Gross margin % | D17: =D7/D5 -> 0.26 | E17: =E7/E5 -> 0.265 | F17: =F7/F5 -> 0.272 | G17: =G7/G5 -> 0.27 | H17: =H7/H5 -> 0.285 | I17: =I7/I5 -> 0.287 | J17: =J7/J5 -> 0.288
A18: EBITDA margin % | D18: =D10/D5 -> 0.11 | E18: =E10/E5 -> 0.11971698 | F18: =F10/F5 -> 0.13109091 | G18: =G10/G5 -> 0.1301626 | H18: =H10/H5 -> 0.14777338 | I18: =I10/I5 -> 0.15123484 | J18: =J10/J5 -> 0.15346335
A20: Balance Sheet | D20: FY2023A | E20: FY2024A | F20: FY2025A | G20: FY2026E | H20: FY2027P | I20: FY2028P | J20: FY2029P
A21: Cash | D21: 610000 | E21: 667500 | F21: 612700 | G21: =Debt_Schedule!G21 -> 500000 | H21: =Debt_Schedule!H21 -> 500000 | I21: =Debt_Schedule!I21 -> 500000 | J21: =Debt_Schedule!J21 -> 1390558.2
A22: Accounts receivable | D22: 1750000 | E22: 1980000 | F22: 2250000 | G22: =G5*Assumptions!G35/365 -> 2426301.4 | H22: =H5*Assumptions!H35/365 -> 2518298.6 | I22: =I5*Assumptions!I35/365 -> 2644213.6 | J22: =J5*Assumptions!J35/365 -> 2749982.1
A23: Inventory | D23: 1420000 | E23: 1500000 | F23: 1640000 | G23: =G6*Assumptions!G41/365 -> 1771200 | H23: =H6*Assumptions!H41/365 -> 1800583.5 | I23: =I6*Assumptions!I41/365 -> 1885324.3 | J23: =J6*Assumptions!J41/365 -> 1957987.3
A24: Prepaids & other current | D24: 90000 | E24: 105000 | F24: 110000 | G24: =G5*Assumptions!$B$62 -> 115312.5 | H24: =H5*Assumptions!$B$62 -> 122231.25 | I24: =I5*Assumptions!$B$62 -> 128342.81 | J24: =J5*Assumptions!$B$62 -> 133476.52
A25: Total current assets | D25: =SUM(D21:D24) -> 3870000 | E25: =SUM(E21:E24) -> 4252500 | F25: =SUM(F21:F24) -> 4612700 | G25: =SUM(G21:G24) -> 4812813.9 | H25: =SUM(H21:H24) -> 4941113.4 | I25: =SUM(I21:I24) -> 5157880.6 | J25: =SUM(J21:J24) -> 6232004.1
A26: Gross PP&E | D26: 7800000 | E26: 8300000 | F26: 9000000 | G26: =F26+G66+G67 -> 9945750 | H26: =G26+H66+H67 -> 13791131 | I26: =H26+I66+I67 -> 14509851 | J26: =I26+J66+J67 -> 15257319
A27: Accumulated depreciation | D27: -3900000 | E27: -4540000 | F27: -5230000 | G27: =F27-G11 -> -5938300 | H27: =G27-H11 -> -7197420.5 | I27: =H27-I11 -> -8507332.5 | J27: =I27-J11 -> -9873807.8
A28: Net PP&E | D28: =D26+D27 -> 3900000 | E28: =E26+E27 -> 3760000 | F28: =F26+F27 -> 3770000 | G28: =G26+G27 -> 4007450 | H28: =H26+H27 -> 6593710.5 | I28: =I26+I27 -> 6002518.2 | J28: =J26+J27 -> 5383511.5
A29: Other assets | D29: 120000 | E29: 115000 | F29: 110000 | G29: =F29 -> 110000 | H29: =G29 -> 110000 | I29: =H29 -> 110000 | J29: =I29 -> 110000
A30: Total assets | D30: =D25+D28+D29 -> 7890000 | E30: =E25+E28+E29 -> 8127500 | F30: =F25+F28+F29 -> 8492700 | G30: =G25+G28+G29 -> 8930263.9 | H30: =H25+H28+H29 -> 11644824 | I30: =I25+I28+I29 -> 11270399 | J30: =J25+J28+J29 -> 11725516
A32: Revolving line of credit | D32: 650000 | E32: 720000 | F32: 780000 | G32: =Debt_Schedule!G18 -> 844437.37 | H32: =Debt_Schedule!H18 -> 483578.56 | I32: =Debt_Schedule!I18 -> 126922.41 | J32: =Debt_Schedule!J18 -> 0
A33: Current portion of term debt | D33: 520000 | E33: 540000 | F33: 560000 | G33: =Debt_Schedule!G13 -> 585000 | H33: =Debt_Schedule!H13 -> 952569.35 | I33: =Debt_Schedule!I13 -> 453247.77 | J33: =Debt_Schedule!J13 -> 395851
A34: Accounts payable | D34: 980000 | E34: 1090000 | F34: 1180000 | G34: =G6*Assumptions!G47/365 -> 1254600 | H34: =H6*Assumptions!H47/365 -> 1302549.8 | I34: =I6*Assumptions!I47/365 -> 1363851.6 | J34: =J6*Assumptions!J47/365 -> 1416416.3
A35: Accrued liabilities | D35: 340000 | E35: 370000 | F35: 410000 | G35: =G6*Assumptions!$B$63 -> 430992 | H35: =H6*Assumptions!$B$63 -> 447464.16 | I35: =I6*Assumptions!$B$63 -> 468523.14 | J35: =J6*Assumptions!$B$63 -> 486580.66
A36: Total current liabilities | D36: =SUM(D32:D35) -> 2490000 | E36: =SUM(E32:E35) -> 2720000 | F36: =SUM(F32:F35) -> 2930000 | G36: =SUM(G32:G35) -> 3115029.4 | H36: =SUM(H32:H35) -> 3186161.9 | I36: =SUM(I32:I35) -> 2412544.9 | J36: =SUM(J32:J35) -> 2298848
A37: Term debt, net of current | D37: 2380000 | E37: 1840000 | F37: 1280000 | G37: =Debt_Schedule!G12-G33 -> 695000 | H37: =Debt_Schedule!H12-H33 -> 2223749.1 | I37: =Debt_Schedule!I12-I33 -> 1770501.3 | J37: =Debt_Schedule!J12-J33 -> 1374650.4
A38: Total liabilities | D38: =D36+D37 -> 4870000 | E38: =E36+E37 -> 4560000 | F38: =F36+F37 -> 4210000 | G38: =G36+G37 -> 3810029.4 | H38: =H36+H37 -> 5409911 | I38: =I36+I37 -> 4183046.3 | J38: =J36+J37 -> 3673498.3
A39: Members' equity | D39: 3020000 | E39: 3567500 | F39: 4282700 | G39: =F39+G15-G16+G59 -> 5120234.5 | H39: =G39+H15-H16+H59 -> 6234912.9 | I39: =H39+I15-I16+I59 -> 7087352.6 | J39: =I39+J15-J16+J59 -> 8052017.3
A40: Total liabilities & equity | D40: =D38+D39 -> 7890000 | E40: =E38+E39 -> 8127500 | F40: =F38+F39 -> 8492700 | G40: =G38+G39 -> 8930263.9 | H40: =H38+H39 -> 11644824 | I40: =I38+I39 -> 11270399 | J40: =J38+J39 -> 11725516
A41: Balance check (must be zero) | D41: =D30-D40 -> 0 | E41: =E30-E40 -> 0 | F41: =F30-F40 -> 0 | G41: =G30-G40 -> 0 | H41: =H30-H40 -> 0 | I41: =I30-I40 -> 0 | J41: =J30-J40 -> 0
A43: Cash Flow Statement | D43: FY2023A | E43: FY2024A | F43: FY2025A | G43: FY2026E | H43: FY2027P | I43: FY2028P | J43: FY2029P
A44: Net income | G44: =G15 -> 1522790 | H44: =H15 -> 1299415.3 | I44: =I15 -> 1549890.3 | J44: =J15 -> 1753935.8
...

Sheet Debt_Schedule
A1: Debt Schedule
A2: Interest on beginning balances (avoids circular references); new term loan interest and principal use exact monthly amortization
A3: Existing term loan | D3: FY2023A | E3: FY2024A | F3: FY2025A | G3: FY2026E | H3: FY2027P | I3: FY2028P | J3: FY2029P
A4: Beginning balance | G4: =F6 -> 1840000 | H4: =G6 -> 1280000 | I4: =H6 -> 695000 | J4: =I6 -> 85000
A5: Scheduled principal | G5: =MIN(G4,Assumptions!G81) -> 560000 | H5: =MIN(H4,Assumptions!H81) -> 585000 | I5: =MIN(I4,Assumptions!I81) -> 610000 | J5: =MIN(J4,Assumptions!J81) -> 85000
A6: Ending balance | F6: =Model!F33+Model!F37 -> 1840000 | G6: =G4-G5 -> 1280000 | H6: =H4-H5 -> 695000 | I6: =I4-I5 -> 85000 | J6: =J4-J5 -> 0
A7: Interest | G7: =G4*Assumptions!$B$72 -> 117760 | H7: =H4*Assumptions!$B$72 -> 81920 | I7: =I4*Assumptions!$B$72 -> 44480 | J7: =J4*Assumptions!$B$72 -> 5440
A8: New equipment term loan | D8: FY2023A | E8: FY2024A | F8: FY2025A | G8: FY2026E | H8: FY2027P | I8: FY2028P | J8: FY2029P
A9: Proceeds | G9: =IF(2026=2027,Assumptions!$B$68,0) -> 0 | H9: =IF(2027=2027,Assumptions!$B$68,0) -> 2800000 | I9: =IF(2028=2027,Assumptions!$B$68,0) -> 0 | J9: =IF(2029=2027,Assumptions!$B$68,0) -> 0
A10: Principal paid | G10: =IF(0>=1,-CUMPRINC(Assumptions!$B$69/12,Assumptions!$B$70,Assumptions!$B$68,(0-1)*12+1,0*12,0),0) -> 0 | H10: =IF(1>=1,-CUMPRINC(Assumptions!$B$69/12,Assumptions!$B$70,Assumptions!$B$68,(1-1)*12+1,1*12,0),0) -> 318681.53 | I10: =IF(2>=1,-CUMPRINC(Assumptions!$B$69/12,Assumptions!$B$70,Assumptions!$B$68,(2-1)*12+1,2*12,0),0) -> 342569.35 | J10: =IF(3>=1,-CUMPRINC(Assumptions!$B$69/12,Assumptions!$B$70,Assumptions!$B$68,(3-1)*12+1,3*12,0),0) -> 368247.77
A11: Ending balance | F11: 0 | G11: =F11+G9-G10 -> 0 | H11: =G11+H9-H10 -> 2481318.5 | I11: =H11+I9-I10 -> 2138749.1 | J11: =I11+J9-J10 -> 1770501.3
A12: Total term debt (existing + new) | G12: =G6+G11 -> 1280000 | H12: =H6+H11 -> 3176318.5 | I12: =I6+I11 -> 2223749.1 | J12: =J6+J11 -> 1770501.3
A13: Current portion (next year's principal) | G13: =MIN(G6,Assumptions!H81)+IF(0>=1,-CUMPRINC(Assumptions!$B$69/12,Assumptions!$B$70,Assumptions!$B$68,(1-1)*12+1,1*12,0),0) -> 585000 | H13: =MIN(H6,Assumptions!I81)+IF(1>=1,-CUMPRINC(Assumptions!$B$69/12,Assumptions!$B$70,Assumptions!$B$68,(2-1)*12+1,2*12,0),0) -> 952569.35 | I13: =MIN(I6,Assumptions!J81)+IF(2>=1,-CUMPRINC(Assumptions!$B$69/12,Assumptions!$B$70,Assumptions!$B$68,(3-1)*12+1,3*12,0),0) -> 453247.77 | J13: =MIN(J6,0)+IF(3>=1,-CUMPRINC(Assumptions!$B$69/12,Assumptions!$B$70,Assumptions!$B$68,(4-1)*12+1,4*12,0),0) -> 395851
A14: Interest | G14: =IF(0>=1,-CUMIPMT(Assumptions!$B$69/12,Assumptions!$B$70,Assumptions!$B$68,(0-1)*12+1,0*12,0),0) -> 0 | H14: =IF(1>=1,-CUMIPMT(Assumptions!$B$69/12,Assumptions!$B$70,Assumptions!$B$68,(1-1)*12+1,1*12,0),0) -> 192548.67 | I14: =IF(2>=1,-CUMIPMT(Assumptions!$B$69/12,Assumptions!$B$70,Assumptions!$B$68,(2-1)*12+1,2*12,0),0) -> 168660.84 | J14: =IF(3>=1,-CUMIPMT(Assumptions!$B$69/12,Assumptions!$B$70,Assumptions!$B$68,(3-1)*12+1,3*12,0),0) -> 142982.43
A15: Revolving line of credit | D15: FY2023A | E15: FY2024A | F15: FY2025A | G15: FY2026E | H15: FY2027P | I15: FY2028P | J15: FY2029P
A16: Beginning balance | G16: =F18 -> 780000 | H16: =G18 -> 844437.37 | I16: =H18 -> 483578.56 | J16: =I18 -> 126922.41
A17: Draw (repayment) | G17: =MIN(Assumptions!$B$74-G16,MAX(Assumptions!$B$75-G20,-G16)) -> 64437.37 | H17: =MIN(Assumptions!$B$74-H16,MAX(Assumptions!$B$75-H20,-H16)) -> -360858.81 | I17: =MIN(Assumptions!$B$74-I16,MAX(Assumptions!$B$75-I20,-I16)) -> -356656.15 | J17: =MIN(Assumptions!$B$74-J16,MAX(Assumptions!$B$75-J20,-J16)) -> -126922.41
A18: Ending balance | F18: =Model!F32 -> 780000 | G18: =G16+G17 -> 844437.37 | H18: =H16+H17 -> 483578.56 | I18: =I16+I17 -> 126922.41 | J18: =J16+J17 -> 0
A19: Availability (commitment less balance) | G19: =Assumptions!$B$74-G18 -> 655562.63 | H19: =Assumptions!$B$74-H18 -> 1016421.4 | I19: =Assumptions!$B$74-I18 -> 1373077.6 | J19: =Assumptions!$B$74-J18 -> 1500000
A20: Cash before revolver | G20: =Model!F21+Model!G51+Model!G55+Model!G56+Model!G57+Model!G59+Model!G60 -> 435562.63 | H20: =Model!G21+Model!H51+Model!H55+Model!H56+Model!H57+Model!H59+Model!H60 -> 860858.81 | I20: =Model!H21+Model!I51+Model!I55+Model!I56+Model!I57+Model!I59+Model!I60 -> 856656.15 | J20: =Model!I21+Model!J51+Model!J55+Model!J56+Model!J57+Model!J59+Model!J60 -> 1517480.6
A21: Ending cash | G21: =G20+G17 -> 500000 | H21: =H20+H17 -> 500000 | I21: =I20+I17 -> 500000 | J21: =J20+J17 -> 1390558.2
A22: Revolver interest | G22: =G16*Assumptions!$B$73 -> 52650 | H22: =H16*Assumptions!$B$73 -> 56999.522 | I22: =I16*Assumptions!$B$73 -> 32641.553 | J22: =J16*Assumptions!$B$73 -> 8567.2627
A23: Liquidity (cash + availability) | G23: =G21+G19 -> 1155562.6 | H23: =H21+H19 -> 1516421.4 | I23: =I21+I19 -> 1873077.6 | J23: =J21+J19 -> 2890558.2
A24: Funding shortfall flag | G24: =IF(G21<Assumptions!$B$75-1,"SHORTFALL","OK") -> OK | H24: =IF(H21<Assumptions!$B$75-1,"SHORTFALL","OK") -> OK | I24: =IF(I21<Assumptions!$B$75-1,"SHORTFALL","OK") -> OK | J24: =IF(J21<Assumptions!$B$75-1,"SHORTFALL","OK") -> OK
A25: Total interest expense | G25: =G7+G14+G22 -> 170410 | H25: =H7+H14+H22 -> 331468.19 | I25: =I7+I14+I22 -> 245782.4 | J25: =J7+J14+J22 -> 156989.69

Sheet Covenants
A1: Bank Covenant Compliance (Projected)
A2: Same definitions as the Package 01 credit memo
A4: Debt service coverage | D4: FY2023A | E4: FY2024A | F4: FY2025A | G4: FY2026E | H4: FY2027P | I4: FY2028P | J4: FY2029P
A5: Net income | G5: =Model!G15 -> 1522790 | H5: =Model!H15 -> 1299415.3 | I5: =Model!I15 -> 1549890.3 | J5: =Model!J15 -> 1753935.8
A6: + Depreciation & amortization | G6: =Model!G11 -> 708300 | H6: =Model!H11 -> 1259120.5 | I6: =Model!I11 -> 1309912 | J6: =Model!J11 -> 1366475.3
A7: + Interest expense | G7: =Model!G13 -> 170410 | H7: =Model!H13 -> 331468.19 | I7: =Model!I13 -> 245782.4 | J7: =Model!J13 -> 156989.69
A8: - Distributions | G8: =-Model!G16 -> -685255.5 | H8: =-Model!H16 -> -584736.88 | I8: =-Model!I16 -> -697450.65 | J8: =-Model!J16 -> -789271.12
A9: Cash flow available for debt service | G9: =SUM(G5:G8) -> 1716244.5 | H9: =SUM(H5:H8) -> 2305267.1 | I9: =SUM(I5:I8) -> 2408134.1 | J9: =SUM(J5:J8) -> 2488129.6
A10: Scheduled term principal | G10: =Debt_Schedule!G5+Debt_Schedule!G10 -> 560000 | H10: =Debt_Schedule!H5+Debt_Schedule!H10 -> 903681.53 | I10: =Debt_Schedule!I5+Debt_Schedule!I10 -> 952569.35 | J10: =Debt_Schedule!J5+Debt_Schedule!J10 -> 453247.77
A11: Interest expense | G11: =Model!G13 -> 170410 | H11: =Model!H13 -> 331468.19 | I11: =Model!I13 -> 245782.4 | J11: =Model!J13 -> 156989.69
A12: Total debt service | G12: =G10+G11 -> 730410 | H12: =H10+H11 -> 1235149.7 | I12: =I10+I11 -> 1198351.8 | J12: =J10+J11 -> 610237.46
A13: DSCR | G13: =G9/G12 -> 2.3497002 | H13: =H9/H12 -> 1.8663868 | I13: =I9/I12 -> 2.0095386 | J13: =J9/J12 -> 4.0773138
A14: Minimum | G14: =Assumptions!$B$76 -> 1.25 | H14: =Assumptions!$B$76 -> 1.25 | I14: =Assumptions!$B$76 -> 1.25 | J14: =Assumptions!$B$76 -> 1.25
A15: Result | G15: =IF(G13>=G14,"PASS","FAIL") -> PASS | H15: =IF(H13>=H14,"PASS","FAIL") -> PASS | I15: =IF(I13>=I14,"PASS","FAIL") -> PASS | J15: =IF(J13>=J14,"PASS","FAIL") -> PASS
A16: Distribution restriction | G16: =IF(G13<Assumptions!$B$78,"Tax distributions only","None") -> None | H16: =IF(H13<Assumptions!$B$78,"Tax distributions only","None") -> None | I16: =IF(I13<Assumptions!$B$78,"Tax distributions only","None") -> None | J16: =IF(J13<Assumptions!$B$78,"Tax distributions only","None") -> None
A18: Leverage | D18: FY2023A | E18: FY2024A | F18: FY2025A | G18: FY2026E | H18: FY2027P | I18: FY2028P | J18: FY2029P
A19: Funded debt (term + revolver) | G19: =Debt_Schedule!G12+Debt_Schedule!G18 -> 2124437.4 | H19: =Debt_Schedule!H12+Debt_Schedule!H18 -> 3659897 | I19: =Debt_Schedule!I12+Debt_Schedule!I18 -> 2350671.5 | J19: =Debt_Schedule!J12+Debt_Schedule!J18 -> 1770501.3
A20: EBITDA | G20: =Model!G10 -> 2401500 | H20: =Model!H10 -> 2890004 | I20: =Model!I10 -> 3105584.8 | J20: =Model!J10 -> 3277400.8
A21: Funded debt / EBITDA | G21: =G19/G20 -> 0.88462934 | H21: =H19/H20 -> 1.2663986 | I21: =I19/I20 -> 0.75691753 | J21: =J19/J20 -> 0.54021509
A22: Maximum | G22: =Assumptions!$B$77 -> 3 | H22: =Assumptions!$B$77 -> 3 | I22: =Assumptions!$B$77 -> 3 | J22: =Assumptions!$B$77 -> 3
A23: Result | G23: =IF(G21<=G22,"PASS","FAIL") -> PASS | H23: =IF(H21<=H22,"PASS","FAIL") -> PASS | I23: =IF(I21<=I22,"PASS","FAIL") -> PASS | J23: =IF(J21<=J22,"PASS","FAIL") -> PASS
A25: Liquidity | D25: FY2023A | E25: FY2024A | F25: FY2025A | G25: FY2026E | H25: FY2027P | I25: FY2028P | J25: FY2029P
A26: Ending cash | G26: =Model!G21 -> 500000 | H26: =Model!H21 -> 500000 | I26: =Model!I21 -> 500000 | J26: =Model!J21 -> 1390558.2
A27: Revolver availability | G27: =Debt_Schedule!G19 -> 655562.63 | H27: =Debt_Schedule!H19 -> 1016421.4 | I27: =Debt_Schedule!I19 -> 1373077.6 | J27: =Debt_Schedule!J19 -> 1500000
A28: Total liquidity | G28: =G26+G27 -> 1155562.6 | H28: =H26+H27 -> 1516421.4 | I28: =I26+I27 -> 1873077.6 | J28: =J26+J27 -> 2890558.2

Sheet Scenario_Compare
A1: Scenario Comparison
A2: Snapshot values captured by running each scenario through the model (switch Assumptions!B4 to reproduce). Not live formulas.
A4: FY2027P | B4: Base | C4: Upside | D4: Downside
A5: Revenue | B5: 19557000 | C5: 20295000 | D5: 15682500
A6: Gross margin | B6: 0.285 | C6: 0.289 | D6: 0.255
A7: EBITDA | B7: 2890004 | C7: 3159005 | D7: 1610090
A8: Net income | B8: 1299415.3 | C8: 1568416.3 | D8: 19501.284
A9: Distributions | B9: 584736.88 | C9: 705787.33 | D9: 7800.5134
A10: Ending cash | B10: 500000 | C10: 500000 | D10: 500000
A11: Revolver balance | B11: 483578.56 | C11: 406693.06 | D11: 879575.97
A12: Funded debt | B12: 3659897 | C12: 3583011.5 | D12: 4055894.4
A13: DSCR (min 1.25x) | B13: 1.8663868 | C13: 1.9861703 | D13: 1.2972431
A14: Funded debt / EBITDA (max 3.0x) | B14: 1.2663986 | C14: 1.1342215 | D14: 2.5190483
A15: Liquidity (cash + availability) | B15: 1516421.4 | C15: 1593306.9 | D15: 1120424
A16: DSCR covenant | B16: PASS | C16: PASS | D16: PASS
A17: Distribution restriction | B17: None | C17: None | D17: Tax distributions only
A19: FY2028P | B19: Base | C19: Upside | D19: Downside
A20: Revenue | B20: 20534850 | C20: 21918600 | D20: 15212025
A21: Gross margin | B21: 0.287 | C21: 0.292 | D21: 0.26
A22: EBITDA | B22: 3105584.8 | C22: 3545008.4 | D22: 1669683.5
A23: Net income | B23: 1549890.3 | C23: 1989392.7 | D23: 110898.07
A24: Distributions | B24: 697450.65 | C24: 895226.7 | D24: 44359.229
A25: Ending cash | B25: 500000 | C25: 605188.02 | D25: 500000
A26: Revolver balance | B26: 126922.41 | C26: 0 | D26: 601489.57
A27: Funded debt | B27: 2350671.5 | C27: 2223749.1 | D27: 2825238.7
A28: DSCR (min 1.25x) | B28: 2.0095386 | C28: 2.2208063 | D28: 1.326707
A29: Funded debt / EBITDA (max 3.0x) | B29: 0.75691753 | C29: 0.62729023 | D29: 1.6920804
A30: Liquidity (cash + availability) | B30: 1873077.6 | C30: 2105188 | D30: 1398510.4
A31: DSCR covenant | B31: PASS | C31: PASS | D31: PASS
A32: Distribution restriction | B32: None | C32: None | D32: Tax distributions only
A34: FY2029P | B34: Base | C34: Upside | D34: Downside
A35: Revenue | B35: 21356244 | C35: 23233716 | D35: 15820506
A36: Gross margin | B36: 0.288 | C36: 0.293 | D36: 0.268
A37: EBITDA | B37: 3277400.8 | C37: 3818816.8 | D37: 1899275.9
A38: Net income | B38: 1753935.8 | C38: 2293271.4 | D38: 394050.06
A39: Distributions | B39: 789271.12 | C39: 1031972.2 | D39: 157620.02
A40: Ending cash | B40: 1390558.2 | C40: 1782795.7 | D40: 546486.86
A41: Revolver balance | B41: 0 | C41: 0 | D41: 0
A42: Funded debt | B42: 1770501.3 | C42: 1770501.3 | D42: 1770501.3
A43: DSCR (min 1.25x) | B43: 4.0773138 | C43: 4.6318475 | D43: 2.711716
...
