Workbook

Sheet Cover
B2: Commercial Credit Analysis Model
B3: Brazos Bend Fabrication, LLC | $2.8MM Equipment Term Loan + $1.5MM Revolving Line of Credit
B4: Prepared by Matthew Dial | Portfolio work sample | October 2026
B6: DISCLAIMER: The borrower, guarantors, bank, and all figures are fictional and were created for portfolio demonstration only. No real customer or employer data is used.
B8: Tab | C8: What it shows
B9: Inputs | C9: Deal terms, pricing, projection and stress assumptions (all blue cells are editable)
B10: Spread | C10: Three-year financial statement spread, equity roll-forward, derived cash flow, tie-out checks
B11: Ratios | C11: Profitability, liquidity, working capital cycle, leverage, and coverage trends
B12: Global_CF | C12: Guarantor personal cash flow, liquidity, and global debt service coverage
B13: ProForma_DSCR | C13: Historical pro forma DSCR with new debt plus projected Year 1 DSCR
B14: Stress_Test | C14: Revenue, margin, and rate sensitivities with breakeven revenue decline
B15: Risk_Rating | C15: Weighted 9-point risk rating scorecard
B16: Collateral_BB | C16: Collateral coverage analysis and borrowing base certificate
B17: Amortization | C17: 84-month amortization schedule for the new equipment term loan
B19: Color legend
B20: Blue text | C20: Hardcoded input or assumption
B21: Black text | C21: Formula on the same sheet
B22: Green text | C22: Formula linking to another sheet
B23: Yellow fill | C23: Key output or policy test

Sheet Inputs
A1: Inputs & Assumptions
A2: Blue cells are inputs. Change them and every tab recalculates.
A4: Deal terms | B4: Value | C4: Notes
A5: Equipment purchase price | B5: 3500000 | C5: Fiber laser cutting system and two CNC press brakes, per vendor quote
A6: Advance rate on equipment cost | B6: 0.8 | C6: Bank policy maximum for new manufacturing equipment
A7: New equipment term loan amount | B7: =B5*B6 -> 2800000 | C7: Calculated
A8: Term loan fixed rate | B8: 0.0725 | C8: Illustrative fixed rate
A9: Term loan amortization (months) | B9: 84 | C9: 7-year amortization, matching useful life
A10: Proposed RLOC commitment | B10: 1500000 | C10: Increase from existing $1.0MM line
A11: Existing RLOC commitment | B11: 1000000
A12: SOFR assumption | B12: 0.04 | C12: Illustrative. Update to current Term SOFR before use
A13: RLOC spread over SOFR | B13: 0.0275
A14: RLOC all-in rate | B14: =B12+B13 -> 0.0675 | C14: Calculated
A15: Assumed average RLOC usage | B15: 900000 | C15: 60% of proposed commitment
A16: Existing term debt interest (next 12 months) | B16: 105000 | C16: From existing note schedule
A17: Existing term debt principal (next 12 months) | B17: =Spread!D31 -> 560000 | C17: Current portion of LTD at FYE 2025
A18: Existing term debt annual P&I | B18: =B16+B17 -> 665000 | C18: Calculated
A19: Equity injection: company cash | B19: 300000 | C19: Verified on FYE 2025 balance sheet
A20: Equity injection: guarantor contribution (Reyes) | B20: 400000 | C20: Verified on personal brokerage statement
A21: Total equity injection | B21: =B19+B20 -> 700000 | C21: Should equal price less loan
A22: Equity injection check | B22: =B21-(B5-B7) -> 0 | C22: Must be zero
A24: Policy limits | B24: Value | C24: Notes
A25: Minimum DSCR (business) | B25: 1.25 | C25: Covenant tested annually
A26: Minimum global DSCR | B26: 1.2
A27: Maximum funded debt / EBITDA | B27: 3 | C27: Covenant tested annually
A28: Minimum collateral coverage | B28: 1
A30: Historical items not on the spread | B30: Value | C30: Notes
A31: FY2022 current portion of LTD | B31: 500000 | C31: Needed for FY2023 DSCR
A32: FY2023 capital expenditures | B32: 600000 | C32: From FY2023 cash flow statement
A34: Projection assumptions (Year 1) | B34: Value | C34: Notes
A35: Revenue growth | B35: 0.06 | C35: Backlog-supported, below 3-yr CAGR of 11.3%
A36: Gross margin improvement from in-sourcing | B36: 0.015 | C36: Replaces outsourced laser cutting; management estimates 2.0%, haircut to 1.5%
A37: Officer compensation growth | B37: 0 | C37: Held flat per management
A38: Other SG&A growth | B38: 0.04
A39: New equipment useful life (years) | B39: 7 | C39: Straight-line depreciation
A40: Distributions as % of net income | B40: 0.45 | C40: Tax distributions plus modest owner draw
A42: Stress test assumptions | B42: Value | C42: Notes
A43: Variable portion of COGS | B43: 0.85 | C43: Materials and direct labor flex with volume
A44: Variable portion of other SG&A | B44: 0.2 | C44: Commissions and freight

Sheet Spread
A1: Financial Statement Spread
A2: Brazos Bend Fabrication, LLC | $ in dollars | FYE December 31 | CPA-reviewed statements
A4: Income Statement | B4: FY2023 | C4: FY2024 | D4: FY2025 | F4: FY23 % | G4: FY24 % | H4: FY25 %
A5: Revenue | B5: 14200000 | C5: 15900000 | D5: 17600000 | F5: =IFERROR(B5/B$5,0) -> 1 | G5: =IFERROR(C5/C$5,0) -> 1 | H5: =IFERROR(D5/D$5,0) -> 1
A6: Cost of goods sold | B6: 10508000 | C6: 11686500 | D6: 12812800 | F6: =IFERROR(B6/B$5,0) -> 0.74 | G6: =IFERROR(C6/C$5,0) -> 0.735 | H6: =IFERROR(D6/D$5,0) -> 0.728
A7: Gross profit | B7: =B5-B6 -> 3692000 | C7: =C5-C6 -> 4213500 | D7: =D5-D6 -> 4787200 | F7: =IFERROR(B7/B$5,0) -> 0.26 | G7: =IFERROR(C7/C$5,0) -> 0.265 | H7: =IFERROR(D7/D$5,0) -> 0.272
A8: Officer compensation | B8: 420000 | C8: 440000 | D8: 460000 | F8: =IFERROR(B8/B$5,0) -> 0.029577465 | G8: =IFERROR(C8/C$5,0) -> 0.027672956 | H8: =IFERROR(D8/D$5,0) -> 0.026136364
A9: Other SG&A | B9: 1710000 | C9: 1870000 | D9: 2020000 | F9: =IFERROR(B9/B$5,0) -> 0.12042254 | G9: =IFERROR(C9/C$5,0) -> 0.11761006 | H9: =IFERROR(D9/D$5,0) -> 0.11477273
A10: EBITDA | B10: =B7-B8-B9 -> 1562000 | C10: =C7-C8-C9 -> 1903500 | D10: =D7-D8-D9 -> 2307200 | F10: =IFERROR(B10/B$5,0) -> 0.11 | G10: =IFERROR(C10/C$5,0) -> 0.11971698 | H10: =IFERROR(D10/D$5,0) -> 0.13109091
A11: Depreciation & amortization | B11: 610000 | C11: 640000 | D11: 690000 | F11: =IFERROR(B11/B$5,0) -> 0.042957746 | G11: =IFERROR(C11/C$5,0) -> 0.040251572 | H11: =IFERROR(D11/D$5,0) -> 0.039204545
A12: EBIT | B12: =B10-B11 -> 952000 | C12: =C10-C11 -> 1263500 | D12: =D10-D11 -> 1617200 | F12: =IFERROR(B12/B$5,0) -> 0.067042254 | G12: =IFERROR(C12/C$5,0) -> 0.079465409 | H12: =IFERROR(D12/D$5,0) -> 0.091886364
A13: Interest expense | B13: 245000 | C13: 228000 | D13: 214000 | F13: =IFERROR(B13/B$5,0) -> 0.017253521 | G13: =IFERROR(C13/C$5,0) -> 0.014339623 | H13: =IFERROR(D13/D$5,0) -> 0.012159091
A14: Other income (expense) | B14: 15000 | C14: -8000 | D14: 12000 | F14: =IFERROR(B14/B$5,0) -> 0.001056338 | G14: =IFERROR(C14/C$5,0) -> -0.00050314465 | H14: =IFERROR(D14/D$5,0) -> 0.00068181818
A15: Net income (pass-through, pre-tax) | B15: =B12-B13+B14 -> 722000 | C15: =C12-C13+C14 -> 1027500 | D15: =D12-D13+D14 -> 1415200 | F15: =IFERROR(B15/B$5,0) -> 0.05084507 | G15: =IFERROR(C15/C$5,0) -> 0.064622642 | H15: =IFERROR(D15/D$5,0) -> 0.080409091
A16: Distributions to members | B16: 400000 | C16: 480000 | D16: 700000 | F16: =IFERROR(B16/B$5,0) -> 0.028169014 | G16: =IFERROR(C16/C$5,0) -> 0.030188679 | H16: =IFERROR(D16/D$5,0) -> 0.039772727
A17: LLC taxed as a partnership: no entity-level income tax. Members receive K-1 income and take tax distributions.
A18: Balance Sheet | B18: FY2023 | C18: FY2024 | D18: FY2025
A19: Cash | B19: 610000 | C19: 667500 | D19: 612700
A20: Accounts receivable | B20: 1750000 | C20: 1980000 | D20: 2250000
A21: Inventory | B21: 1420000 | C21: 1500000 | D21: 1640000
A22: Prepaids & other current | B22: 90000 | C22: 105000 | D22: 110000
A23: Total current assets | B23: =SUM(B19:B22) -> 3870000 | C23: =SUM(C19:C22) -> 4252500 | D23: =SUM(D19:D22) -> 4612700
A24: Gross PP&E | B24: 7800000 | C24: 8300000 | D24: 9000000
A25: Accumulated depreciation | B25: -3900000 | C25: -4540000 | D25: -5230000
A26: Net PP&E | B26: =B24+B25 -> 3900000 | C26: =C24+C25 -> 3760000 | D26: =D24+D25 -> 3770000
A27: Other assets | B27: 120000 | C27: 115000 | D27: 110000
A28: Total assets | B28: =B23+B26+B27 -> 7890000 | C28: =C23+C26+C27 -> 8127500 | D28: =D23+D26+D27 -> 8492700
A30: Line of credit | B30: 650000 | C30: 720000 | D30: 780000
A31: Current portion of LTD | B31: 520000 | C31: 540000 | D31: 560000
A32: Accounts payable | B32: 980000 | C32: 1090000 | D32: 1180000
A33: Accrued liabilities | B33: 340000 | C33: 370000 | D33: 410000
A34: Total current liabilities | B34: =SUM(B30:B33) -> 2490000 | C34: =SUM(C30:C33) -> 2720000 | D34: =SUM(D30:D33) -> 2930000
A35: Long-term debt, net of current | B35: 2380000 | C35: 1840000 | D35: 1280000
A36: Total liabilities | B36: =B34+B35 -> 4870000 | C36: =C34+C35 -> 4560000 | D36: =D34+D35 -> 4210000
A37: Members' equity | B37: 3020000 | C37: 3567500 | D37: 4282700
A38: Total liabilities & equity | B38: =B36+B37 -> 7890000 | C38: =C36+C37 -> 8127500 | D38: =D36+D37 -> 8492700
A39: Balance check (must be zero) | B39: =B28-B38 -> 0 | C39: =C28-C38 -> 0 | D39: =D28-D38 -> 0
A41: Equity Roll-Forward | B41: FY2023 | C41: FY2024 | D41: FY2025
A42: Beginning equity | C42: =B37 -> 3020000 | D42: =C37 -> 3567500
A43: + Net income | C43: =C15 -> 1027500 | D43: =D15 -> 1415200
...

Sheet Ratios
A1: Ratio Analysis
A2: All ratios link to the Spread tab
A4: Ratio | B4: FY2023 | C4: FY2024 | D4: FY2025 | F4: How to read it
A5: Profitability
A6: Revenue growth | B6: n/a | C6: =IFERROR(Spread!C5/Spread!B5-1,0) -> 0.11971831 | D6: =IFERROR(Spread!D5/Spread!C5-1,0) -> 0.10691824 | F6: Three-year trend shows steady double-digit growth
A7: Gross margin | B7: =Spread!B7/Spread!B5 -> 0.26 | C7: =Spread!C7/Spread!C5 -> 0.265 | D7: =Spread!D7/Spread!D5 -> 0.272 | F7: Improving as pricing passes through steel costs
A8: EBITDA margin | B8: =Spread!B10/Spread!B5 -> 0.11 | C8: =Spread!C10/Spread!C5 -> 0.11971698 | D8: =Spread!D10/Spread!D5 -> 0.13109091
A9: Net margin | B9: =Spread!B15/Spread!B5 -> 0.05084507 | C9: =Spread!C15/Spread!C5 -> 0.064622642 | D9: =Spread!D15/Spread!D5 -> 0.080409091 | F9: Pre-tax, pass-through entity
A10: Liquidity
A11: Current ratio | B11: =Spread!B23/Spread!B34 -> 1.5542169 | C11: =Spread!C23/Spread!C34 -> 1.5634191 | D11: =Spread!D23/Spread!D34 -> 1.5743003 | F11: Current assets / current liabilities
A12: Quick ratio | B12: =(Spread!B19+Spread!B20)/Spread!B34 -> 0.94779116 | C12: =(Spread!C19+Spread!C20)/Spread!C34 -> 0.97334559 | D12: =(Spread!D19+Spread!D20)/Spread!D34 -> 0.97703072 | F12: Excludes inventory and prepaids
A13: Working capital | B13: =Spread!B23-Spread!B34 -> 1380000 | C13: =Spread!C23-Spread!C34 -> 1532500 | D13: =Spread!D23-Spread!D34 -> 1682700
A14: Working Capital Cycle
A15: Days sales outstanding (DSO) | B15: =Spread!B20/Spread!B5*365 -> 44.982394 | C15: =Spread!C20/Spread!C5*365 -> 45.45283 | D15: =Spread!D20/Spread!D5*365 -> 46.661932 | F15: Creeping up; watch item
A16: Days inventory outstanding (DIO) | B16: =Spread!B21/Spread!B6*365 -> 49.324324 | C16: =Spread!C21/Spread!C6*365 -> 46.848928 | D16: =Spread!D21/Spread!D6*365 -> 46.718906
A17: Days payables outstanding (DPO) | B17: =Spread!B32/Spread!B6*365 -> 34.040731 | C17: =Spread!C32/Spread!C6*365 -> 34.043555 | D17: =Spread!D32/Spread!D6*365 -> 33.614823
A18: Cash conversion cycle (days) | B18: =B15+B16-B17 -> 60.265988 | C18: =C15+C16-C17 -> 58.258204 | D18: =D15+D16-D17 -> 59.766015 | F18: DSO + DIO - DPO
A19: Leverage
A20: Debt to worth | B20: =Spread!B36/Spread!B37 -> 1.6125828 | C20: =Spread!C36/Spread!C37 -> 1.278206 | D20: =Spread!D36/Spread!D37 -> 0.98302473 | F20: Total liabilities / members' equity
A21: Funded debt | B21: =Spread!B30+Spread!B31+Spread!B35 -> 3550000 | C21: =Spread!C30+Spread!C31+Spread!C35 -> 3100000 | D21: =Spread!D30+Spread!D31+Spread!D35 -> 2620000 | F21: Line + all term debt
A22: Funded debt / EBITDA | B22: =B21/Spread!B10 -> 2.2727273 | C22: =C21/Spread!C10 -> 1.6285789 | D22: =D21/Spread!D10 -> 1.1355756 | F22: Policy max 3.0x
A23: Coverage
A24: Prior-year CPLTD | B24: =Inputs!B31 -> 500000 | C24: =Spread!B31 -> 520000 | D24: =Spread!C31 -> 540000 | F24: Principal due during the year
A25: Traditional DSCR | B25: =(Spread!B15+Spread!B11+Spread!B13-Spread!B16)/(B24+Spread!B13) -> 1.5798658 | C25: =(Spread!C15+Spread!C11+Spread!C13-Spread!C16)/(C24+Spread!C13) -> 1.8923797 | D25: =(Spread!D15+Spread!D11+Spread!D13-Spread!D16)/(D24+Spread!D13) -> 2.1474801 | F25: (NI + D&A + interest - distributions) / (prior CPLTD + interest)
A26: EBITDA DSCR | B26: =Spread!B10/(B24+Spread!B13) -> 2.0966443 | C26: =Spread!C10/(C24+Spread!C13) -> 2.5447861 | D26: =Spread!D10/(D24+Spread!D13) -> 3.0599469 | F26: Before distributions
A27: Capital expenditures | B27: =Inputs!B32 -> 600000 | C27: =-Spread!C57 -> 500000 | D27: =-Spread!D57 -> 700000
A28: Fixed charge coverage | B28: =(Spread!B10-B27-Spread!B16)/(B24+Spread!B13) -> 0.75436242 | C28: =(Spread!C10-C27-Spread!C16)/(C24+Spread!C13) -> 1.2346257 | D28: =(Spread!D10-D27-Spread!D16)/(D24+Spread!D13) -> 1.203183 | F28: (EBITDA - capex - distributions) / (prior CPLTD + interest). Capex in FY24-25 was funded from cash

Sheet ProForma_DSCR
A1: Pro Forma Debt Service Coverage
A2: Section A: FY2025 actual cash flow against post-closing debt service. Section B: projected first full year with new equipment.
A4: A. Historical Pro Forma (FY2025 base) | B4: Amount | D4: Notes
A5: Net income FY2025 | B5: =Spread!D15 -> 1415200
A6: + Depreciation & amortization | B6: =Spread!D11 -> 690000
A7: + Interest expense | B7: =Spread!D13 -> 214000 | D7: Historical interest added back; replaced by pro forma debt service below
A8: - Distributions | B8: =-Spread!D16 -> -700000 | D8: Deducted because members rely on them for taxes
A9: Cash flow available for debt service (CFADS) | B9: =SUM(B5:B8) -> 1619200
A11: Existing term debt P&I | B11: =Inputs!B18 -> 665000
A12: New equipment term loan P&I | B12: =-PMT(Inputs!B8/12,Inputs!B9,Inputs!B7)*12 -> 511230.2 | D12: Level monthly payment x 12
A13: RLOC interest at assumed usage | B13: =Inputs!B15*Inputs!B14 -> 60750 | D13: Interest-only revolver
A14: Total pro forma debt service | B14: =SUM(B11:B13) -> 1236980.2
A16: Pro forma DSCR | B16: =B9/B14 -> 1.3089943
A17: Policy minimum | B17: =Inputs!B25 -> 1.25
A18: Result | B18: =IF(B16>=B17,"PASS","FAIL") -> PASS
A19: Excess cash flow after debt service | B19: =B9-B14 -> 382219.8
A20: Pro forma funded debt / EBITDA | B20: =(Spread!D30+Spread!D31+Spread!D35+Inputs!B7)/Spread!D10 -> 2.3491678 | D20: Assumes line balance unchanged
A21: Leverage result | B21: =IF(B20<=Inputs!B27,"PASS","FAIL") -> PASS
A23: B. Projected Year 1 (first full year post-installation) | B23: Amount | D23: Notes
A24: Revenue | B24: =Spread!D5*(1+Inputs!B35) -> 18656000 | D24: FY2025 x (1 + growth)
A25: Cost of goods sold | B25: =B24*(Spread!D6/Spread!D5-Inputs!B36) -> 13301728 | D25: FY2025 COGS % less in-sourcing savings
A26: Gross profit | B26: =B24-B25 -> 5354272
A27: Officer compensation | B27: =Spread!D8*(1+Inputs!B37) -> 460000
A28: Other SG&A | B28: =Spread!D9*(1+Inputs!B38) -> 2100800
A29: EBITDA | B29: =B26-B27-B28 -> 2793472
A30: Depreciation (existing + new equipment) | B30: =Spread!D11+Inputs!B5/Inputs!B39 -> 1190000
A31: Interest (existing + new loan Yr1 + RLOC) | B31: =Inputs!B16+Amortization!G4+B13 -> 358298.67
A32: Net income | B32: =B29-B30-B31 -> 1245173.3
A33: Distributions | B33: =B32*Inputs!B40 -> 560328
A34: CFADS (EBITDA - distributions) | B34: =B29-B33 -> 2233144 | D34: Equivalent to NI + D&A + interest - distributions
A35: Total debt service | B35: =B14 -> 1236980.2
A36: Projected DSCR | B36: =B34/B35 -> 1.8053191
A37: Result | B37: =IF(B36>=Inputs!B25,"PASS","FAIL") -> PASS

Sheet Global_CF
A1: Global Cash Flow Analysis
A2: Business cash flow after distributions plus guarantor personal cash flow, against all business and personal debt service (FY2025 tax year)
A4: Guarantor personal cash flow | B4: D. Reyes | C4: A. Brooks | D4: Combined | F4: Notes
A5: Ownership % | B5: 0.6 | C5: 0.4 | F5: Per operating agreement
A6: W-2 officer compensation | B6: 260000 | C6: 200000 | D6: =B6+C6 -> 460000 | F6: Ties to FY2025 officer compensation
A7: K-1 distributions received | B7: =B5*Spread!$D$16 -> 420000 | C7: =C5*Spread!$D$16 -> 280000 | D7: =B7+C7 -> 700000
A8: K-1 taxable income | B8: =B5*Spread!$D$15 -> 849120 | C8: =C5*Spread!$D$15 -> 566080 | D8: =B8+C8 -> 1415200 | F8: Taxed whether or not distributed
A9: Other income (rental NOI) | B9: 54000 | C9: 0 | D9: =B9+C9 -> 54000 | F9: Reyes owns one rental property
A10: Estimated effective personal tax rate | B10: 0.32 | C10: 0.3 | F10: From 2025 personal returns
A11: Personal income taxes | B11: =-B10*(B6+B8+B9) -> -372198.4 | C11: =-C10*(C6+C8+C9) -> -229824 | D11: =B11+C11 -> -602022.4 | F11: Applied to taxable income, not cash received
A12: Living expenses | B12: -150000 | C12: -110000 | D12: =B12+C12 -> -260000 | F12: Per personal financial statement
A13: Personal cash available for debt service | B13: =B6+B7+B9+B11+B12 -> 211801.6 | C13: =C6+C7+C9+C11+C12 -> 140176 | D13: =B13+C13 -> 351977.6
A15: Residence mortgage | B15: 72000 | C15: 48000 | D15: =B15+C15 -> 120000 | F15: Annual payments per credit report
A16: Auto loans | B16: 14000 | C16: 9000 | D16: =B16+C16 -> 23000
A17: Rental property mortgage | B17: 30000 | C17: 0 | D17: =B17+C17 -> 30000
A18: Total personal debt service | B18: =SUM(B15:B17) -> 116000 | C18: =SUM(C15:C17) -> 57000 | D18: =B18+C18 -> 173000
A19: Personal coverage | B19: =B13/B18 -> 1.8258759 | C19: =C13/C18 -> 2.4592281 | D19: =D13/D18 -> 2.0345526
A21: Global debt service coverage | B21: Amount | F21: Notes
A22: Business CFADS (after distributions) | B22: =ProForma_DSCR!B9 -> 1619200 | F22: Distributions already removed, so no double count
A23: + Personal cash available | B23: =D13 -> 351977.6
A24: Global cash available | B24: =B22+B23 -> 1971177.6
A25: Business pro forma debt service | B25: =ProForma_DSCR!B14 -> 1236980.2
A26: + Personal debt service | B26: =D18 -> 173000
A27: Global debt service | B27: =B25+B26 -> 1409980.2
A28: Global DSCR | B28: =B24/B27 -> 1.3980179
A29: Policy minimum | B29: =Inputs!B26 -> 1.2
A30: Result | B30: =IF(B28>=B29,"PASS","FAIL") -> PASS
A32: Guarantor balance sheet strength | B32: D. Reyes | C32: A. Brooks | D32: Combined | F32: Notes
A33: Liquid assets (cash + marketable securities) | B33: 640000 | C33: 310000 | D33: =B33+C33 -> 950000 | F33: Verified statements, Sept 2026
A34: Less: equity injection | B34: =-Inputs!B20 -> -400000 | C34: 0 | D34: =B34+C34 -> -400000
A35: Post-closing liquidity | B35: =B33+B34 -> 240000 | C35: =C33+C34 -> 310000 | D35: =B35+C35 -> 550000
A36: Adjusted net worth | B36: 4100000 | C36: 1900000 | D36: =B36+C36 -> 6000000 | F36: Excludes business interest
A37: Contingent liabilities | B37: 0 | C37: 0 | D37: =B37+C37 -> 0 | F37: No other guarantees disclosed
A38: Post-closing liquidity / annual business debt service | D38: =D35/ProForma_DSCR!B14 -> 0.44463121

Sheet Stress_Test
A1: Stress Test & Sensitivity
A2: Shocks applied to FY2025 historical pro forma. Distributions flex with net income at the FY2025 payout ratio.
A4: Base revenue | B4: =Spread!D5 -> 17600000
A5: Contribution margin ratio | B5: =1-(Spread!D6*Inputs!B43+Spread!D9*Inputs!B44)/Spread!D5 -> 0.35824545
A6: Base CFADS | B6: =ProForma_DSCR!B9 -> 1619200
A7: Base debt service | B7: =ProForma_DSCR!B14 -> 1236980.2
A8: Distribution payout ratio | B8: =Spread!D16/Spread!D15 -> 0.49462973
A9: Scenario | B9: Revenue shock | C9: Gross margin shock | D9: Rate shock | E9: EBITDA impact | F9: Distribution offset | G9: Stressed CFADS | H9: Debt service | I9: DSCR | J9: Result
A10: Base case | B10: 0 | C10: 0 | D10: 0 | E10: =$B$4*B10*$B$5+$B$4*(1+B10)*C10 -> 0 | F10: =-(E10-Inputs!$B$15*D10)*$B$8 -> 0 | G10: =$B$6+E10+F10 -> 1619200 | H10: =$B$7+Inputs!$B$15*D10 -> 1236980.2 | I10: =G10/H10 -> 1.3089943 | J10: =IF(I10>=1.25,"PASS",IF(I10>=1,"WATCH","FAIL")) -> PASS
A11: Revenue down 10% | B11: -0.1 | C11: 0 | D11: 0 | E11: =$B$4*B11*$B$5+$B$4*(1+B11)*C11 -> -630512 | F11: =-(E11-Inputs!$B$15*D11)*$B$8 -> 311869.98 | G11: =$B$6+E11+F11 -> 1300558 | H11: =$B$7+Inputs!$B$15*D11 -> 1236980.2 | I11: =G11/H11 -> 1.0513976 | J11: =IF(I11>=1.25,"PASS",IF(I11>=1,"WATCH","FAIL")) -> WATCH
A12: Revenue down 20% | B12: -0.2 | C12: 0 | D12: 0 | E12: =$B$4*B12*$B$5+$B$4*(1+B12)*C12 -> -1261024 | F12: =-(E12-Inputs!$B$15*D12)*$B$8 -> 623739.97 | G12: =$B$6+E12+F12 -> 981915.97 | H12: =$B$7+Inputs!$B$15*D12 -> 1236980.2 | I12: =G12/H12 -> 0.79380088 | J12: =IF(I12>=1.25,"PASS",IF(I12>=1,"WATCH","FAIL")) -> FAIL
A13: Gross margin down 200 bps | B13: 0 | C13: -0.02 | D13: 0 | E13: =$B$4*B13*$B$5+$B$4*(1+B13)*C13 -> -352000 | F13: =-(E13-Inputs!$B$15*D13)*$B$8 -> 174109.67 | G13: =$B$6+E13+F13 -> 1441309.7 | H13: =$B$7+Inputs!$B$15*D13 -> 1236980.2 | I13: =G13/H13 -> 1.1651841 | J13: =IF(I13>=1.25,"PASS",IF(I13>=1,"WATCH","FAIL")) -> WATCH
A14: Rates up 200 bps | B14: 0 | C14: 0 | D14: 0.02 | E14: =$B$4*B14*$B$5+$B$4*(1+B14)*C14 -> 0 | F14: =-(E14-Inputs!$B$15*D14)*$B$8 -> 8903.3352 | G14: =$B$6+E14+F14 -> 1628103.3 | H14: =$B$7+Inputs!$B$15*D14 -> 1254980.2 | I14: =G14/H14 -> 1.297314 | J14: =IF(I14>=1.25,"PASS",IF(I14>=1,"WATCH","FAIL")) -> PASS
A15: Combined: Rev -10%, GM -100 bps, +200 bps | B15: -0.1 | C15: -0.01 | D15: 0.02 | E15: =$B$4*B15*$B$5+$B$4*(1+B15)*C15 -> -788912 | F15: =-(E15-Inputs!$B$15*D15)*$B$8 -> 399122.67 | G15: =$B$6+E15+F15 -> 1229410.7 | H15: =$B$7+Inputs!$B$15*D15 -> 1254980.2 | I15: =G15/H15 -> 0.97962555 | J15: =IF(I15>=1.25,"PASS",IF(I15>=1,"WATCH","FAIL")) -> FAIL
A17: PASS = meets 1.25x covenant. WATCH = still covers debt service (1.00x to 1.24x). FAIL = below 1.00x.
A19: Breakeven analysis | B19: Value
A20: Revenue decline to reach 1.25x DSCR | B20: =-(B6-1.25*B7)/(B4*B5*(1-B8)) -> -0.022901798
A21: Revenue decline to reach 1.00x DSCR | B21: =-(B6-B7)/(B4*B5*(1-B8)) -> -0.11995273
A22: Revenue at 1.00x DSCR | B22: =B4*(1+B21) -> 15488832

Sheet Collateral_BB
A1: Collateral Coverage & Borrowing Base
A2: All business assets pledged under a blanket lien; new equipment under a first-priority purchase money lien
A4: Collateral | B4: Book / cost | C4: Advance | D4: Lendable value | F4: Basis
A5: Accounts receivable | B5: =Spread!D20 -> 2250000 | C5: 0.8 | D5: =B5*C5 -> 1800000 | F5: Eligible A/R, see borrowing base below
A6: Inventory | B6: =Spread!D21 -> 1640000 | C6: 0.5 | D6: =B6*C6 -> 820000 | F6: Raw steel and finished goods
A7: Existing equipment (net book value) | B7: =Spread!D26 -> 3770000 | C7: 0.5 | D7: =B7*C7 -> 1885000 | F7: Desktop orderly liquidation estimate
A8: New equipment (cost) | B8: =Inputs!B5 -> 3500000 | C8: 0.7 | D8: =B8*C8 -> 2450000 | F8: New fiber lasers hold value well; vendor resale data
A9: Total lendable collateral | D9: =SUM(D5:D8) -> 6955000
A11: Total relationship exposure | B11: Amount
A12: Existing term debt | D12: =Spread!D31+Spread!D35 -> 1840000
A13: New equipment term loan | D13: =Inputs!B7 -> 2800000
A14: RLOC commitment (fully drawn) | D14: =Inputs!B10 -> 1500000
A15: Total exposure | D15: =SUM(D12:D14) -> 6140000
A16: Collateral coverage | D16: =D9/D15 -> 1.1327362
A17: Result | D17: =IF(D16>=Inputs!B28,"PASS","FAIL") -> PASS
A18: New equipment loan-to-cost | D18: =Inputs!B7/Inputs!B5 -> 0.8
A20: Borrowing Base Certificate (as of 12/31/2025) | B20: Amount
A21: A/R aging: current | D21: 1520000
A22: A/R aging: 31 to 60 days | D22: 480000
A23: A/R aging: 61 to 90 days | D23: 115000
A24: A/R aging: over 90 days | D24: 135000
A25: Total A/R | D25: =SUM(D21:D24) -> 2250000
A26: Tie-out to balance sheet (must be zero) | D26: =D25-Spread!D20 -> 0
A27: Less: over 90 days | D27: =-D24 -> -135000
A28: Less: affiliate and contra accounts | D28: -40000
A29: Eligible A/R | D29: =D25+D27+D28 -> 2075000
A30: A/R advance rate | D30: 0.8
A31: A/R availability | D31: =D29*D30 -> 1660000
A33: Inventory: raw materials | D33: 1050000
A34: Inventory: work in process | D34: 360000
A35: Inventory: finished goods | D35: 230000
A36: Tie-out to balance sheet (must be zero) | D36: =SUM(D33:D35)-Spread!D21 -> 0
A37: Eligible inventory (excludes WIP) | D37: =D33+D35 -> 1280000
A38: Inventory advance rate | D38: 0.5
A39: Inventory sublimit cap | D39: 600000
A40: Inventory availability | D40: =MIN(D37*D38,D39) -> 600000
A42: Total borrowing base | D42: =D31+D40 -> 2260000
A43: Lesser of borrowing base or commitment | D43: =MIN(D42,Inputs!B10) -> 1500000
A44: Less: outstanding balance | D44: =-Spread!D30 -> -780000
A45: Net availability | D45: =D43+D44 -> 720000

Sheet Risk_Rating
A1: Risk Rating Scorecard
A2: 9-point scale: 1 = lowest risk, 9 = highest. Quantitative scores pull from the model; qualitative scores are analyst judgment (blue).
H3: Scoring thresholds (lower bound of each band)
A4: Factor | B4: Metric | C4: Score | D4: Weight | E4: Weighted | F4: Rationale | H4: DSCR band | I4: 0 | J4: 0.9 | K4: 1 | L4: 1.1 | M4: 1.25 | N4: 1.5 | O4: 1.75 | P4: 2.25 | Q4: 3
A5: Repayment capacity (pro forma DSCR) | B5: =ProForma_DSCR!B16 -> 1.3089943 | C5: =INDEX($I$5:$Q$5,MATCH(B5,$I$4:$Q$4,1)) -> 5 | D5: 0.3 | E5: =C5*D5 -> 1.5 | F5: Historical pro forma covers new debt at about 1.3x; projected Year 1 is stronger | H5: DSCR score | I5: 9 | J5: 8 | K5: 7 | L5: 6 | M5: 5 | N5: 4 | O5: 3 | P5: 2 | Q5: 1
A6: Leverage (pro forma funded debt / EBITDA) | B6: =ProForma_DSCR!B20 -> 2.3491678 | C6: =INDEX($I$8:$Q$8,MATCH(B6,$I$7:$Q$7,1)) -> 4 | D6: 0.15 | E6: =C6*D6 -> 0.6 | F6: Moderate leverage after funding, well inside 3.0x covenant
A7: Liquidity (current ratio) | B7: =Ratios!D11 -> 1.5743003 | C7: =INDEX($I$11:$Q$11,MATCH(B7,$I$10:$Q$10,1)) -> 4 | D7: 0.1 | E7: =C7*D7 -> 0.4 | F7: Adequate; line availability supports working capital | H7: Leverage band | I7: 0 | J7: 1 | K7: 1.5 | L7: 2 | M7: 2.5 | N7: 3 | O7: 3.5 | P7: 4 | Q7: 5
A8: Management & ownership | B8: Qualitative | C8: 3 | D8: 0.15 | E8: =C8*D8 -> 0.45 | F8: Owners have 20+ years in fabrication; CPA-reviewed statements; clean reporting history | H8: Leverage score | I8: 1 | J8: 2 | K8: 3 | L8: 4 | M8: 5 | N8: 6 | O8: 7 | P8: 8 | Q8: 9
A9: Industry risk | B9: Qualitative | C9: 5 | D9: 0.1 | E9: =C9*D9 -> 0.5 | F9: Cyclical demand tied to construction and energy; steel tariffs raise input cost volatility
A10: Collateral coverage | B10: =Collateral_BB!D16 -> 1.1327362 | C10: =INDEX($I$14:$Q$14,MATCH(B10,$I$13:$Q$13,1)) -> 4 | D10: 0.1 | E10: =C10*D10 -> 0.4 | F10: Blanket lien plus PMSI on new equipment | H10: Current band | I10: 0 | J10: 0.8 | K10: 1 | L10: 1.1 | M10: 1.25 | N10: 1.5 | O10: 1.75 | P10: 2 | Q10: 2.5
A11: Guarantor support | B11: Qualitative | C11: 3 | D11: 0.1 | E11: =C11*D11 -> 0.3 | F11: Combined post-closing liquidity of about $550K and adjusted net worth of $6.0MM | H11: Current score | I11: 9 | J11: 8 | K11: 7 | L11: 6 | M11: 5 | N11: 4 | O11: 3 | P11: 2 | Q11: 1
A12: Total | D12: =SUM(D5:D11) -> 1 | E12: =SUM(E5:E11) -> 4.15
H13: Collateral band | I13: 0 | J13: 0.6 | K13: 0.8 | L13: 0.9 | M13: 1 | N13: 1.1 | O13: 1.25 | P13: 1.5 | Q13: 2
A14: Composite score | C14: =E12 -> 4.15 | H14: Collateral score | I14: 9 | J14: 8 | K14: 7 | L14: 6 | M14: 5 | N14: 4 | O14: 3 | P14: 2 | Q14: 1
A15: Recommended risk rating | C15: =ROUND(C14,0) -> 4
A16: Rating description | C16: =INDEX($I$22:$Q$22,C15) -> Satisfactory
H21: Rating scale | I21: 1 | J21: 2 | K21: 3 | L21: 4 | M21: 5 | N21: 6 | O21: 7 | P21: 8 | Q21: 9
H22: Description | I22: Exceptional | J22: Strong | K22: Good | L22: Satisfactory | M22: Acceptable | N22: Watch | O22: Special Mention | P22: Substandard | Q22: Doubtful

Sheet Amortization
A1: Equipment Term Loan Amortization
A2: Level monthly payments, fixed rate
G3: Year 1 interest | H3: Year 1 principal
A4: Monthly payment | C4: =-PMT(Inputs!B8/12,Inputs!B9,Inputs!B7) -> 42602.517 | G4: =SUM(D7:D18) -> 192548.67 | H4: =SUM(E7:E18) -> 318681.53
A6: Month | B6: Beginning balance | C6: Payment | D6: Interest | E6: Principal | G6: Year | H6: Payments | I6: Interest | J6: Principal | K6: Ending balance
A7: 1 | B7: =Inputs!B7 -> 2800000 | C7: =$C$4 -> 42602.517 | D7: =B7*Inputs!$B$8/12 -> 16916.667 | E7: =C7-D7 -> 25685.85 | G7: Year 1 | H7: =SUM(C7:C18) -> 511230.2 | I7: =SUM(D7:D18) -> 192548.67 | J7: =SUM(E7:E18) -> 318681.53 | K7: =B18-E18 -> 2481318.5
A8: 2 | B8: =B7-E7 -> 2774314.2 | C8: =$C$4 -> 42602.517 | D8: =B8*Inputs!$B$8/12 -> 16761.481 | E8: =C8-D8 -> 25841.035 | G8: Year 2 | H8: =SUM(C19:C30) -> 511230.2 | I8: =SUM(D19:D30) -> 168660.84 | J8: =SUM(E19:E30) -> 342569.35 | K8: =B30-E30 -> 2138749.1
A9: 3 | B9: =B8-E8 -> 2748473.1 | C9: =$C$4 -> 42602.517 | D9: =B9*Inputs!$B$8/12 -> 16605.358 | E9: =C9-D9 -> 25997.158 | G9: Year 3 | H9: =SUM(C31:C42) -> 511230.2 | I9: =SUM(D31:D42) -> 142982.43 | J9: =SUM(E31:E42) -> 368247.77 | K9: =B42-E42 -> 1770501.3
A10: 4 | B10: =B9-E9 -> 2722476 | C10: =$C$4 -> 42602.517 | D10: =B10*Inputs!$B$8/12 -> 16448.292 | E10: =C10-D10 -> 26154.224 | G10: Year 4 | H10: =SUM(C43:C54) -> 511230.2 | I10: =SUM(D43:D54) -> 115379.2 | J10: =SUM(E43:E54) -> 395851 | K10: =B54-E54 -> 1374650.4
A11: 5 | B11: =B10-E10 -> 2696321.7 | C11: =$C$4 -> 42602.517 | D11: =B11*Inputs!$B$8/12 -> 16290.277 | E11: =C11-D11 -> 26312.239 | G11: Year 5 | H11: =SUM(C55:C66) -> 511230.2 | I11: =SUM(D55:D66) -> 85706.886 | J11: =SUM(E55:E66) -> 425523.31 | K11: =B66-E66 -> 949127.04
A12: 6 | B12: =B11-E11 -> 2670009.5 | C12: =$C$4 -> 42602.517 | D12: =B12*Inputs!$B$8/12 -> 16131.307 | E12: =C12-D12 -> 26471.209 | G12: Year 6 | H12: =SUM(C67:C78) -> 511230.2 | I12: =SUM(D67:D78) -> 53810.383 | J12: =SUM(E67:E78) -> 457419.81 | K12: =B78-E78 -> 491707.23
A13: 7 | B13: =B12-E12 -> 2643538.3 | C13: =$C$4 -> 42602.517 | D13: =B13*Inputs!$B$8/12 -> 15971.377 | E13: =C13-D13 -> 26631.139 | G13: Year 7 | H13: =SUM(C79:C90) -> 511230.2 | I13: =SUM(D79:D90) -> 19522.973 | J13: =SUM(E79:E90) -> 491707.23 | K13: =B90-E90 -> 2.401066e-10
A14: 8 | B14: =B13-E13 -> 2616907.1 | C14: =$C$4 -> 42602.517 | D14: =B14*Inputs!$B$8/12 -> 15810.481 | E14: =C14-D14 -> 26792.036
A15: 9 | B15: =B14-E14 -> 2590115.1 | C15: =$C$4 -> 42602.517 | D15: =B15*Inputs!$B$8/12 -> 15648.612 | E15: =C15-D15 -> 26953.904
A16: 10 | B16: =B15-E15 -> 2563161.2 | C16: =$C$4 -> 42602.517 | D16: =B16*Inputs!$B$8/12 -> 15485.766 | E16: =C16-D16 -> 27116.751
A17: 11 | B17: =B16-E16 -> 2536044.5 | C17: =$C$4 -> 42602.517 | D17: =B17*Inputs!$B$8/12 -> 15321.935 | E17: =C17-D17 -> 27280.581
A18: 12 | B18: =B17-E17 -> 2508763.9 | C18: =$C$4 -> 42602.517 | D18: =B18*Inputs!$B$8/12 -> 15157.115 | E18: =C18-D18 -> 27445.401
A19: 13 | B19: =B18-E18 -> 2481318.5 | C19: =$C$4 -> 42602.517 | D19: =B19*Inputs!$B$8/12 -> 14991.299 | E19: =C19-D19 -> 27611.217
A20: 14 | B20: =B19-E19 -> 2453707.3 | C20: =$C$4 -> 42602.517 | D20: =B20*Inputs!$B$8/12 -> 14824.481 | E20: =C20-D20 -> 27778.035
A21: 15 | B21: =B20-E20 -> 2425929.2 | C21: =$C$4 -> 42602.517 | D21: =B21*Inputs!$B$8/12 -> 14656.656 | E21: =C21-D21 -> 27945.861
A22: 16 | B22: =B21-E21 -> 2397983.4 | C22: =$C$4 -> 42602.517 | D22: =B22*Inputs!$B$8/12 -> 14487.816 | E22: =C22-D22 -> 28114.7
A23: 17 | B23: =B22-E22 -> 2369868.7 | C23: =$C$4 -> 42602.517 | D23: =B23*Inputs!$B$8/12 -> 14317.956 | E23: =C23-D23 -> 28284.56
A24: 18 | B24: =B23-E23 -> 2341584.1 | C24: =$C$4 -> 42602.517 | D24: =B24*Inputs!$B$8/12 -> 14147.071 | E24: =C24-D24 -> 28455.446
A25: 19 | B25: =B24-E24 -> 2313128.7 | C25: =$C$4 -> 42602.517 | D25: =B25*Inputs!$B$8/12 -> 13975.152 | E25: =C25-D25 -> 28627.364
... A90: 84 | B90: =B89-E89 -> 42346.672 | C90: =$C$4 -> 42602.517 | D90: =B90*Inputs!$B$8/12 -> 255.84448 | E90: =C90-D90 -> 42346.672
A92: Ending | B92: =B90-E90 -> 2.401066e-10
